2025-03-02 01:53:56,800 - INFO - Database table created or already exists.
2025-03-02 01:57:02,574 - ERROR - Validation error: [{'type': 'int_parsing', 'loc': ('body', 'year'), 'msg': 'Input should be a valid integer, unable to parse string as an integer', 'input': ''}, {'type': 'value_error', 'loc': ('body', 'retail_srp'), 'msg': 'Value error, Retail SRP must be positive', 'input': 0, 'ctx': {'error': ValueError('Retail SRP must be positive')}}]
2025-03-02 01:57:02,574 - ERROR - Unhandled exception: Object of type ValueError is not JSON serializable
Traceback (most recent call last):
  File "C:\Users\Sobre\OneDrive\Desktop\Vroomble\.venv\Lib\site-packages\starlette\_exception_handler.py", line 42, in wrapped_app
    await app(scope, receive, sender)
  File "C:\Users\Sobre\OneDrive\Desktop\Vroomble\.venv\Lib\site-packages\starlette\routing.py", line 73, in app
    response = await f(request)
               ^^^^^^^^^^^^^^^^
  File "C:\Users\Sobre\OneDrive\Desktop\Vroomble\.venv\Lib\site-packages\fastapi\routing.py", line 346, in app
    raise validation_error
fastapi.exceptions.RequestValidationError: [{'type': 'int_parsing', 'loc': ('body', 'year'), 'msg': 'Input should be a valid integer, unable to parse string as an integer', 'input': ''}, {'type': 'value_error', 'loc': ('body', 'retail_srp'), 'msg': 'Value error, Retail SRP must be positive', 'input': 0, 'ctx': {'error': ValueError('Retail SRP must be positive')}}]

During handling of the above exception, another exception occurred:

Traceback (most recent call last):
  File "C:\Users\Sobre\OneDrive\Desktop\Vroomble\.venv\Lib\site-packages\starlette\middleware\errors.py", line 165, in __call__
    await self.app(scope, receive, _send)
  File "C:\Users\Sobre\OneDrive\Desktop\Vroomble\.venv\Lib\site-packages\starlette\middleware\cors.py", line 93, in __call__
    await self.simple_response(scope, receive, send, request_headers=headers)
  File "C:\Users\Sobre\OneDrive\Desktop\Vroomble\.venv\Lib\site-packages\starlette\middleware\cors.py", line 144, in simple_response
    await self.app(scope, receive, send)
  File "C:\Users\Sobre\OneDrive\Desktop\Vroomble\.venv\Lib\site-packages\starlette\middleware\exceptions.py", line 62, in __call__
    await wrap_app_handling_exceptions(self.app, conn)(scope, receive, send)
  File "C:\Users\Sobre\OneDrive\Desktop\Vroomble\.venv\Lib\site-packages\starlette\_exception_handler.py", line 53, in wrapped_app
    raise exc
  File "C:\Users\Sobre\OneDrive\Desktop\Vroomble\.venv\Lib\site-packages\starlette\_exception_handler.py", line 42, in wrapped_app
    await app(scope, receive, sender)
  File "C:\Users\Sobre\OneDrive\Desktop\Vroomble\.venv\Lib\site-packages\starlette\routing.py", line 715, in __call__
    await self.middleware_stack(scope, receive, send)
  File "C:\Users\Sobre\OneDrive\Desktop\Vroomble\.venv\Lib\site-packages\starlette\routing.py", line 735, in app
    await route.handle(scope, receive, send)
  File "C:\Users\Sobre\OneDrive\Desktop\Vroomble\.venv\Lib\site-packages\starlette\routing.py", line 288, in handle
    await self.app(scope, receive, send)
  File "C:\Users\Sobre\OneDrive\Desktop\Vroomble\.venv\Lib\site-packages\starlette\routing.py", line 76, in app
    await wrap_app_handling_exceptions(app, request)(scope, receive, send)
  File "C:\Users\Sobre\OneDrive\Desktop\Vroomble\.venv\Lib\site-packages\starlette\_exception_handler.py", line 59, in wrapped_app
    response = await handler(conn, exc)
               ^^^^^^^^^^^^^^^^^^^^^^^^
  File "C:\Users\Sobre\OneDrive\Desktop\Vroomble\src\APIs\vehicle_registration.py", line 170, in validation_exception_handler
    return JSONResponse(
           ^^^^^^^^^^^^^
  File "C:\Users\Sobre\OneDrive\Desktop\Vroomble\.venv\Lib\site-packages\starlette\responses.py", line 181, in __init__
    super().__init__(content, status_code, headers, media_type, background)
  File "C:\Users\Sobre\OneDrive\Desktop\Vroomble\.venv\Lib\site-packages\starlette\responses.py", line 44, in __init__
    self.body = self.render(content)
                ^^^^^^^^^^^^^^^^^^^^
  File "C:\Users\Sobre\OneDrive\Desktop\Vroomble\.venv\Lib\site-packages\starlette\responses.py", line 184, in render
    return json.dumps(
           ^^^^^^^^^^^
  File "C:\Program Files\WindowsApps\PythonSoftwareFoundation.Python.3.11_3.11.2544.0_x64__qbz5n2kfra8p0\Lib\json\__init__.py", line 238, in dumps
    **kw).encode(obj)
          ^^^^^^^^^^^
  File "C:\Program Files\WindowsApps\PythonSoftwareFoundation.Python.3.11_3.11.2544.0_x64__qbz5n2kfra8p0\Lib\json\encoder.py", line 200, in encode
    chunks = self.iterencode(o, _one_shot=True)
             ^^^^^^^^^^^^^^^^^^^^^^^^^^^^^^^^^^
  File "C:\Program Files\WindowsApps\PythonSoftwareFoundation.Python.3.11_3.11.2544.0_x64__qbz5n2kfra8p0\Lib\json\encoder.py", line 258, in iterencode
    return _iterencode(o, 0)
           ^^^^^^^^^^^^^^^^^
  File "C:\Program Files\WindowsApps\PythonSoftwareFoundation.Python.3.11_3.11.2544.0_x64__qbz5n2kfra8p0\Lib\json\encoder.py", line 180, in default
    raise TypeError(f'Object of type {o.__class__.__name__} '
TypeError: Object of type ValueError is not JSON serializable
2025-03-02 01:57:10,637 - ERROR - Validation error: [{'type': 'int_parsing', 'loc': ('body', 'year'), 'msg': 'Input should be a valid integer, unable to parse string as an integer', 'input': ''}, {'type': 'value_error', 'loc': ('body', 'retail_srp'), 'msg': 'Value error, Retail SRP must be positive', 'input': 0, 'ctx': {'error': ValueError('Retail SRP must be positive')}}]
2025-03-02 01:57:10,637 - ERROR - Unhandled exception: Object of type ValueError is not JSON serializable
Traceback (most recent call last):
  File "C:\Users\Sobre\OneDrive\Desktop\Vroomble\.venv\Lib\site-packages\starlette\_exception_handler.py", line 42, in wrapped_app
    await app(scope, receive, sender)
  File "C:\Users\Sobre\OneDrive\Desktop\Vroomble\.venv\Lib\site-packages\starlette\routing.py", line 73, in app
    response = await f(request)
               ^^^^^^^^^^^^^^^^
  File "C:\Users\Sobre\OneDrive\Desktop\Vroomble\.venv\Lib\site-packages\fastapi\routing.py", line 346, in app
    raise validation_error
fastapi.exceptions.RequestValidationError: [{'type': 'int_parsing', 'loc': ('body', 'year'), 'msg': 'Input should be a valid integer, unable to parse string as an integer', 'input': ''}, {'type': 'value_error', 'loc': ('body', 'retail_srp'), 'msg': 'Value error, Retail SRP must be positive', 'input': 0, 'ctx': {'error': ValueError('Retail SRP must be positive')}}]

During handling of the above exception, another exception occurred:

Traceback (most recent call last):
  File "C:\Users\Sobre\OneDrive\Desktop\Vroomble\.venv\Lib\site-packages\starlette\middleware\errors.py", line 165, in __call__
    await self.app(scope, receive, _send)
  File "C:\Users\Sobre\OneDrive\Desktop\Vroomble\.venv\Lib\site-packages\starlette\middleware\cors.py", line 93, in __call__
    await self.simple_response(scope, receive, send, request_headers=headers)
  File "C:\Users\Sobre\OneDrive\Desktop\Vroomble\.venv\Lib\site-packages\starlette\middleware\cors.py", line 144, in simple_response
    await self.app(scope, receive, send)
  File "C:\Users\Sobre\OneDrive\Desktop\Vroomble\.venv\Lib\site-packages\starlette\middleware\exceptions.py", line 62, in __call__
    await wrap_app_handling_exceptions(self.app, conn)(scope, receive, send)
  File "C:\Users\Sobre\OneDrive\Desktop\Vroomble\.venv\Lib\site-packages\starlette\_exception_handler.py", line 53, in wrapped_app
    raise exc
  File "C:\Users\Sobre\OneDrive\Desktop\Vroomble\.venv\Lib\site-packages\starlette\_exception_handler.py", line 42, in wrapped_app
    await app(scope, receive, sender)
  File "C:\Users\Sobre\OneDrive\Desktop\Vroomble\.venv\Lib\site-packages\starlette\routing.py", line 715, in __call__
    await self.middleware_stack(scope, receive, send)
  File "C:\Users\Sobre\OneDrive\Desktop\Vroomble\.venv\Lib\site-packages\starlette\routing.py", line 735, in app
    await route.handle(scope, receive, send)
  File "C:\Users\Sobre\OneDrive\Desktop\Vroomble\.venv\Lib\site-packages\starlette\routing.py", line 288, in handle
    await self.app(scope, receive, send)
  File "C:\Users\Sobre\OneDrive\Desktop\Vroomble\.venv\Lib\site-packages\starlette\routing.py", line 76, in app
    await wrap_app_handling_exceptions(app, request)(scope, receive, send)
  File "C:\Users\Sobre\OneDrive\Desktop\Vroomble\.venv\Lib\site-packages\starlette\_exception_handler.py", line 59, in wrapped_app
    response = await handler(conn, exc)
               ^^^^^^^^^^^^^^^^^^^^^^^^
  File "C:\Users\Sobre\OneDrive\Desktop\Vroomble\src\APIs\vehicle_registration.py", line 170, in validation_exception_handler
    return JSONResponse(
           ^^^^^^^^^^^^^
  File "C:\Users\Sobre\OneDrive\Desktop\Vroomble\.venv\Lib\site-packages\starlette\responses.py", line 181, in __init__
    super().__init__(content, status_code, headers, media_type, background)
  File "C:\Users\Sobre\OneDrive\Desktop\Vroomble\.venv\Lib\site-packages\starlette\responses.py", line 44, in __init__
    self.body = self.render(content)
                ^^^^^^^^^^^^^^^^^^^^
  File "C:\Users\Sobre\OneDrive\Desktop\Vroomble\.venv\Lib\site-packages\starlette\responses.py", line 184, in render
    return json.dumps(
           ^^^^^^^^^^^
  File "C:\Program Files\WindowsApps\PythonSoftwareFoundation.Python.3.11_3.11.2544.0_x64__qbz5n2kfra8p0\Lib\json\__init__.py", line 238, in dumps
    **kw).encode(obj)
          ^^^^^^^^^^^
  File "C:\Program Files\WindowsApps\PythonSoftwareFoundation.Python.3.11_3.11.2544.0_x64__qbz5n2kfra8p0\Lib\json\encoder.py", line 200, in encode
    chunks = self.iterencode(o, _one_shot=True)
             ^^^^^^^^^^^^^^^^^^^^^^^^^^^^^^^^^^
  File "C:\Program Files\WindowsApps\PythonSoftwareFoundation.Python.3.11_3.11.2544.0_x64__qbz5n2kfra8p0\Lib\json\encoder.py", line 258, in iterencode
    return _iterencode(o, 0)
           ^^^^^^^^^^^^^^^^^
  File "C:\Program Files\WindowsApps\PythonSoftwareFoundation.Python.3.11_3.11.2544.0_x64__qbz5n2kfra8p0\Lib\json\encoder.py", line 180, in default
    raise TypeError(f'Object of type {o.__class__.__name__} '
TypeError: Object of type ValueError is not JSON serializable
2025-03-02 01:57:17,118 - ERROR - Validation error: [{'type': 'int_parsing', 'loc': ('body', 'year'), 'msg': 'Input should be a valid integer, unable to parse string as an integer', 'input': ''}, {'type': 'value_error', 'loc': ('body', 'retail_srp'), 'msg': 'Value error, Retail SRP must be positive', 'input': 0, 'ctx': {'error': ValueError('Retail SRP must be positive')}}]
2025-03-02 01:57:17,118 - ERROR - Unhandled exception: Object of type ValueError is not JSON serializable
Traceback (most recent call last):
  File "C:\Users\Sobre\OneDrive\Desktop\Vroomble\.venv\Lib\site-packages\starlette\_exception_handler.py", line 42, in wrapped_app
    await app(scope, receive, sender)
  File "C:\Users\Sobre\OneDrive\Desktop\Vroomble\.venv\Lib\site-packages\starlette\routing.py", line 73, in app
    response = await f(request)
               ^^^^^^^^^^^^^^^^
  File "C:\Users\Sobre\OneDrive\Desktop\Vroomble\.venv\Lib\site-packages\fastapi\routing.py", line 346, in app
    raise validation_error
fastapi.exceptions.RequestValidationError: [{'type': 'int_parsing', 'loc': ('body', 'year'), 'msg': 'Input should be a valid integer, unable to parse string as an integer', 'input': ''}, {'type': 'value_error', 'loc': ('body', 'retail_srp'), 'msg': 'Value error, Retail SRP must be positive', 'input': 0, 'ctx': {'error': ValueError('Retail SRP must be positive')}}]

During handling of the above exception, another exception occurred:

Traceback (most recent call last):
  File "C:\Users\Sobre\OneDrive\Desktop\Vroomble\.venv\Lib\site-packages\starlette\middleware\errors.py", line 165, in __call__
    await self.app(scope, receive, _send)
  File "C:\Users\Sobre\OneDrive\Desktop\Vroomble\.venv\Lib\site-packages\starlette\middleware\cors.py", line 93, in __call__
    await self.simple_response(scope, receive, send, request_headers=headers)
  File "C:\Users\Sobre\OneDrive\Desktop\Vroomble\.venv\Lib\site-packages\starlette\middleware\cors.py", line 144, in simple_response
    await self.app(scope, receive, send)
  File "C:\Users\Sobre\OneDrive\Desktop\Vroomble\.venv\Lib\site-packages\starlette\middleware\exceptions.py", line 62, in __call__
    await wrap_app_handling_exceptions(self.app, conn)(scope, receive, send)
  File "C:\Users\Sobre\OneDrive\Desktop\Vroomble\.venv\Lib\site-packages\starlette\_exception_handler.py", line 53, in wrapped_app
    raise exc
  File "C:\Users\Sobre\OneDrive\Desktop\Vroomble\.venv\Lib\site-packages\starlette\_exception_handler.py", line 42, in wrapped_app
    await app(scope, receive, sender)
  File "C:\Users\Sobre\OneDrive\Desktop\Vroomble\.venv\Lib\site-packages\starlette\routing.py", line 715, in __call__
    await self.middleware_stack(scope, receive, send)
  File "C:\Users\Sobre\OneDrive\Desktop\Vroomble\.venv\Lib\site-packages\starlette\routing.py", line 735, in app
    await route.handle(scope, receive, send)
  File "C:\Users\Sobre\OneDrive\Desktop\Vroomble\.venv\Lib\site-packages\starlette\routing.py", line 288, in handle
    await self.app(scope, receive, send)
  File "C:\Users\Sobre\OneDrive\Desktop\Vroomble\.venv\Lib\site-packages\starlette\routing.py", line 76, in app
    await wrap_app_handling_exceptions(app, request)(scope, receive, send)
  File "C:\Users\Sobre\OneDrive\Desktop\Vroomble\.venv\Lib\site-packages\starlette\_exception_handler.py", line 59, in wrapped_app
    response = await handler(conn, exc)
               ^^^^^^^^^^^^^^^^^^^^^^^^
  File "C:\Users\Sobre\OneDrive\Desktop\Vroomble\src\APIs\vehicle_registration.py", line 170, in validation_exception_handler
    return JSONResponse(
           ^^^^^^^^^^^^^
  File "C:\Users\Sobre\OneDrive\Desktop\Vroomble\.venv\Lib\site-packages\starlette\responses.py", line 181, in __init__
    super().__init__(content, status_code, headers, media_type, background)
  File "C:\Users\Sobre\OneDrive\Desktop\Vroomble\.venv\Lib\site-packages\starlette\responses.py", line 44, in __init__
    self.body = self.render(content)
                ^^^^^^^^^^^^^^^^^^^^
  File "C:\Users\Sobre\OneDrive\Desktop\Vroomble\.venv\Lib\site-packages\starlette\responses.py", line 184, in render
    return json.dumps(
           ^^^^^^^^^^^
  File "C:\Program Files\WindowsApps\PythonSoftwareFoundation.Python.3.11_3.11.2544.0_x64__qbz5n2kfra8p0\Lib\json\__init__.py", line 238, in dumps
    **kw).encode(obj)
          ^^^^^^^^^^^
  File "C:\Program Files\WindowsApps\PythonSoftwareFoundation.Python.3.11_3.11.2544.0_x64__qbz5n2kfra8p0\Lib\json\encoder.py", line 200, in encode
    chunks = self.iterencode(o, _one_shot=True)
             ^^^^^^^^^^^^^^^^^^^^^^^^^^^^^^^^^^
  File "C:\Program Files\WindowsApps\PythonSoftwareFoundation.Python.3.11_3.11.2544.0_x64__qbz5n2kfra8p0\Lib\json\encoder.py", line 258, in iterencode
    return _iterencode(o, 0)
           ^^^^^^^^^^^^^^^^^
  File "C:\Program Files\WindowsApps\PythonSoftwareFoundation.Python.3.11_3.11.2544.0_x64__qbz5n2kfra8p0\Lib\json\encoder.py", line 180, in default
    raise TypeError(f'Object of type {o.__class__.__name__} '
TypeError: Object of type ValueError is not JSON serializable
2025-03-02 01:57:20,380 - ERROR - Validation error: [{'type': 'int_parsing', 'loc': ('body', 'year'), 'msg': 'Input should be a valid integer, unable to parse string as an integer', 'input': ''}, {'type': 'value_error', 'loc': ('body', 'retail_srp'), 'msg': 'Value error, Retail SRP must be positive', 'input': 0, 'ctx': {'error': ValueError('Retail SRP must be positive')}}]
2025-03-02 01:57:20,382 - ERROR - Unhandled exception: Object of type ValueError is not JSON serializable
Traceback (most recent call last):
  File "C:\Users\Sobre\OneDrive\Desktop\Vroomble\.venv\Lib\site-packages\starlette\_exception_handler.py", line 42, in wrapped_app
    await app(scope, receive, sender)
  File "C:\Users\Sobre\OneDrive\Desktop\Vroomble\.venv\Lib\site-packages\starlette\routing.py", line 73, in app
    response = await f(request)
               ^^^^^^^^^^^^^^^^
  File "C:\Users\Sobre\OneDrive\Desktop\Vroomble\.venv\Lib\site-packages\fastapi\routing.py", line 346, in app
    raise validation_error
fastapi.exceptions.RequestValidationError: [{'type': 'int_parsing', 'loc': ('body', 'year'), 'msg': 'Input should be a valid integer, unable to parse string as an integer', 'input': ''}, {'type': 'value_error', 'loc': ('body', 'retail_srp'), 'msg': 'Value error, Retail SRP must be positive', 'input': 0, 'ctx': {'error': ValueError('Retail SRP must be positive')}}]

During handling of the above exception, another exception occurred:

Traceback (most recent call last):
  File "C:\Users\Sobre\OneDrive\Desktop\Vroomble\.venv\Lib\site-packages\starlette\middleware\errors.py", line 165, in __call__
    await self.app(scope, receive, _send)
  File "C:\Users\Sobre\OneDrive\Desktop\Vroomble\.venv\Lib\site-packages\starlette\middleware\cors.py", line 93, in __call__
    await self.simple_response(scope, receive, send, request_headers=headers)
  File "C:\Users\Sobre\OneDrive\Desktop\Vroomble\.venv\Lib\site-packages\starlette\middleware\cors.py", line 144, in simple_response
    await self.app(scope, receive, send)
  File "C:\Users\Sobre\OneDrive\Desktop\Vroomble\.venv\Lib\site-packages\starlette\middleware\exceptions.py", line 62, in __call__
    await wrap_app_handling_exceptions(self.app, conn)(scope, receive, send)
  File "C:\Users\Sobre\OneDrive\Desktop\Vroomble\.venv\Lib\site-packages\starlette\_exception_handler.py", line 53, in wrapped_app
    raise exc
  File "C:\Users\Sobre\OneDrive\Desktop\Vroomble\.venv\Lib\site-packages\starlette\_exception_handler.py", line 42, in wrapped_app
    await app(scope, receive, sender)
  File "C:\Users\Sobre\OneDrive\Desktop\Vroomble\.venv\Lib\site-packages\starlette\routing.py", line 715, in __call__
    await self.middleware_stack(scope, receive, send)
  File "C:\Users\Sobre\OneDrive\Desktop\Vroomble\.venv\Lib\site-packages\starlette\routing.py", line 735, in app
    await route.handle(scope, receive, send)
  File "C:\Users\Sobre\OneDrive\Desktop\Vroomble\.venv\Lib\site-packages\starlette\routing.py", line 288, in handle
    await self.app(scope, receive, send)
  File "C:\Users\Sobre\OneDrive\Desktop\Vroomble\.venv\Lib\site-packages\starlette\routing.py", line 76, in app
    await wrap_app_handling_exceptions(app, request)(scope, receive, send)
  File "C:\Users\Sobre\OneDrive\Desktop\Vroomble\.venv\Lib\site-packages\starlette\_exception_handler.py", line 59, in wrapped_app
    response = await handler(conn, exc)
               ^^^^^^^^^^^^^^^^^^^^^^^^
  File "C:\Users\Sobre\OneDrive\Desktop\Vroomble\src\APIs\vehicle_registration.py", line 170, in validation_exception_handler
    return JSONResponse(
           ^^^^^^^^^^^^^
  File "C:\Users\Sobre\OneDrive\Desktop\Vroomble\.venv\Lib\site-packages\starlette\responses.py", line 181, in __init__
    super().__init__(content, status_code, headers, media_type, background)
  File "C:\Users\Sobre\OneDrive\Desktop\Vroomble\.venv\Lib\site-packages\starlette\responses.py", line 44, in __init__
    self.body = self.render(content)
                ^^^^^^^^^^^^^^^^^^^^
  File "C:\Users\Sobre\OneDrive\Desktop\Vroomble\.venv\Lib\site-packages\starlette\responses.py", line 184, in render
    return json.dumps(
           ^^^^^^^^^^^
  File "C:\Program Files\WindowsApps\PythonSoftwareFoundation.Python.3.11_3.11.2544.0_x64__qbz5n2kfra8p0\Lib\json\__init__.py", line 238, in dumps
    **kw).encode(obj)
          ^^^^^^^^^^^
  File "C:\Program Files\WindowsApps\PythonSoftwareFoundation.Python.3.11_3.11.2544.0_x64__qbz5n2kfra8p0\Lib\json\encoder.py", line 200, in encode
    chunks = self.iterencode(o, _one_shot=True)
             ^^^^^^^^^^^^^^^^^^^^^^^^^^^^^^^^^^
  File "C:\Program Files\WindowsApps\PythonSoftwareFoundation.Python.3.11_3.11.2544.0_x64__qbz5n2kfra8p0\Lib\json\encoder.py", line 258, in iterencode
    return _iterencode(o, 0)
           ^^^^^^^^^^^^^^^^^
  File "C:\Program Files\WindowsApps\PythonSoftwareFoundation.Python.3.11_3.11.2544.0_x64__qbz5n2kfra8p0\Lib\json\encoder.py", line 180, in default
    raise TypeError(f'Object of type {o.__class__.__name__} '
TypeError: Object of type ValueError is not JSON serializable
2025-03-02 02:04:17,407 - INFO - Database table created or already exists.
2025-03-02 02:10:10,129 - ERROR - Validation error: [{'type': 'int_parsing', 'loc': ('body', 'year'), 'msg': 'Input should be a valid integer, unable to parse string as an integer', 'input': ''}, {'type': 'float_parsing', 'loc': ('body', 'retail_srp'), 'msg': 'Input should be a valid number, unable to parse string as a number', 'input': ''}]
2025-03-02 02:10:13,286 - ERROR - Validation error: [{'type': 'int_parsing', 'loc': ('body', 'year'), 'msg': 'Input should be a valid integer, unable to parse string as an integer', 'input': ''}, {'type': 'float_parsing', 'loc': ('body', 'retail_srp'), 'msg': 'Input should be a valid number, unable to parse string as a number', 'input': ''}]
2025-03-02 02:12:40,730 - ERROR - Validation error: [{'type': 'value_error', 'loc': ('body', 'year'), 'msg': 'Value error, Invalid year', 'input': 0, 'ctx': {'error': ValueError('Invalid year')}}, {'type': 'value_error', 'loc': ('body', 'retail_srp'), 'msg': 'Value error, Retail SRP must be positive', 'input': 0, 'ctx': {'error': ValueError('Retail SRP must be positive')}}]
2025-03-02 02:12:40,731 - ERROR - Unhandled exception: Object of type ValueError is not JSON serializable
Traceback (most recent call last):
  File "C:\Users\Sobre\OneDrive\Desktop\Vroomble\.venv\Lib\site-packages\starlette\_exception_handler.py", line 42, in wrapped_app
    await app(scope, receive, sender)
  File "C:\Users\Sobre\OneDrive\Desktop\Vroomble\.venv\Lib\site-packages\starlette\routing.py", line 73, in app
    response = await f(request)
               ^^^^^^^^^^^^^^^^
  File "C:\Users\Sobre\OneDrive\Desktop\Vroomble\.venv\Lib\site-packages\fastapi\routing.py", line 346, in app
    raise validation_error
fastapi.exceptions.RequestValidationError: [{'type': 'value_error', 'loc': ('body', 'year'), 'msg': 'Value error, Invalid year', 'input': 0, 'ctx': {'error': ValueError('Invalid year')}}, {'type': 'value_error', 'loc': ('body', 'retail_srp'), 'msg': 'Value error, Retail SRP must be positive', 'input': 0, 'ctx': {'error': ValueError('Retail SRP must be positive')}}]

During handling of the above exception, another exception occurred:

Traceback (most recent call last):
  File "C:\Users\Sobre\OneDrive\Desktop\Vroomble\.venv\Lib\site-packages\starlette\middleware\errors.py", line 165, in __call__
    await self.app(scope, receive, _send)
  File "C:\Users\Sobre\OneDrive\Desktop\Vroomble\.venv\Lib\site-packages\starlette\middleware\cors.py", line 93, in __call__
    await self.simple_response(scope, receive, send, request_headers=headers)
  File "C:\Users\Sobre\OneDrive\Desktop\Vroomble\.venv\Lib\site-packages\starlette\middleware\cors.py", line 144, in simple_response
    await self.app(scope, receive, send)
  File "C:\Users\Sobre\OneDrive\Desktop\Vroomble\.venv\Lib\site-packages\starlette\middleware\exceptions.py", line 62, in __call__
    await wrap_app_handling_exceptions(self.app, conn)(scope, receive, send)
  File "C:\Users\Sobre\OneDrive\Desktop\Vroomble\.venv\Lib\site-packages\starlette\_exception_handler.py", line 53, in wrapped_app
    raise exc
  File "C:\Users\Sobre\OneDrive\Desktop\Vroomble\.venv\Lib\site-packages\starlette\_exception_handler.py", line 42, in wrapped_app
    await app(scope, receive, sender)
  File "C:\Users\Sobre\OneDrive\Desktop\Vroomble\.venv\Lib\site-packages\starlette\routing.py", line 715, in __call__
    await self.middleware_stack(scope, receive, send)
  File "C:\Users\Sobre\OneDrive\Desktop\Vroomble\.venv\Lib\site-packages\starlette\routing.py", line 735, in app
    await route.handle(scope, receive, send)
  File "C:\Users\Sobre\OneDrive\Desktop\Vroomble\.venv\Lib\site-packages\starlette\routing.py", line 288, in handle
    await self.app(scope, receive, send)
  File "C:\Users\Sobre\OneDrive\Desktop\Vroomble\.venv\Lib\site-packages\starlette\routing.py", line 76, in app
    await wrap_app_handling_exceptions(app, request)(scope, receive, send)
  File "C:\Users\Sobre\OneDrive\Desktop\Vroomble\.venv\Lib\site-packages\starlette\_exception_handler.py", line 59, in wrapped_app
    response = await handler(conn, exc)
               ^^^^^^^^^^^^^^^^^^^^^^^^
  File "C:\Users\Sobre\OneDrive\Desktop\Vroomble\src\APIs\vehicle_registration.py", line 172, in validation_exception_handler
    return JSONResponse(
           ^^^^^^^^^^^^^
  File "C:\Users\Sobre\OneDrive\Desktop\Vroomble\.venv\Lib\site-packages\starlette\responses.py", line 181, in __init__
    super().__init__(content, status_code, headers, media_type, background)
  File "C:\Users\Sobre\OneDrive\Desktop\Vroomble\.venv\Lib\site-packages\starlette\responses.py", line 44, in __init__
    self.body = self.render(content)
                ^^^^^^^^^^^^^^^^^^^^
  File "C:\Users\Sobre\OneDrive\Desktop\Vroomble\.venv\Lib\site-packages\starlette\responses.py", line 184, in render
    return json.dumps(
           ^^^^^^^^^^^
  File "C:\Program Files\WindowsApps\PythonSoftwareFoundation.Python.3.11_3.11.2544.0_x64__qbz5n2kfra8p0\Lib\json\__init__.py", line 238, in dumps
    **kw).encode(obj)
          ^^^^^^^^^^^
  File "C:\Program Files\WindowsApps\PythonSoftwareFoundation.Python.3.11_3.11.2544.0_x64__qbz5n2kfra8p0\Lib\json\encoder.py", line 200, in encode
    chunks = self.iterencode(o, _one_shot=True)
             ^^^^^^^^^^^^^^^^^^^^^^^^^^^^^^^^^^
  File "C:\Program Files\WindowsApps\PythonSoftwareFoundation.Python.3.11_3.11.2544.0_x64__qbz5n2kfra8p0\Lib\json\encoder.py", line 258, in iterencode
    return _iterencode(o, 0)
           ^^^^^^^^^^^^^^^^^
  File "C:\Program Files\WindowsApps\PythonSoftwareFoundation.Python.3.11_3.11.2544.0_x64__qbz5n2kfra8p0\Lib\json\encoder.py", line 180, in default
    raise TypeError(f'Object of type {o.__class__.__name__} '
TypeError: Object of type ValueError is not JSON serializable
2025-03-02 02:12:50,339 - ERROR - Validation error: [{'type': 'value_error', 'loc': ('body', 'year'), 'msg': 'Value error, Invalid year', 'input': 0, 'ctx': {'error': ValueError('Invalid year')}}, {'type': 'value_error', 'loc': ('body', 'retail_srp'), 'msg': 'Value error, Retail SRP must be positive', 'input': 0, 'ctx': {'error': ValueError('Retail SRP must be positive')}}]
2025-03-02 02:12:50,339 - ERROR - Unhandled exception: Object of type ValueError is not JSON serializable
Traceback (most recent call last):
  File "C:\Users\Sobre\OneDrive\Desktop\Vroomble\.venv\Lib\site-packages\starlette\_exception_handler.py", line 42, in wrapped_app
    await app(scope, receive, sender)
  File "C:\Users\Sobre\OneDrive\Desktop\Vroomble\.venv\Lib\site-packages\starlette\routing.py", line 73, in app
    response = await f(request)
               ^^^^^^^^^^^^^^^^
  File "C:\Users\Sobre\OneDrive\Desktop\Vroomble\.venv\Lib\site-packages\fastapi\routing.py", line 346, in app
    raise validation_error
fastapi.exceptions.RequestValidationError: [{'type': 'value_error', 'loc': ('body', 'year'), 'msg': 'Value error, Invalid year', 'input': 0, 'ctx': {'error': ValueError('Invalid year')}}, {'type': 'value_error', 'loc': ('body', 'retail_srp'), 'msg': 'Value error, Retail SRP must be positive', 'input': 0, 'ctx': {'error': ValueError('Retail SRP must be positive')}}]

During handling of the above exception, another exception occurred:

Traceback (most recent call last):
  File "C:\Users\Sobre\OneDrive\Desktop\Vroomble\.venv\Lib\site-packages\starlette\middleware\errors.py", line 165, in __call__
    await self.app(scope, receive, _send)
  File "C:\Users\Sobre\OneDrive\Desktop\Vroomble\.venv\Lib\site-packages\starlette\middleware\cors.py", line 93, in __call__
    await self.simple_response(scope, receive, send, request_headers=headers)
  File "C:\Users\Sobre\OneDrive\Desktop\Vroomble\.venv\Lib\site-packages\starlette\middleware\cors.py", line 144, in simple_response
    await self.app(scope, receive, send)
  File "C:\Users\Sobre\OneDrive\Desktop\Vroomble\.venv\Lib\site-packages\starlette\middleware\exceptions.py", line 62, in __call__
    await wrap_app_handling_exceptions(self.app, conn)(scope, receive, send)
  File "C:\Users\Sobre\OneDrive\Desktop\Vroomble\.venv\Lib\site-packages\starlette\_exception_handler.py", line 53, in wrapped_app
    raise exc
  File "C:\Users\Sobre\OneDrive\Desktop\Vroomble\.venv\Lib\site-packages\starlette\_exception_handler.py", line 42, in wrapped_app
    await app(scope, receive, sender)
  File "C:\Users\Sobre\OneDrive\Desktop\Vroomble\.venv\Lib\site-packages\starlette\routing.py", line 715, in __call__
    await self.middleware_stack(scope, receive, send)
  File "C:\Users\Sobre\OneDrive\Desktop\Vroomble\.venv\Lib\site-packages\starlette\routing.py", line 735, in app
    await route.handle(scope, receive, send)
  File "C:\Users\Sobre\OneDrive\Desktop\Vroomble\.venv\Lib\site-packages\starlette\routing.py", line 288, in handle
    await self.app(scope, receive, send)
  File "C:\Users\Sobre\OneDrive\Desktop\Vroomble\.venv\Lib\site-packages\starlette\routing.py", line 76, in app
    await wrap_app_handling_exceptions(app, request)(scope, receive, send)
  File "C:\Users\Sobre\OneDrive\Desktop\Vroomble\.venv\Lib\site-packages\starlette\_exception_handler.py", line 59, in wrapped_app
    response = await handler(conn, exc)
               ^^^^^^^^^^^^^^^^^^^^^^^^
  File "C:\Users\Sobre\OneDrive\Desktop\Vroomble\src\APIs\vehicle_registration.py", line 172, in validation_exception_handler
    return JSONResponse(
           ^^^^^^^^^^^^^
  File "C:\Users\Sobre\OneDrive\Desktop\Vroomble\.venv\Lib\site-packages\starlette\responses.py", line 181, in __init__
    super().__init__(content, status_code, headers, media_type, background)
  File "C:\Users\Sobre\OneDrive\Desktop\Vroomble\.venv\Lib\site-packages\starlette\responses.py", line 44, in __init__
    self.body = self.render(content)
                ^^^^^^^^^^^^^^^^^^^^
  File "C:\Users\Sobre\OneDrive\Desktop\Vroomble\.venv\Lib\site-packages\starlette\responses.py", line 184, in render
    return json.dumps(
           ^^^^^^^^^^^
  File "C:\Program Files\WindowsApps\PythonSoftwareFoundation.Python.3.11_3.11.2544.0_x64__qbz5n2kfra8p0\Lib\json\__init__.py", line 238, in dumps
    **kw).encode(obj)
          ^^^^^^^^^^^
  File "C:\Program Files\WindowsApps\PythonSoftwareFoundation.Python.3.11_3.11.2544.0_x64__qbz5n2kfra8p0\Lib\json\encoder.py", line 200, in encode
    chunks = self.iterencode(o, _one_shot=True)
             ^^^^^^^^^^^^^^^^^^^^^^^^^^^^^^^^^^
  File "C:\Program Files\WindowsApps\PythonSoftwareFoundation.Python.3.11_3.11.2544.0_x64__qbz5n2kfra8p0\Lib\json\encoder.py", line 258, in iterencode
    return _iterencode(o, 0)
           ^^^^^^^^^^^^^^^^^
  File "C:\Program Files\WindowsApps\PythonSoftwareFoundation.Python.3.11_3.11.2544.0_x64__qbz5n2kfra8p0\Lib\json\encoder.py", line 180, in default
    raise TypeError(f'Object of type {o.__class__.__name__} '
TypeError: Object of type ValueError is not JSON serializable
2025-03-02 02:12:54,203 - ERROR - Validation error: [{'type': 'value_error', 'loc': ('body', 'year'), 'msg': 'Value error, Invalid year', 'input': 0, 'ctx': {'error': ValueError('Invalid year')}}, {'type': 'value_error', 'loc': ('body', 'retail_srp'), 'msg': 'Value error, Retail SRP must be positive', 'input': 0, 'ctx': {'error': ValueError('Retail SRP must be positive')}}]
2025-03-02 02:12:54,203 - ERROR - Unhandled exception: Object of type ValueError is not JSON serializable
Traceback (most recent call last):
  File "C:\Users\Sobre\OneDrive\Desktop\Vroomble\.venv\Lib\site-packages\starlette\_exception_handler.py", line 42, in wrapped_app
    await app(scope, receive, sender)
  File "C:\Users\Sobre\OneDrive\Desktop\Vroomble\.venv\Lib\site-packages\starlette\routing.py", line 73, in app
    response = await f(request)
               ^^^^^^^^^^^^^^^^
  File "C:\Users\Sobre\OneDrive\Desktop\Vroomble\.venv\Lib\site-packages\fastapi\routing.py", line 346, in app
    raise validation_error
fastapi.exceptions.RequestValidationError: [{'type': 'value_error', 'loc': ('body', 'year'), 'msg': 'Value error, Invalid year', 'input': 0, 'ctx': {'error': ValueError('Invalid year')}}, {'type': 'value_error', 'loc': ('body', 'retail_srp'), 'msg': 'Value error, Retail SRP must be positive', 'input': 0, 'ctx': {'error': ValueError('Retail SRP must be positive')}}]

During handling of the above exception, another exception occurred:

Traceback (most recent call last):
  File "C:\Users\Sobre\OneDrive\Desktop\Vroomble\.venv\Lib\site-packages\starlette\middleware\errors.py", line 165, in __call__
    await self.app(scope, receive, _send)
  File "C:\Users\Sobre\OneDrive\Desktop\Vroomble\.venv\Lib\site-packages\starlette\middleware\cors.py", line 93, in __call__
    await self.simple_response(scope, receive, send, request_headers=headers)
  File "C:\Users\Sobre\OneDrive\Desktop\Vroomble\.venv\Lib\site-packages\starlette\middleware\cors.py", line 144, in simple_response
    await self.app(scope, receive, send)
  File "C:\Users\Sobre\OneDrive\Desktop\Vroomble\.venv\Lib\site-packages\starlette\middleware\exceptions.py", line 62, in __call__
    await wrap_app_handling_exceptions(self.app, conn)(scope, receive, send)
  File "C:\Users\Sobre\OneDrive\Desktop\Vroomble\.venv\Lib\site-packages\starlette\_exception_handler.py", line 53, in wrapped_app
    raise exc
  File "C:\Users\Sobre\OneDrive\Desktop\Vroomble\.venv\Lib\site-packages\starlette\_exception_handler.py", line 42, in wrapped_app
    await app(scope, receive, sender)
  File "C:\Users\Sobre\OneDrive\Desktop\Vroomble\.venv\Lib\site-packages\starlette\routing.py", line 715, in __call__
    await self.middleware_stack(scope, receive, send)
  File "C:\Users\Sobre\OneDrive\Desktop\Vroomble\.venv\Lib\site-packages\starlette\routing.py", line 735, in app
    await route.handle(scope, receive, send)
  File "C:\Users\Sobre\OneDrive\Desktop\Vroomble\.venv\Lib\site-packages\starlette\routing.py", line 288, in handle
    await self.app(scope, receive, send)
  File "C:\Users\Sobre\OneDrive\Desktop\Vroomble\.venv\Lib\site-packages\starlette\routing.py", line 76, in app
    await wrap_app_handling_exceptions(app, request)(scope, receive, send)
  File "C:\Users\Sobre\OneDrive\Desktop\Vroomble\.venv\Lib\site-packages\starlette\_exception_handler.py", line 59, in wrapped_app
    response = await handler(conn, exc)
               ^^^^^^^^^^^^^^^^^^^^^^^^
  File "C:\Users\Sobre\OneDrive\Desktop\Vroomble\src\APIs\vehicle_registration.py", line 172, in validation_exception_handler
    return JSONResponse(
           ^^^^^^^^^^^^^
  File "C:\Users\Sobre\OneDrive\Desktop\Vroomble\.venv\Lib\site-packages\starlette\responses.py", line 181, in __init__
    super().__init__(content, status_code, headers, media_type, background)
  File "C:\Users\Sobre\OneDrive\Desktop\Vroomble\.venv\Lib\site-packages\starlette\responses.py", line 44, in __init__
    self.body = self.render(content)
                ^^^^^^^^^^^^^^^^^^^^
  File "C:\Users\Sobre\OneDrive\Desktop\Vroomble\.venv\Lib\site-packages\starlette\responses.py", line 184, in render
    return json.dumps(
           ^^^^^^^^^^^
  File "C:\Program Files\WindowsApps\PythonSoftwareFoundation.Python.3.11_3.11.2544.0_x64__qbz5n2kfra8p0\Lib\json\__init__.py", line 238, in dumps
    **kw).encode(obj)
          ^^^^^^^^^^^
  File "C:\Program Files\WindowsApps\PythonSoftwareFoundation.Python.3.11_3.11.2544.0_x64__qbz5n2kfra8p0\Lib\json\encoder.py", line 200, in encode
    chunks = self.iterencode(o, _one_shot=True)
             ^^^^^^^^^^^^^^^^^^^^^^^^^^^^^^^^^^
  File "C:\Program Files\WindowsApps\PythonSoftwareFoundation.Python.3.11_3.11.2544.0_x64__qbz5n2kfra8p0\Lib\json\encoder.py", line 258, in iterencode
    return _iterencode(o, 0)
           ^^^^^^^^^^^^^^^^^
  File "C:\Program Files\WindowsApps\PythonSoftwareFoundation.Python.3.11_3.11.2544.0_x64__qbz5n2kfra8p0\Lib\json\encoder.py", line 180, in default
    raise TypeError(f'Object of type {o.__class__.__name__} '
TypeError: Object of type ValueError is not JSON serializable
2025-03-02 02:12:56,907 - ERROR - Validation error: [{'type': 'value_error', 'loc': ('body', 'year'), 'msg': 'Value error, Invalid year', 'input': 0, 'ctx': {'error': ValueError('Invalid year')}}, {'type': 'value_error', 'loc': ('body', 'retail_srp'), 'msg': 'Value error, Retail SRP must be positive', 'input': 0, 'ctx': {'error': ValueError('Retail SRP must be positive')}}]
2025-03-02 02:12:56,907 - ERROR - Unhandled exception: Object of type ValueError is not JSON serializable
Traceback (most recent call last):
  File "C:\Users\Sobre\OneDrive\Desktop\Vroomble\.venv\Lib\site-packages\starlette\_exception_handler.py", line 42, in wrapped_app
    await app(scope, receive, sender)
  File "C:\Users\Sobre\OneDrive\Desktop\Vroomble\.venv\Lib\site-packages\starlette\routing.py", line 73, in app
    response = await f(request)
               ^^^^^^^^^^^^^^^^
  File "C:\Users\Sobre\OneDrive\Desktop\Vroomble\.venv\Lib\site-packages\fastapi\routing.py", line 346, in app
    raise validation_error
fastapi.exceptions.RequestValidationError: [{'type': 'value_error', 'loc': ('body', 'year'), 'msg': 'Value error, Invalid year', 'input': 0, 'ctx': {'error': ValueError('Invalid year')}}, {'type': 'value_error', 'loc': ('body', 'retail_srp'), 'msg': 'Value error, Retail SRP must be positive', 'input': 0, 'ctx': {'error': ValueError('Retail SRP must be positive')}}]

During handling of the above exception, another exception occurred:

Traceback (most recent call last):
  File "C:\Users\Sobre\OneDrive\Desktop\Vroomble\.venv\Lib\site-packages\starlette\middleware\errors.py", line 165, in __call__
    await self.app(scope, receive, _send)
  File "C:\Users\Sobre\OneDrive\Desktop\Vroomble\.venv\Lib\site-packages\starlette\middleware\cors.py", line 93, in __call__
    await self.simple_response(scope, receive, send, request_headers=headers)
  File "C:\Users\Sobre\OneDrive\Desktop\Vroomble\.venv\Lib\site-packages\starlette\middleware\cors.py", line 144, in simple_response
    await self.app(scope, receive, send)
  File "C:\Users\Sobre\OneDrive\Desktop\Vroomble\.venv\Lib\site-packages\starlette\middleware\exceptions.py", line 62, in __call__
    await wrap_app_handling_exceptions(self.app, conn)(scope, receive, send)
  File "C:\Users\Sobre\OneDrive\Desktop\Vroomble\.venv\Lib\site-packages\starlette\_exception_handler.py", line 53, in wrapped_app
    raise exc
  File "C:\Users\Sobre\OneDrive\Desktop\Vroomble\.venv\Lib\site-packages\starlette\_exception_handler.py", line 42, in wrapped_app
    await app(scope, receive, sender)
  File "C:\Users\Sobre\OneDrive\Desktop\Vroomble\.venv\Lib\site-packages\starlette\routing.py", line 715, in __call__
    await self.middleware_stack(scope, receive, send)
  File "C:\Users\Sobre\OneDrive\Desktop\Vroomble\.venv\Lib\site-packages\starlette\routing.py", line 735, in app
    await route.handle(scope, receive, send)
  File "C:\Users\Sobre\OneDrive\Desktop\Vroomble\.venv\Lib\site-packages\starlette\routing.py", line 288, in handle
    await self.app(scope, receive, send)
  File "C:\Users\Sobre\OneDrive\Desktop\Vroomble\.venv\Lib\site-packages\starlette\routing.py", line 76, in app
    await wrap_app_handling_exceptions(app, request)(scope, receive, send)
  File "C:\Users\Sobre\OneDrive\Desktop\Vroomble\.venv\Lib\site-packages\starlette\_exception_handler.py", line 59, in wrapped_app
    response = await handler(conn, exc)
               ^^^^^^^^^^^^^^^^^^^^^^^^
  File "C:\Users\Sobre\OneDrive\Desktop\Vroomble\src\APIs\vehicle_registration.py", line 172, in validation_exception_handler
    return JSONResponse(
           ^^^^^^^^^^^^^
  File "C:\Users\Sobre\OneDrive\Desktop\Vroomble\.venv\Lib\site-packages\starlette\responses.py", line 181, in __init__
    super().__init__(content, status_code, headers, media_type, background)
  File "C:\Users\Sobre\OneDrive\Desktop\Vroomble\.venv\Lib\site-packages\starlette\responses.py", line 44, in __init__
    self.body = self.render(content)
                ^^^^^^^^^^^^^^^^^^^^
  File "C:\Users\Sobre\OneDrive\Desktop\Vroomble\.venv\Lib\site-packages\starlette\responses.py", line 184, in render
    return json.dumps(
           ^^^^^^^^^^^
  File "C:\Program Files\WindowsApps\PythonSoftwareFoundation.Python.3.11_3.11.2544.0_x64__qbz5n2kfra8p0\Lib\json\__init__.py", line 238, in dumps
    **kw).encode(obj)
          ^^^^^^^^^^^
  File "C:\Program Files\WindowsApps\PythonSoftwareFoundation.Python.3.11_3.11.2544.0_x64__qbz5n2kfra8p0\Lib\json\encoder.py", line 200, in encode
    chunks = self.iterencode(o, _one_shot=True)
             ^^^^^^^^^^^^^^^^^^^^^^^^^^^^^^^^^^
  File "C:\Program Files\WindowsApps\PythonSoftwareFoundation.Python.3.11_3.11.2544.0_x64__qbz5n2kfra8p0\Lib\json\encoder.py", line 258, in iterencode
    return _iterencode(o, 0)
           ^^^^^^^^^^^^^^^^^
  File "C:\Program Files\WindowsApps\PythonSoftwareFoundation.Python.3.11_3.11.2544.0_x64__qbz5n2kfra8p0\Lib\json\encoder.py", line 180, in default
    raise TypeError(f'Object of type {o.__class__.__name__} '
TypeError: Object of type ValueError is not JSON serializable
2025-03-02 02:12:59,774 - ERROR - Validation error: [{'type': 'value_error', 'loc': ('body', 'year'), 'msg': 'Value error, Invalid year', 'input': 0, 'ctx': {'error': ValueError('Invalid year')}}, {'type': 'value_error', 'loc': ('body', 'retail_srp'), 'msg': 'Value error, Retail SRP must be positive', 'input': 0, 'ctx': {'error': ValueError('Retail SRP must be positive')}}]
2025-03-02 02:12:59,774 - ERROR - Unhandled exception: Object of type ValueError is not JSON serializable
Traceback (most recent call last):
  File "C:\Users\Sobre\OneDrive\Desktop\Vroomble\.venv\Lib\site-packages\starlette\_exception_handler.py", line 42, in wrapped_app
    await app(scope, receive, sender)
  File "C:\Users\Sobre\OneDrive\Desktop\Vroomble\.venv\Lib\site-packages\starlette\routing.py", line 73, in app
    response = await f(request)
               ^^^^^^^^^^^^^^^^
  File "C:\Users\Sobre\OneDrive\Desktop\Vroomble\.venv\Lib\site-packages\fastapi\routing.py", line 346, in app
    raise validation_error
fastapi.exceptions.RequestValidationError: [{'type': 'value_error', 'loc': ('body', 'year'), 'msg': 'Value error, Invalid year', 'input': 0, 'ctx': {'error': ValueError('Invalid year')}}, {'type': 'value_error', 'loc': ('body', 'retail_srp'), 'msg': 'Value error, Retail SRP must be positive', 'input': 0, 'ctx': {'error': ValueError('Retail SRP must be positive')}}]

During handling of the above exception, another exception occurred:

Traceback (most recent call last):
  File "C:\Users\Sobre\OneDrive\Desktop\Vroomble\.venv\Lib\site-packages\starlette\middleware\errors.py", line 165, in __call__
    await self.app(scope, receive, _send)
  File "C:\Users\Sobre\OneDrive\Desktop\Vroomble\.venv\Lib\site-packages\starlette\middleware\cors.py", line 93, in __call__
    await self.simple_response(scope, receive, send, request_headers=headers)
  File "C:\Users\Sobre\OneDrive\Desktop\Vroomble\.venv\Lib\site-packages\starlette\middleware\cors.py", line 144, in simple_response
    await self.app(scope, receive, send)
  File "C:\Users\Sobre\OneDrive\Desktop\Vroomble\.venv\Lib\site-packages\starlette\middleware\exceptions.py", line 62, in __call__
    await wrap_app_handling_exceptions(self.app, conn)(scope, receive, send)
  File "C:\Users\Sobre\OneDrive\Desktop\Vroomble\.venv\Lib\site-packages\starlette\_exception_handler.py", line 53, in wrapped_app
    raise exc
  File "C:\Users\Sobre\OneDrive\Desktop\Vroomble\.venv\Lib\site-packages\starlette\_exception_handler.py", line 42, in wrapped_app
    await app(scope, receive, sender)
  File "C:\Users\Sobre\OneDrive\Desktop\Vroomble\.venv\Lib\site-packages\starlette\routing.py", line 715, in __call__
    await self.middleware_stack(scope, receive, send)
  File "C:\Users\Sobre\OneDrive\Desktop\Vroomble\.venv\Lib\site-packages\starlette\routing.py", line 735, in app
    await route.handle(scope, receive, send)
  File "C:\Users\Sobre\OneDrive\Desktop\Vroomble\.venv\Lib\site-packages\starlette\routing.py", line 288, in handle
    await self.app(scope, receive, send)
  File "C:\Users\Sobre\OneDrive\Desktop\Vroomble\.venv\Lib\site-packages\starlette\routing.py", line 76, in app
    await wrap_app_handling_exceptions(app, request)(scope, receive, send)
  File "C:\Users\Sobre\OneDrive\Desktop\Vroomble\.venv\Lib\site-packages\starlette\_exception_handler.py", line 59, in wrapped_app
    response = await handler(conn, exc)
               ^^^^^^^^^^^^^^^^^^^^^^^^
  File "C:\Users\Sobre\OneDrive\Desktop\Vroomble\src\APIs\vehicle_registration.py", line 172, in validation_exception_handler
    return JSONResponse(
           ^^^^^^^^^^^^^
  File "C:\Users\Sobre\OneDrive\Desktop\Vroomble\.venv\Lib\site-packages\starlette\responses.py", line 181, in __init__
    super().__init__(content, status_code, headers, media_type, background)
  File "C:\Users\Sobre\OneDrive\Desktop\Vroomble\.venv\Lib\site-packages\starlette\responses.py", line 44, in __init__
    self.body = self.render(content)
                ^^^^^^^^^^^^^^^^^^^^
  File "C:\Users\Sobre\OneDrive\Desktop\Vroomble\.venv\Lib\site-packages\starlette\responses.py", line 184, in render
    return json.dumps(
           ^^^^^^^^^^^
  File "C:\Program Files\WindowsApps\PythonSoftwareFoundation.Python.3.11_3.11.2544.0_x64__qbz5n2kfra8p0\Lib\json\__init__.py", line 238, in dumps
    **kw).encode(obj)
          ^^^^^^^^^^^
  File "C:\Program Files\WindowsApps\PythonSoftwareFoundation.Python.3.11_3.11.2544.0_x64__qbz5n2kfra8p0\Lib\json\encoder.py", line 200, in encode
    chunks = self.iterencode(o, _one_shot=True)
             ^^^^^^^^^^^^^^^^^^^^^^^^^^^^^^^^^^
  File "C:\Program Files\WindowsApps\PythonSoftwareFoundation.Python.3.11_3.11.2544.0_x64__qbz5n2kfra8p0\Lib\json\encoder.py", line 258, in iterencode
    return _iterencode(o, 0)
           ^^^^^^^^^^^^^^^^^
  File "C:\Program Files\WindowsApps\PythonSoftwareFoundation.Python.3.11_3.11.2544.0_x64__qbz5n2kfra8p0\Lib\json\encoder.py", line 180, in default
    raise TypeError(f'Object of type {o.__class__.__name__} '
TypeError: Object of type ValueError is not JSON serializable
2025-03-02 02:13:02,454 - ERROR - Validation error: [{'type': 'value_error', 'loc': ('body', 'year'), 'msg': 'Value error, Invalid year', 'input': 0, 'ctx': {'error': ValueError('Invalid year')}}, {'type': 'value_error', 'loc': ('body', 'retail_srp'), 'msg': 'Value error, Retail SRP must be positive', 'input': 0, 'ctx': {'error': ValueError('Retail SRP must be positive')}}]
2025-03-02 02:13:02,454 - ERROR - Unhandled exception: Object of type ValueError is not JSON serializable
Traceback (most recent call last):
  File "C:\Users\Sobre\OneDrive\Desktop\Vroomble\.venv\Lib\site-packages\starlette\_exception_handler.py", line 42, in wrapped_app
    await app(scope, receive, sender)
  File "C:\Users\Sobre\OneDrive\Desktop\Vroomble\.venv\Lib\site-packages\starlette\routing.py", line 73, in app
    response = await f(request)
               ^^^^^^^^^^^^^^^^
  File "C:\Users\Sobre\OneDrive\Desktop\Vroomble\.venv\Lib\site-packages\fastapi\routing.py", line 346, in app
    raise validation_error
fastapi.exceptions.RequestValidationError: [{'type': 'value_error', 'loc': ('body', 'year'), 'msg': 'Value error, Invalid year', 'input': 0, 'ctx': {'error': ValueError('Invalid year')}}, {'type': 'value_error', 'loc': ('body', 'retail_srp'), 'msg': 'Value error, Retail SRP must be positive', 'input': 0, 'ctx': {'error': ValueError('Retail SRP must be positive')}}]

During handling of the above exception, another exception occurred:

Traceback (most recent call last):
  File "C:\Users\Sobre\OneDrive\Desktop\Vroomble\.venv\Lib\site-packages\starlette\middleware\errors.py", line 165, in __call__
    await self.app(scope, receive, _send)
  File "C:\Users\Sobre\OneDrive\Desktop\Vroomble\.venv\Lib\site-packages\starlette\middleware\cors.py", line 93, in __call__
    await self.simple_response(scope, receive, send, request_headers=headers)
  File "C:\Users\Sobre\OneDrive\Desktop\Vroomble\.venv\Lib\site-packages\starlette\middleware\cors.py", line 144, in simple_response
    await self.app(scope, receive, send)
  File "C:\Users\Sobre\OneDrive\Desktop\Vroomble\.venv\Lib\site-packages\starlette\middleware\exceptions.py", line 62, in __call__
    await wrap_app_handling_exceptions(self.app, conn)(scope, receive, send)
  File "C:\Users\Sobre\OneDrive\Desktop\Vroomble\.venv\Lib\site-packages\starlette\_exception_handler.py", line 53, in wrapped_app
    raise exc
  File "C:\Users\Sobre\OneDrive\Desktop\Vroomble\.venv\Lib\site-packages\starlette\_exception_handler.py", line 42, in wrapped_app
    await app(scope, receive, sender)
  File "C:\Users\Sobre\OneDrive\Desktop\Vroomble\.venv\Lib\site-packages\starlette\routing.py", line 715, in __call__
    await self.middleware_stack(scope, receive, send)
  File "C:\Users\Sobre\OneDrive\Desktop\Vroomble\.venv\Lib\site-packages\starlette\routing.py", line 735, in app
    await route.handle(scope, receive, send)
  File "C:\Users\Sobre\OneDrive\Desktop\Vroomble\.venv\Lib\site-packages\starlette\routing.py", line 288, in handle
    await self.app(scope, receive, send)
  File "C:\Users\Sobre\OneDrive\Desktop\Vroomble\.venv\Lib\site-packages\starlette\routing.py", line 76, in app
    await wrap_app_handling_exceptions(app, request)(scope, receive, send)
  File "C:\Users\Sobre\OneDrive\Desktop\Vroomble\.venv\Lib\site-packages\starlette\_exception_handler.py", line 59, in wrapped_app
    response = await handler(conn, exc)
               ^^^^^^^^^^^^^^^^^^^^^^^^
  File "C:\Users\Sobre\OneDrive\Desktop\Vroomble\src\APIs\vehicle_registration.py", line 172, in validation_exception_handler
    return JSONResponse(
           ^^^^^^^^^^^^^
  File "C:\Users\Sobre\OneDrive\Desktop\Vroomble\.venv\Lib\site-packages\starlette\responses.py", line 181, in __init__
    super().__init__(content, status_code, headers, media_type, background)
  File "C:\Users\Sobre\OneDrive\Desktop\Vroomble\.venv\Lib\site-packages\starlette\responses.py", line 44, in __init__
    self.body = self.render(content)
                ^^^^^^^^^^^^^^^^^^^^
  File "C:\Users\Sobre\OneDrive\Desktop\Vroomble\.venv\Lib\site-packages\starlette\responses.py", line 184, in render
    return json.dumps(
           ^^^^^^^^^^^
  File "C:\Program Files\WindowsApps\PythonSoftwareFoundation.Python.3.11_3.11.2544.0_x64__qbz5n2kfra8p0\Lib\json\__init__.py", line 238, in dumps
    **kw).encode(obj)
          ^^^^^^^^^^^
  File "C:\Program Files\WindowsApps\PythonSoftwareFoundation.Python.3.11_3.11.2544.0_x64__qbz5n2kfra8p0\Lib\json\encoder.py", line 200, in encode
    chunks = self.iterencode(o, _one_shot=True)
             ^^^^^^^^^^^^^^^^^^^^^^^^^^^^^^^^^^
  File "C:\Program Files\WindowsApps\PythonSoftwareFoundation.Python.3.11_3.11.2544.0_x64__qbz5n2kfra8p0\Lib\json\encoder.py", line 258, in iterencode
    return _iterencode(o, 0)
           ^^^^^^^^^^^^^^^^^
  File "C:\Program Files\WindowsApps\PythonSoftwareFoundation.Python.3.11_3.11.2544.0_x64__qbz5n2kfra8p0\Lib\json\encoder.py", line 180, in default
    raise TypeError(f'Object of type {o.__class__.__name__} '
TypeError: Object of type ValueError is not JSON serializable
2025-03-02 02:13:48,125 - ERROR - Validation error: [{'type': 'value_error', 'loc': ('body', 'year'), 'msg': 'Value error, Invalid year', 'input': 0, 'ctx': {'error': ValueError('Invalid year')}}, {'type': 'value_error', 'loc': ('body', 'retail_srp'), 'msg': 'Value error, Retail SRP must be positive', 'input': 0, 'ctx': {'error': ValueError('Retail SRP must be positive')}}]
2025-03-02 02:13:48,125 - ERROR - Unhandled exception: Object of type ValueError is not JSON serializable
Traceback (most recent call last):
  File "C:\Users\Sobre\OneDrive\Desktop\Vroomble\.venv\Lib\site-packages\starlette\_exception_handler.py", line 42, in wrapped_app
    await app(scope, receive, sender)
  File "C:\Users\Sobre\OneDrive\Desktop\Vroomble\.venv\Lib\site-packages\starlette\routing.py", line 73, in app
    response = await f(request)
               ^^^^^^^^^^^^^^^^
  File "C:\Users\Sobre\OneDrive\Desktop\Vroomble\.venv\Lib\site-packages\fastapi\routing.py", line 346, in app
    raise validation_error
fastapi.exceptions.RequestValidationError: [{'type': 'value_error', 'loc': ('body', 'year'), 'msg': 'Value error, Invalid year', 'input': 0, 'ctx': {'error': ValueError('Invalid year')}}, {'type': 'value_error', 'loc': ('body', 'retail_srp'), 'msg': 'Value error, Retail SRP must be positive', 'input': 0, 'ctx': {'error': ValueError('Retail SRP must be positive')}}]

During handling of the above exception, another exception occurred:

Traceback (most recent call last):
  File "C:\Users\Sobre\OneDrive\Desktop\Vroomble\.venv\Lib\site-packages\starlette\middleware\errors.py", line 165, in __call__
    await self.app(scope, receive, _send)
  File "C:\Users\Sobre\OneDrive\Desktop\Vroomble\.venv\Lib\site-packages\starlette\middleware\cors.py", line 93, in __call__
    await self.simple_response(scope, receive, send, request_headers=headers)
  File "C:\Users\Sobre\OneDrive\Desktop\Vroomble\.venv\Lib\site-packages\starlette\middleware\cors.py", line 144, in simple_response
    await self.app(scope, receive, send)
  File "C:\Users\Sobre\OneDrive\Desktop\Vroomble\.venv\Lib\site-packages\starlette\middleware\exceptions.py", line 62, in __call__
    await wrap_app_handling_exceptions(self.app, conn)(scope, receive, send)
  File "C:\Users\Sobre\OneDrive\Desktop\Vroomble\.venv\Lib\site-packages\starlette\_exception_handler.py", line 53, in wrapped_app
    raise exc
  File "C:\Users\Sobre\OneDrive\Desktop\Vroomble\.venv\Lib\site-packages\starlette\_exception_handler.py", line 42, in wrapped_app
    await app(scope, receive, sender)
  File "C:\Users\Sobre\OneDrive\Desktop\Vroomble\.venv\Lib\site-packages\starlette\routing.py", line 715, in __call__
    await self.middleware_stack(scope, receive, send)
  File "C:\Users\Sobre\OneDrive\Desktop\Vroomble\.venv\Lib\site-packages\starlette\routing.py", line 735, in app
    await route.handle(scope, receive, send)
  File "C:\Users\Sobre\OneDrive\Desktop\Vroomble\.venv\Lib\site-packages\starlette\routing.py", line 288, in handle
    await self.app(scope, receive, send)
  File "C:\Users\Sobre\OneDrive\Desktop\Vroomble\.venv\Lib\site-packages\starlette\routing.py", line 76, in app
    await wrap_app_handling_exceptions(app, request)(scope, receive, send)
  File "C:\Users\Sobre\OneDrive\Desktop\Vroomble\.venv\Lib\site-packages\starlette\_exception_handler.py", line 59, in wrapped_app
    response = await handler(conn, exc)
               ^^^^^^^^^^^^^^^^^^^^^^^^
  File "C:\Users\Sobre\OneDrive\Desktop\Vroomble\src\APIs\vehicle_registration.py", line 172, in validation_exception_handler
    return JSONResponse(
           ^^^^^^^^^^^^^
  File "C:\Users\Sobre\OneDrive\Desktop\Vroomble\.venv\Lib\site-packages\starlette\responses.py", line 181, in __init__
    super().__init__(content, status_code, headers, media_type, background)
  File "C:\Users\Sobre\OneDrive\Desktop\Vroomble\.venv\Lib\site-packages\starlette\responses.py", line 44, in __init__
    self.body = self.render(content)
                ^^^^^^^^^^^^^^^^^^^^
  File "C:\Users\Sobre\OneDrive\Desktop\Vroomble\.venv\Lib\site-packages\starlette\responses.py", line 184, in render
    return json.dumps(
           ^^^^^^^^^^^
  File "C:\Program Files\WindowsApps\PythonSoftwareFoundation.Python.3.11_3.11.2544.0_x64__qbz5n2kfra8p0\Lib\json\__init__.py", line 238, in dumps
    **kw).encode(obj)
          ^^^^^^^^^^^
  File "C:\Program Files\WindowsApps\PythonSoftwareFoundation.Python.3.11_3.11.2544.0_x64__qbz5n2kfra8p0\Lib\json\encoder.py", line 200, in encode
    chunks = self.iterencode(o, _one_shot=True)
             ^^^^^^^^^^^^^^^^^^^^^^^^^^^^^^^^^^
  File "C:\Program Files\WindowsApps\PythonSoftwareFoundation.Python.3.11_3.11.2544.0_x64__qbz5n2kfra8p0\Lib\json\encoder.py", line 258, in iterencode
    return _iterencode(o, 0)
           ^^^^^^^^^^^^^^^^^
  File "C:\Program Files\WindowsApps\PythonSoftwareFoundation.Python.3.11_3.11.2544.0_x64__qbz5n2kfra8p0\Lib\json\encoder.py", line 180, in default
    raise TypeError(f'Object of type {o.__class__.__name__} '
TypeError: Object of type ValueError is not JSON serializable
2025-03-02 02:17:22,284 - INFO - Database table created or already exists.
2025-03-02 02:17:35,022 - ERROR - Validation error: [{'type': 'value_error', 'loc': ('body', 'year'), 'msg': 'Value error, Invalid year', 'input': 0, 'ctx': {'error': ValueError('Invalid year')}}, {'type': 'value_error', 'loc': ('body', 'retail_srp'), 'msg': 'Value error, Retail SRP must be positive', 'input': 0, 'ctx': {'error': ValueError('Retail SRP must be positive')}}]
2025-03-02 02:17:35,022 - ERROR - Unhandled exception: Object of type ValueError is not JSON serializable
Traceback (most recent call last):
  File "C:\Users\Sobre\OneDrive\Desktop\Vroomble\.venv\Lib\site-packages\starlette\_exception_handler.py", line 42, in wrapped_app
    await app(scope, receive, sender)
  File "C:\Users\Sobre\OneDrive\Desktop\Vroomble\.venv\Lib\site-packages\starlette\routing.py", line 73, in app
    response = await f(request)
               ^^^^^^^^^^^^^^^^
  File "C:\Users\Sobre\OneDrive\Desktop\Vroomble\.venv\Lib\site-packages\fastapi\routing.py", line 346, in app
    raise validation_error
fastapi.exceptions.RequestValidationError: [{'type': 'value_error', 'loc': ('body', 'year'), 'msg': 'Value error, Invalid year', 'input': 0, 'ctx': {'error': ValueError('Invalid year')}}, {'type': 'value_error', 'loc': ('body', 'retail_srp'), 'msg': 'Value error, Retail SRP must be positive', 'input': 0, 'ctx': {'error': ValueError('Retail SRP must be positive')}}]

During handling of the above exception, another exception occurred:

Traceback (most recent call last):
  File "C:\Users\Sobre\OneDrive\Desktop\Vroomble\.venv\Lib\site-packages\starlette\middleware\errors.py", line 165, in __call__
    await self.app(scope, receive, _send)
  File "C:\Users\Sobre\OneDrive\Desktop\Vroomble\.venv\Lib\site-packages\starlette\middleware\cors.py", line 93, in __call__
    await self.simple_response(scope, receive, send, request_headers=headers)
  File "C:\Users\Sobre\OneDrive\Desktop\Vroomble\.venv\Lib\site-packages\starlette\middleware\cors.py", line 144, in simple_response
    await self.app(scope, receive, send)
  File "C:\Users\Sobre\OneDrive\Desktop\Vroomble\.venv\Lib\site-packages\starlette\middleware\exceptions.py", line 62, in __call__
    await wrap_app_handling_exceptions(self.app, conn)(scope, receive, send)
  File "C:\Users\Sobre\OneDrive\Desktop\Vroomble\.venv\Lib\site-packages\starlette\_exception_handler.py", line 53, in wrapped_app
    raise exc
  File "C:\Users\Sobre\OneDrive\Desktop\Vroomble\.venv\Lib\site-packages\starlette\_exception_handler.py", line 42, in wrapped_app
    await app(scope, receive, sender)
  File "C:\Users\Sobre\OneDrive\Desktop\Vroomble\.venv\Lib\site-packages\starlette\routing.py", line 715, in __call__
    await self.middleware_stack(scope, receive, send)
  File "C:\Users\Sobre\OneDrive\Desktop\Vroomble\.venv\Lib\site-packages\starlette\routing.py", line 735, in app
    await route.handle(scope, receive, send)
  File "C:\Users\Sobre\OneDrive\Desktop\Vroomble\.venv\Lib\site-packages\starlette\routing.py", line 288, in handle
    await self.app(scope, receive, send)
  File "C:\Users\Sobre\OneDrive\Desktop\Vroomble\.venv\Lib\site-packages\starlette\routing.py", line 76, in app
    await wrap_app_handling_exceptions(app, request)(scope, receive, send)
  File "C:\Users\Sobre\OneDrive\Desktop\Vroomble\.venv\Lib\site-packages\starlette\_exception_handler.py", line 59, in wrapped_app
    response = await handler(conn, exc)
               ^^^^^^^^^^^^^^^^^^^^^^^^
  File "C:\Users\Sobre\OneDrive\Desktop\Vroomble\src\APIs\vehicle_registration.py", line 172, in validation_exception_handler
    return JSONResponse(
           ^^^^^^^^^^^^^
  File "C:\Users\Sobre\OneDrive\Desktop\Vroomble\.venv\Lib\site-packages\starlette\responses.py", line 181, in __init__
    super().__init__(content, status_code, headers, media_type, background)
  File "C:\Users\Sobre\OneDrive\Desktop\Vroomble\.venv\Lib\site-packages\starlette\responses.py", line 44, in __init__
    self.body = self.render(content)
                ^^^^^^^^^^^^^^^^^^^^
  File "C:\Users\Sobre\OneDrive\Desktop\Vroomble\.venv\Lib\site-packages\starlette\responses.py", line 184, in render
    return json.dumps(
           ^^^^^^^^^^^
  File "C:\Program Files\WindowsApps\PythonSoftwareFoundation.Python.3.11_3.11.2544.0_x64__qbz5n2kfra8p0\Lib\json\__init__.py", line 238, in dumps
    **kw).encode(obj)
          ^^^^^^^^^^^
  File "C:\Program Files\WindowsApps\PythonSoftwareFoundation.Python.3.11_3.11.2544.0_x64__qbz5n2kfra8p0\Lib\json\encoder.py", line 200, in encode
    chunks = self.iterencode(o, _one_shot=True)
             ^^^^^^^^^^^^^^^^^^^^^^^^^^^^^^^^^^
  File "C:\Program Files\WindowsApps\PythonSoftwareFoundation.Python.3.11_3.11.2544.0_x64__qbz5n2kfra8p0\Lib\json\encoder.py", line 258, in iterencode
    return _iterencode(o, 0)
           ^^^^^^^^^^^^^^^^^
  File "C:\Program Files\WindowsApps\PythonSoftwareFoundation.Python.3.11_3.11.2544.0_x64__qbz5n2kfra8p0\Lib\json\encoder.py", line 180, in default
    raise TypeError(f'Object of type {o.__class__.__name__} '
TypeError: Object of type ValueError is not JSON serializable
2025-03-02 02:20:04,008 - INFO - Database table created or already exists.
2025-03-02 08:40:12,272 - INFO - Database table created or already exists.
2025-03-02 10:17:08,627 - INFO - Database table created or already exists.
2025-03-02 10:19:55,246 - INFO - Database and table created successfully (if not already existing).
2025-03-02 10:22:08,438 - INFO - Database and table created successfully (if not already existing).
2025-03-02 10:25:02,177 - INFO - Database and table created successfully (if not already existing).
2025-03-02 10:26:47,810 - INFO - Database and table created successfully (if not already existing).
2025-03-02 10:27:09,702 - INFO - Executing SQL: 
            INSERT INTO cars (Make, Model, Body_Type, Transmission, Drivetrain, Fuel_Type, Year, Retail_SRP, Variant)
            VALUES (?, ?, ?, ?, ?, ?, ?, ?, ?)
         with values ('TOYOTA', 'FORTUNER', 'SUV', 'CVT', 'RWD', 'Diesel', 2014, '1300000.00', 'G')
2025-03-02 10:27:09,706 - INFO - Car added successfully: make='TOYOTA' model='FORTUNER' body_type='SUV' variant='G' transmission='CVT' drivetrain='RWD' fuel_type='Diesel' year=2014 retail_srp=1300000.0
2025-03-02 10:29:37,288 - INFO - Executing SQL: 
            INSERT INTO cars (Make, Model, Body_Type, Transmission, Drivetrain, Fuel_Type, Year, Retail_SRP, Variant)
            VALUES (?, ?, ?, ?, ?, ?, ?, ?, ?)
         with values ('MOTOLITE', 'FORTUNER', 'SUV', 'CVT', 'RWD', '', 2014, '1300000.00', 'G')
2025-03-02 10:29:37,291 - INFO - Car added successfully: make='MOTOLITE' model='FORTUNER' body_type='SUV' variant='G' transmission='CVT' drivetrain='RWD' fuel_type='' year=2014 retail_srp=1300000.0
2025-03-02 10:30:19,010 - INFO - Database and table created successfully (if not already existing).
2025-03-02 10:41:21,948 - INFO - Database and table created successfully (if not already existing).
2025-03-02 11:17:26,347 - INFO - Database and table created successfully (if not already existing).
2025-03-02 11:19:33,832 - INFO - Database and table created successfully (if not already existing).
2025-03-02 11:21:03,829 - ERROR - Unhandled exception: Expecting value: line 1 column 1 (char 0)
Traceback (most recent call last):
  File "C:\Users\Sobre\OneDrive\Desktop\Vroomble\.venv\Lib\site-packages\starlette\middleware\errors.py", line 165, in __call__
    await self.app(scope, receive, _send)
  File "C:\Users\Sobre\OneDrive\Desktop\Vroomble\.venv\Lib\site-packages\starlette\middleware\cors.py", line 93, in __call__
    await self.simple_response(scope, receive, send, request_headers=headers)
  File "C:\Users\Sobre\OneDrive\Desktop\Vroomble\.venv\Lib\site-packages\starlette\middleware\cors.py", line 144, in simple_response
    await self.app(scope, receive, send)
  File "C:\Users\Sobre\OneDrive\Desktop\Vroomble\.venv\Lib\site-packages\starlette\middleware\exceptions.py", line 62, in __call__
    await wrap_app_handling_exceptions(self.app, conn)(scope, receive, send)
  File "C:\Users\Sobre\OneDrive\Desktop\Vroomble\.venv\Lib\site-packages\starlette\_exception_handler.py", line 53, in wrapped_app
    raise exc
  File "C:\Users\Sobre\OneDrive\Desktop\Vroomble\.venv\Lib\site-packages\starlette\_exception_handler.py", line 42, in wrapped_app
    await app(scope, receive, sender)
  File "C:\Users\Sobre\OneDrive\Desktop\Vroomble\.venv\Lib\site-packages\starlette\routing.py", line 715, in __call__
    await self.middleware_stack(scope, receive, send)
  File "C:\Users\Sobre\OneDrive\Desktop\Vroomble\.venv\Lib\site-packages\starlette\routing.py", line 735, in app
    await route.handle(scope, receive, send)
  File "C:\Users\Sobre\OneDrive\Desktop\Vroomble\.venv\Lib\site-packages\starlette\routing.py", line 288, in handle
    await self.app(scope, receive, send)
  File "C:\Users\Sobre\OneDrive\Desktop\Vroomble\.venv\Lib\site-packages\starlette\routing.py", line 76, in app
    await wrap_app_handling_exceptions(app, request)(scope, receive, send)
  File "C:\Users\Sobre\OneDrive\Desktop\Vroomble\.venv\Lib\site-packages\starlette\_exception_handler.py", line 53, in wrapped_app
    raise exc
  File "C:\Users\Sobre\OneDrive\Desktop\Vroomble\.venv\Lib\site-packages\starlette\_exception_handler.py", line 42, in wrapped_app
    await app(scope, receive, sender)
  File "C:\Users\Sobre\OneDrive\Desktop\Vroomble\.venv\Lib\site-packages\starlette\routing.py", line 73, in app
    response = await f(request)
               ^^^^^^^^^^^^^^^^
  File "C:\Users\Sobre\OneDrive\Desktop\Vroomble\.venv\Lib\site-packages\fastapi\routing.py", line 301, in app
    raw_response = await run_endpoint_function(
                   ^^^^^^^^^^^^^^^^^^^^^^^^^^^^
  File "C:\Users\Sobre\OneDrive\Desktop\Vroomble\.venv\Lib\site-packages\fastapi\routing.py", line 212, in run_endpoint_function
    return await dependant.call(**values)
           ^^^^^^^^^^^^^^^^^^^^^^^^^^^^^^
  File "C:\Users\Sobre\OneDrive\Desktop\Vroomble\src\APIs\vehicle_registration.py", line 75, in submit_form
    body = await request.json()
           ^^^^^^^^^^^^^^^^^^^^
  File "C:\Users\Sobre\OneDrive\Desktop\Vroomble\.venv\Lib\site-packages\starlette\requests.py", line 249, in json
    self._json = json.loads(body)
                 ^^^^^^^^^^^^^^^^
  File "C:\Program Files\WindowsApps\PythonSoftwareFoundation.Python.3.11_3.11.2544.0_x64__qbz5n2kfra8p0\Lib\json\__init__.py", line 346, in loads
    return _default_decoder.decode(s)
           ^^^^^^^^^^^^^^^^^^^^^^^^^^
  File "C:\Program Files\WindowsApps\PythonSoftwareFoundation.Python.3.11_3.11.2544.0_x64__qbz5n2kfra8p0\Lib\json\decoder.py", line 337, in decode
    obj, end = self.raw_decode(s, idx=_w(s, 0).end())
               ^^^^^^^^^^^^^^^^^^^^^^^^^^^^^^^^^^^^^^
  File "C:\Program Files\WindowsApps\PythonSoftwareFoundation.Python.3.11_3.11.2544.0_x64__qbz5n2kfra8p0\Lib\json\decoder.py", line 355, in raw_decode
    raise JSONDecodeError("Expecting value", s, err.value) from None
json.decoder.JSONDecodeError: Expecting value: line 1 column 1 (char 0)
2025-03-02 11:21:05,566 - ERROR - Unhandled exception: Expecting value: line 1 column 1 (char 0)
Traceback (most recent call last):
  File "C:\Users\Sobre\OneDrive\Desktop\Vroomble\.venv\Lib\site-packages\starlette\middleware\errors.py", line 165, in __call__
    await self.app(scope, receive, _send)
  File "C:\Users\Sobre\OneDrive\Desktop\Vroomble\.venv\Lib\site-packages\starlette\middleware\cors.py", line 93, in __call__
    await self.simple_response(scope, receive, send, request_headers=headers)
  File "C:\Users\Sobre\OneDrive\Desktop\Vroomble\.venv\Lib\site-packages\starlette\middleware\cors.py", line 144, in simple_response
    await self.app(scope, receive, send)
  File "C:\Users\Sobre\OneDrive\Desktop\Vroomble\.venv\Lib\site-packages\starlette\middleware\exceptions.py", line 62, in __call__
    await wrap_app_handling_exceptions(self.app, conn)(scope, receive, send)
  File "C:\Users\Sobre\OneDrive\Desktop\Vroomble\.venv\Lib\site-packages\starlette\_exception_handler.py", line 53, in wrapped_app
    raise exc
  File "C:\Users\Sobre\OneDrive\Desktop\Vroomble\.venv\Lib\site-packages\starlette\_exception_handler.py", line 42, in wrapped_app
    await app(scope, receive, sender)
  File "C:\Users\Sobre\OneDrive\Desktop\Vroomble\.venv\Lib\site-packages\starlette\routing.py", line 715, in __call__
    await self.middleware_stack(scope, receive, send)
  File "C:\Users\Sobre\OneDrive\Desktop\Vroomble\.venv\Lib\site-packages\starlette\routing.py", line 735, in app
    await route.handle(scope, receive, send)
  File "C:\Users\Sobre\OneDrive\Desktop\Vroomble\.venv\Lib\site-packages\starlette\routing.py", line 288, in handle
    await self.app(scope, receive, send)
  File "C:\Users\Sobre\OneDrive\Desktop\Vroomble\.venv\Lib\site-packages\starlette\routing.py", line 76, in app
    await wrap_app_handling_exceptions(app, request)(scope, receive, send)
  File "C:\Users\Sobre\OneDrive\Desktop\Vroomble\.venv\Lib\site-packages\starlette\_exception_handler.py", line 53, in wrapped_app
    raise exc
  File "C:\Users\Sobre\OneDrive\Desktop\Vroomble\.venv\Lib\site-packages\starlette\_exception_handler.py", line 42, in wrapped_app
    await app(scope, receive, sender)
  File "C:\Users\Sobre\OneDrive\Desktop\Vroomble\.venv\Lib\site-packages\starlette\routing.py", line 73, in app
    response = await f(request)
               ^^^^^^^^^^^^^^^^
  File "C:\Users\Sobre\OneDrive\Desktop\Vroomble\.venv\Lib\site-packages\fastapi\routing.py", line 301, in app
    raw_response = await run_endpoint_function(
                   ^^^^^^^^^^^^^^^^^^^^^^^^^^^^
  File "C:\Users\Sobre\OneDrive\Desktop\Vroomble\.venv\Lib\site-packages\fastapi\routing.py", line 212, in run_endpoint_function
    return await dependant.call(**values)
           ^^^^^^^^^^^^^^^^^^^^^^^^^^^^^^
  File "C:\Users\Sobre\OneDrive\Desktop\Vroomble\src\APIs\vehicle_registration.py", line 75, in submit_form
    body = await request.json()
           ^^^^^^^^^^^^^^^^^^^^
  File "C:\Users\Sobre\OneDrive\Desktop\Vroomble\.venv\Lib\site-packages\starlette\requests.py", line 249, in json
    self._json = json.loads(body)
                 ^^^^^^^^^^^^^^^^
  File "C:\Program Files\WindowsApps\PythonSoftwareFoundation.Python.3.11_3.11.2544.0_x64__qbz5n2kfra8p0\Lib\json\__init__.py", line 346, in loads
    return _default_decoder.decode(s)
           ^^^^^^^^^^^^^^^^^^^^^^^^^^
  File "C:\Program Files\WindowsApps\PythonSoftwareFoundation.Python.3.11_3.11.2544.0_x64__qbz5n2kfra8p0\Lib\json\decoder.py", line 337, in decode
    obj, end = self.raw_decode(s, idx=_w(s, 0).end())
               ^^^^^^^^^^^^^^^^^^^^^^^^^^^^^^^^^^^^^^
  File "C:\Program Files\WindowsApps\PythonSoftwareFoundation.Python.3.11_3.11.2544.0_x64__qbz5n2kfra8p0\Lib\json\decoder.py", line 355, in raw_decode
    raise JSONDecodeError("Expecting value", s, err.value) from None
json.decoder.JSONDecodeError: Expecting value: line 1 column 1 (char 0)
2025-03-02 11:21:05,933 - ERROR - Unhandled exception: Expecting value: line 1 column 1 (char 0)
Traceback (most recent call last):
  File "C:\Users\Sobre\OneDrive\Desktop\Vroomble\.venv\Lib\site-packages\starlette\middleware\errors.py", line 165, in __call__
    await self.app(scope, receive, _send)
  File "C:\Users\Sobre\OneDrive\Desktop\Vroomble\.venv\Lib\site-packages\starlette\middleware\cors.py", line 93, in __call__
    await self.simple_response(scope, receive, send, request_headers=headers)
  File "C:\Users\Sobre\OneDrive\Desktop\Vroomble\.venv\Lib\site-packages\starlette\middleware\cors.py", line 144, in simple_response
    await self.app(scope, receive, send)
  File "C:\Users\Sobre\OneDrive\Desktop\Vroomble\.venv\Lib\site-packages\starlette\middleware\exceptions.py", line 62, in __call__
    await wrap_app_handling_exceptions(self.app, conn)(scope, receive, send)
  File "C:\Users\Sobre\OneDrive\Desktop\Vroomble\.venv\Lib\site-packages\starlette\_exception_handler.py", line 53, in wrapped_app
    raise exc
  File "C:\Users\Sobre\OneDrive\Desktop\Vroomble\.venv\Lib\site-packages\starlette\_exception_handler.py", line 42, in wrapped_app
    await app(scope, receive, sender)
  File "C:\Users\Sobre\OneDrive\Desktop\Vroomble\.venv\Lib\site-packages\starlette\routing.py", line 715, in __call__
    await self.middleware_stack(scope, receive, send)
  File "C:\Users\Sobre\OneDrive\Desktop\Vroomble\.venv\Lib\site-packages\starlette\routing.py", line 735, in app
    await route.handle(scope, receive, send)
  File "C:\Users\Sobre\OneDrive\Desktop\Vroomble\.venv\Lib\site-packages\starlette\routing.py", line 288, in handle
    await self.app(scope, receive, send)
  File "C:\Users\Sobre\OneDrive\Desktop\Vroomble\.venv\Lib\site-packages\starlette\routing.py", line 76, in app
    await wrap_app_handling_exceptions(app, request)(scope, receive, send)
  File "C:\Users\Sobre\OneDrive\Desktop\Vroomble\.venv\Lib\site-packages\starlette\_exception_handler.py", line 53, in wrapped_app
    raise exc
  File "C:\Users\Sobre\OneDrive\Desktop\Vroomble\.venv\Lib\site-packages\starlette\_exception_handler.py", line 42, in wrapped_app
    await app(scope, receive, sender)
  File "C:\Users\Sobre\OneDrive\Desktop\Vroomble\.venv\Lib\site-packages\starlette\routing.py", line 73, in app
    response = await f(request)
               ^^^^^^^^^^^^^^^^
  File "C:\Users\Sobre\OneDrive\Desktop\Vroomble\.venv\Lib\site-packages\fastapi\routing.py", line 301, in app
    raw_response = await run_endpoint_function(
                   ^^^^^^^^^^^^^^^^^^^^^^^^^^^^
  File "C:\Users\Sobre\OneDrive\Desktop\Vroomble\.venv\Lib\site-packages\fastapi\routing.py", line 212, in run_endpoint_function
    return await dependant.call(**values)
           ^^^^^^^^^^^^^^^^^^^^^^^^^^^^^^
  File "C:\Users\Sobre\OneDrive\Desktop\Vroomble\src\APIs\vehicle_registration.py", line 75, in submit_form
    body = await request.json()
           ^^^^^^^^^^^^^^^^^^^^
  File "C:\Users\Sobre\OneDrive\Desktop\Vroomble\.venv\Lib\site-packages\starlette\requests.py", line 249, in json
    self._json = json.loads(body)
                 ^^^^^^^^^^^^^^^^
  File "C:\Program Files\WindowsApps\PythonSoftwareFoundation.Python.3.11_3.11.2544.0_x64__qbz5n2kfra8p0\Lib\json\__init__.py", line 346, in loads
    return _default_decoder.decode(s)
           ^^^^^^^^^^^^^^^^^^^^^^^^^^
  File "C:\Program Files\WindowsApps\PythonSoftwareFoundation.Python.3.11_3.11.2544.0_x64__qbz5n2kfra8p0\Lib\json\decoder.py", line 337, in decode
    obj, end = self.raw_decode(s, idx=_w(s, 0).end())
               ^^^^^^^^^^^^^^^^^^^^^^^^^^^^^^^^^^^^^^
  File "C:\Program Files\WindowsApps\PythonSoftwareFoundation.Python.3.11_3.11.2544.0_x64__qbz5n2kfra8p0\Lib\json\decoder.py", line 355, in raw_decode
    raise JSONDecodeError("Expecting value", s, err.value) from None
json.decoder.JSONDecodeError: Expecting value: line 1 column 1 (char 0)
2025-03-02 11:21:06,606 - ERROR - Unhandled exception: Expecting value: line 1 column 1 (char 0)
Traceback (most recent call last):
  File "C:\Users\Sobre\OneDrive\Desktop\Vroomble\.venv\Lib\site-packages\starlette\middleware\errors.py", line 165, in __call__
    await self.app(scope, receive, _send)
  File "C:\Users\Sobre\OneDrive\Desktop\Vroomble\.venv\Lib\site-packages\starlette\middleware\cors.py", line 93, in __call__
    await self.simple_response(scope, receive, send, request_headers=headers)
  File "C:\Users\Sobre\OneDrive\Desktop\Vroomble\.venv\Lib\site-packages\starlette\middleware\cors.py", line 144, in simple_response
    await self.app(scope, receive, send)
  File "C:\Users\Sobre\OneDrive\Desktop\Vroomble\.venv\Lib\site-packages\starlette\middleware\exceptions.py", line 62, in __call__
    await wrap_app_handling_exceptions(self.app, conn)(scope, receive, send)
  File "C:\Users\Sobre\OneDrive\Desktop\Vroomble\.venv\Lib\site-packages\starlette\_exception_handler.py", line 53, in wrapped_app
    raise exc
  File "C:\Users\Sobre\OneDrive\Desktop\Vroomble\.venv\Lib\site-packages\starlette\_exception_handler.py", line 42, in wrapped_app
    await app(scope, receive, sender)
  File "C:\Users\Sobre\OneDrive\Desktop\Vroomble\.venv\Lib\site-packages\starlette\routing.py", line 715, in __call__
    await self.middleware_stack(scope, receive, send)
  File "C:\Users\Sobre\OneDrive\Desktop\Vroomble\.venv\Lib\site-packages\starlette\routing.py", line 735, in app
    await route.handle(scope, receive, send)
  File "C:\Users\Sobre\OneDrive\Desktop\Vroomble\.venv\Lib\site-packages\starlette\routing.py", line 288, in handle
    await self.app(scope, receive, send)
  File "C:\Users\Sobre\OneDrive\Desktop\Vroomble\.venv\Lib\site-packages\starlette\routing.py", line 76, in app
    await wrap_app_handling_exceptions(app, request)(scope, receive, send)
  File "C:\Users\Sobre\OneDrive\Desktop\Vroomble\.venv\Lib\site-packages\starlette\_exception_handler.py", line 53, in wrapped_app
    raise exc
  File "C:\Users\Sobre\OneDrive\Desktop\Vroomble\.venv\Lib\site-packages\starlette\_exception_handler.py", line 42, in wrapped_app
    await app(scope, receive, sender)
  File "C:\Users\Sobre\OneDrive\Desktop\Vroomble\.venv\Lib\site-packages\starlette\routing.py", line 73, in app
    response = await f(request)
               ^^^^^^^^^^^^^^^^
  File "C:\Users\Sobre\OneDrive\Desktop\Vroomble\.venv\Lib\site-packages\fastapi\routing.py", line 301, in app
    raw_response = await run_endpoint_function(
                   ^^^^^^^^^^^^^^^^^^^^^^^^^^^^
  File "C:\Users\Sobre\OneDrive\Desktop\Vroomble\.venv\Lib\site-packages\fastapi\routing.py", line 212, in run_endpoint_function
    return await dependant.call(**values)
           ^^^^^^^^^^^^^^^^^^^^^^^^^^^^^^
  File "C:\Users\Sobre\OneDrive\Desktop\Vroomble\src\APIs\vehicle_registration.py", line 75, in submit_form
    body = await request.json()
           ^^^^^^^^^^^^^^^^^^^^
  File "C:\Users\Sobre\OneDrive\Desktop\Vroomble\.venv\Lib\site-packages\starlette\requests.py", line 249, in json
    self._json = json.loads(body)
                 ^^^^^^^^^^^^^^^^
  File "C:\Program Files\WindowsApps\PythonSoftwareFoundation.Python.3.11_3.11.2544.0_x64__qbz5n2kfra8p0\Lib\json\__init__.py", line 346, in loads
    return _default_decoder.decode(s)
           ^^^^^^^^^^^^^^^^^^^^^^^^^^
  File "C:\Program Files\WindowsApps\PythonSoftwareFoundation.Python.3.11_3.11.2544.0_x64__qbz5n2kfra8p0\Lib\json\decoder.py", line 337, in decode
    obj, end = self.raw_decode(s, idx=_w(s, 0).end())
               ^^^^^^^^^^^^^^^^^^^^^^^^^^^^^^^^^^^^^^
  File "C:\Program Files\WindowsApps\PythonSoftwareFoundation.Python.3.11_3.11.2544.0_x64__qbz5n2kfra8p0\Lib\json\decoder.py", line 355, in raw_decode
    raise JSONDecodeError("Expecting value", s, err.value) from None
json.decoder.JSONDecodeError: Expecting value: line 1 column 1 (char 0)
2025-03-02 11:24:34,265 - INFO - Database and table created successfully (if not already existing).
2025-03-02 11:25:16,160 - INFO - Executing SQL: 
            INSERT INTO cars (Make, Model, Body_Type, Transmission, Drivetrain, Fuel_Type, Year, Retail_SRP, Variant)
            VALUES (?, ?, ?, ?, ?, ?, ?, ?, ?)
         with values ('TOYOTA', 'FORTUNER', 'SUV', 'CVT', 'RWD', 'Diesel', 2014, '1300000.00', 'G')
2025-03-02 11:25:16,163 - INFO - Car added successfully: make='TOYOTA' model='FORTUNER' body_type='SUV' variant='G' transmission='CVT' drivetrain='RWD' fuel_type='Diesel' year=2014 retail_srp=1300000.0
2025-03-02 11:27:04,624 - INFO - Database and table created successfully (if not already existing).
2025-03-02 11:27:09,496 - INFO - Database and table created successfully (if not already existing).
2025-03-02 11:27:33,202 - INFO - Entering create_car_form function...
2025-03-02 11:27:33,204 - INFO - Executing SQL: 
            INSERT INTO cars (Make, Model, Body_Type, Transmission, Drivetrain, Fuel_Type, Year, Retail_SRP, Variant)
            VALUES (?, ?, ?, ?, ?, ?, ?, ?, ?)
         with values ('TOYOTA', 'FORTUNER', 'SUV', 'CVT', 'RWD', 'Diesel', 2014, '1300000.00', 'G')
2025-03-02 11:27:33,205 - INFO - Car added successfully: make='TOYOTA' model='FORTUNER' body_type='SUV' variant='G' transmission='CVT' drivetrain='RWD' fuel_type='Diesel' year=2014 retail_srp=1300000.0
2025-03-02 11:28:11,140 - INFO - Entering create_car_form function...
2025-03-02 11:28:11,142 - INFO - Executing SQL: 
            INSERT INTO cars (Make, Model, Body_Type, Transmission, Drivetrain, Fuel_Type, Year, Retail_SRP, Variant)
            VALUES (?, ?, ?, ?, ?, ?, ?, ?, ?)
         with values ('TOYOTA', 'FORTUNER', 'SUV', 'CVT', 'RWD', 'Diesel', 2014, '1300000.00', 'G')
2025-03-02 11:28:11,145 - INFO - Car added successfully: make='TOYOTA' model='FORTUNER' body_type='SUV' variant='G' transmission='CVT' drivetrain='RWD' fuel_type='Diesel' year=2014 retail_srp=1300000.0
