2025-03-02 01:53:56,800 - INFO - Database table created or already exists.
2025-03-02 01:57:02,574 - ERROR - Validation error: [{'type': 'int_parsing', 'loc': ('body', 'year'), 'msg': 'Input should be a valid integer, unable to parse string as an integer', 'input': ''}, {'type': 'value_error', 'loc': ('body', 'retail_srp'), 'msg': 'Value error, Retail SRP must be positive', 'input': 0, 'ctx': {'error': ValueError('Retail SRP must be positive')}}]
2025-03-02 01:57:02,574 - ERROR - Unhandled exception: Object of type ValueError is not JSON serializable
Traceback (most recent call last):
  File "C:\Users\Sobre\OneDrive\Desktop\Vroomble\.venv\Lib\site-packages\starlette\_exception_handler.py", line 42, in wrapped_app
    await app(scope, receive, sender)
  File "C:\Users\Sobre\OneDrive\Desktop\Vroomble\.venv\Lib\site-packages\starlette\routing.py", line 73, in app
    response = await f(request)
               ^^^^^^^^^^^^^^^^
  File "C:\Users\Sobre\OneDrive\Desktop\Vroomble\.venv\Lib\site-packages\fastapi\routing.py", line 346, in app
    raise validation_error
fastapi.exceptions.RequestValidationError: [{'type': 'int_parsing', 'loc': ('body', 'year'), 'msg': 'Input should be a valid integer, unable to parse string as an integer', 'input': ''}, {'type': 'value_error', 'loc': ('body', 'retail_srp'), 'msg': 'Value error, Retail SRP must be positive', 'input': 0, 'ctx': {'error': ValueError('Retail SRP must be positive')}}]

During handling of the above exception, another exception occurred:

Traceback (most recent call last):
  File "C:\Users\Sobre\OneDrive\Desktop\Vroomble\.venv\Lib\site-packages\starlette\middleware\errors.py", line 165, in __call__
    await self.app(scope, receive, _send)
  File "C:\Users\Sobre\OneDrive\Desktop\Vroomble\.venv\Lib\site-packages\starlette\middleware\cors.py", line 93, in __call__
    await self.simple_response(scope, receive, send, request_headers=headers)
  File "C:\Users\Sobre\OneDrive\Desktop\Vroomble\.venv\Lib\site-packages\starlette\middleware\cors.py", line 144, in simple_response
    await self.app(scope, receive, send)
  File "C:\Users\Sobre\OneDrive\Desktop\Vroomble\.venv\Lib\site-packages\starlette\middleware\exceptions.py", line 62, in __call__
    await wrap_app_handling_exceptions(self.app, conn)(scope, receive, send)
  File "C:\Users\Sobre\OneDrive\Desktop\Vroomble\.venv\Lib\site-packages\starlette\_exception_handler.py", line 53, in wrapped_app
    raise exc
  File "C:\Users\Sobre\OneDrive\Desktop\Vroomble\.venv\Lib\site-packages\starlette\_exception_handler.py", line 42, in wrapped_app
    await app(scope, receive, sender)
  File "C:\Users\Sobre\OneDrive\Desktop\Vroomble\.venv\Lib\site-packages\starlette\routing.py", line 715, in __call__
    await self.middleware_stack(scope, receive, send)
  File "C:\Users\Sobre\OneDrive\Desktop\Vroomble\.venv\Lib\site-packages\starlette\routing.py", line 735, in app
    await route.handle(scope, receive, send)
  File "C:\Users\Sobre\OneDrive\Desktop\Vroomble\.venv\Lib\site-packages\starlette\routing.py", line 288, in handle
    await self.app(scope, receive, send)
  File "C:\Users\Sobre\OneDrive\Desktop\Vroomble\.venv\Lib\site-packages\starlette\routing.py", line 76, in app
    await wrap_app_handling_exceptions(app, request)(scope, receive, send)
  File "C:\Users\Sobre\OneDrive\Desktop\Vroomble\.venv\Lib\site-packages\starlette\_exception_handler.py", line 59, in wrapped_app
    response = await handler(conn, exc)
               ^^^^^^^^^^^^^^^^^^^^^^^^
  File "C:\Users\Sobre\OneDrive\Desktop\Vroomble\src\APIs\vehicle_registration.py", line 170, in validation_exception_handler
    return JSONResponse(
           ^^^^^^^^^^^^^
  File "C:\Users\Sobre\OneDrive\Desktop\Vroomble\.venv\Lib\site-packages\starlette\responses.py", line 181, in __init__
    super().__init__(content, status_code, headers, media_type, background)
  File "C:\Users\Sobre\OneDrive\Desktop\Vroomble\.venv\Lib\site-packages\starlette\responses.py", line 44, in __init__
    self.body = self.render(content)
                ^^^^^^^^^^^^^^^^^^^^
  File "C:\Users\Sobre\OneDrive\Desktop\Vroomble\.venv\Lib\site-packages\starlette\responses.py", line 184, in render
    return json.dumps(
           ^^^^^^^^^^^
  File "C:\Program Files\WindowsApps\PythonSoftwareFoundation.Python.3.11_3.11.2544.0_x64__qbz5n2kfra8p0\Lib\json\__init__.py", line 238, in dumps
    **kw).encode(obj)
          ^^^^^^^^^^^
  File "C:\Program Files\WindowsApps\PythonSoftwareFoundation.Python.3.11_3.11.2544.0_x64__qbz5n2kfra8p0\Lib\json\encoder.py", line 200, in encode
    chunks = self.iterencode(o, _one_shot=True)
             ^^^^^^^^^^^^^^^^^^^^^^^^^^^^^^^^^^
  File "C:\Program Files\WindowsApps\PythonSoftwareFoundation.Python.3.11_3.11.2544.0_x64__qbz5n2kfra8p0\Lib\json\encoder.py", line 258, in iterencode
    return _iterencode(o, 0)
           ^^^^^^^^^^^^^^^^^
  File "C:\Program Files\WindowsApps\PythonSoftwareFoundation.Python.3.11_3.11.2544.0_x64__qbz5n2kfra8p0\Lib\json\encoder.py", line 180, in default
    raise TypeError(f'Object of type {o.__class__.__name__} '
TypeError: Object of type ValueError is not JSON serializable
2025-03-02 01:57:10,637 - ERROR - Validation error: [{'type': 'int_parsing', 'loc': ('body', 'year'), 'msg': 'Input should be a valid integer, unable to parse string as an integer', 'input': ''}, {'type': 'value_error', 'loc': ('body', 'retail_srp'), 'msg': 'Value error, Retail SRP must be positive', 'input': 0, 'ctx': {'error': ValueError('Retail SRP must be positive')}}]
2025-03-02 01:57:10,637 - ERROR - Unhandled exception: Object of type ValueError is not JSON serializable
Traceback (most recent call last):
  File "C:\Users\Sobre\OneDrive\Desktop\Vroomble\.venv\Lib\site-packages\starlette\_exception_handler.py", line 42, in wrapped_app
    await app(scope, receive, sender)
  File "C:\Users\Sobre\OneDrive\Desktop\Vroomble\.venv\Lib\site-packages\starlette\routing.py", line 73, in app
    response = await f(request)
               ^^^^^^^^^^^^^^^^
  File "C:\Users\Sobre\OneDrive\Desktop\Vroomble\.venv\Lib\site-packages\fastapi\routing.py", line 346, in app
    raise validation_error
fastapi.exceptions.RequestValidationError: [{'type': 'int_parsing', 'loc': ('body', 'year'), 'msg': 'Input should be a valid integer, unable to parse string as an integer', 'input': ''}, {'type': 'value_error', 'loc': ('body', 'retail_srp'), 'msg': 'Value error, Retail SRP must be positive', 'input': 0, 'ctx': {'error': ValueError('Retail SRP must be positive')}}]

During handling of the above exception, another exception occurred:

Traceback (most recent call last):
  File "C:\Users\Sobre\OneDrive\Desktop\Vroomble\.venv\Lib\site-packages\starlette\middleware\errors.py", line 165, in __call__
    await self.app(scope, receive, _send)
  File "C:\Users\Sobre\OneDrive\Desktop\Vroomble\.venv\Lib\site-packages\starlette\middleware\cors.py", line 93, in __call__
    await self.simple_response(scope, receive, send, request_headers=headers)
  File "C:\Users\Sobre\OneDrive\Desktop\Vroomble\.venv\Lib\site-packages\starlette\middleware\cors.py", line 144, in simple_response
    await self.app(scope, receive, send)
  File "C:\Users\Sobre\OneDrive\Desktop\Vroomble\.venv\Lib\site-packages\starlette\middleware\exceptions.py", line 62, in __call__
    await wrap_app_handling_exceptions(self.app, conn)(scope, receive, send)
  File "C:\Users\Sobre\OneDrive\Desktop\Vroomble\.venv\Lib\site-packages\starlette\_exception_handler.py", line 53, in wrapped_app
    raise exc
  File "C:\Users\Sobre\OneDrive\Desktop\Vroomble\.venv\Lib\site-packages\starlette\_exception_handler.py", line 42, in wrapped_app
    await app(scope, receive, sender)
  File "C:\Users\Sobre\OneDrive\Desktop\Vroomble\.venv\Lib\site-packages\starlette\routing.py", line 715, in __call__
    await self.middleware_stack(scope, receive, send)
  File "C:\Users\Sobre\OneDrive\Desktop\Vroomble\.venv\Lib\site-packages\starlette\routing.py", line 735, in app
    await route.handle(scope, receive, send)
  File "C:\Users\Sobre\OneDrive\Desktop\Vroomble\.venv\Lib\site-packages\starlette\routing.py", line 288, in handle
    await self.app(scope, receive, send)
  File "C:\Users\Sobre\OneDrive\Desktop\Vroomble\.venv\Lib\site-packages\starlette\routing.py", line 76, in app
    await wrap_app_handling_exceptions(app, request)(scope, receive, send)
  File "C:\Users\Sobre\OneDrive\Desktop\Vroomble\.venv\Lib\site-packages\starlette\_exception_handler.py", line 59, in wrapped_app
    response = await handler(conn, exc)
               ^^^^^^^^^^^^^^^^^^^^^^^^
  File "C:\Users\Sobre\OneDrive\Desktop\Vroomble\src\APIs\vehicle_registration.py", line 170, in validation_exception_handler
    return JSONResponse(
           ^^^^^^^^^^^^^
  File "C:\Users\Sobre\OneDrive\Desktop\Vroomble\.venv\Lib\site-packages\starlette\responses.py", line 181, in __init__
    super().__init__(content, status_code, headers, media_type, background)
  File "C:\Users\Sobre\OneDrive\Desktop\Vroomble\.venv\Lib\site-packages\starlette\responses.py", line 44, in __init__
    self.body = self.render(content)
                ^^^^^^^^^^^^^^^^^^^^
  File "C:\Users\Sobre\OneDrive\Desktop\Vroomble\.venv\Lib\site-packages\starlette\responses.py", line 184, in render
    return json.dumps(
           ^^^^^^^^^^^
  File "C:\Program Files\WindowsApps\PythonSoftwareFoundation.Python.3.11_3.11.2544.0_x64__qbz5n2kfra8p0\Lib\json\__init__.py", line 238, in dumps
    **kw).encode(obj)
          ^^^^^^^^^^^
  File "C:\Program Files\WindowsApps\PythonSoftwareFoundation.Python.3.11_3.11.2544.0_x64__qbz5n2kfra8p0\Lib\json\encoder.py", line 200, in encode
    chunks = self.iterencode(o, _one_shot=True)
             ^^^^^^^^^^^^^^^^^^^^^^^^^^^^^^^^^^
  File "C:\Program Files\WindowsApps\PythonSoftwareFoundation.Python.3.11_3.11.2544.0_x64__qbz5n2kfra8p0\Lib\json\encoder.py", line 258, in iterencode
    return _iterencode(o, 0)
           ^^^^^^^^^^^^^^^^^
  File "C:\Program Files\WindowsApps\PythonSoftwareFoundation.Python.3.11_3.11.2544.0_x64__qbz5n2kfra8p0\Lib\json\encoder.py", line 180, in default
    raise TypeError(f'Object of type {o.__class__.__name__} '
TypeError: Object of type ValueError is not JSON serializable
2025-03-02 01:57:17,118 - ERROR - Validation error: [{'type': 'int_parsing', 'loc': ('body', 'year'), 'msg': 'Input should be a valid integer, unable to parse string as an integer', 'input': ''}, {'type': 'value_error', 'loc': ('body', 'retail_srp'), 'msg': 'Value error, Retail SRP must be positive', 'input': 0, 'ctx': {'error': ValueError('Retail SRP must be positive')}}]
2025-03-02 01:57:17,118 - ERROR - Unhandled exception: Object of type ValueError is not JSON serializable
Traceback (most recent call last):
  File "C:\Users\Sobre\OneDrive\Desktop\Vroomble\.venv\Lib\site-packages\starlette\_exception_handler.py", line 42, in wrapped_app
    await app(scope, receive, sender)
  File "C:\Users\Sobre\OneDrive\Desktop\Vroomble\.venv\Lib\site-packages\starlette\routing.py", line 73, in app
    response = await f(request)
               ^^^^^^^^^^^^^^^^
  File "C:\Users\Sobre\OneDrive\Desktop\Vroomble\.venv\Lib\site-packages\fastapi\routing.py", line 346, in app
    raise validation_error
fastapi.exceptions.RequestValidationError: [{'type': 'int_parsing', 'loc': ('body', 'year'), 'msg': 'Input should be a valid integer, unable to parse string as an integer', 'input': ''}, {'type': 'value_error', 'loc': ('body', 'retail_srp'), 'msg': 'Value error, Retail SRP must be positive', 'input': 0, 'ctx': {'error': ValueError('Retail SRP must be positive')}}]

During handling of the above exception, another exception occurred:

Traceback (most recent call last):
  File "C:\Users\Sobre\OneDrive\Desktop\Vroomble\.venv\Lib\site-packages\starlette\middleware\errors.py", line 165, in __call__
    await self.app(scope, receive, _send)
  File "C:\Users\Sobre\OneDrive\Desktop\Vroomble\.venv\Lib\site-packages\starlette\middleware\cors.py", line 93, in __call__
    await self.simple_response(scope, receive, send, request_headers=headers)
  File "C:\Users\Sobre\OneDrive\Desktop\Vroomble\.venv\Lib\site-packages\starlette\middleware\cors.py", line 144, in simple_response
    await self.app(scope, receive, send)
  File "C:\Users\Sobre\OneDrive\Desktop\Vroomble\.venv\Lib\site-packages\starlette\middleware\exceptions.py", line 62, in __call__
    await wrap_app_handling_exceptions(self.app, conn)(scope, receive, send)
  File "C:\Users\Sobre\OneDrive\Desktop\Vroomble\.venv\Lib\site-packages\starlette\_exception_handler.py", line 53, in wrapped_app
    raise exc
  File "C:\Users\Sobre\OneDrive\Desktop\Vroomble\.venv\Lib\site-packages\starlette\_exception_handler.py", line 42, in wrapped_app
    await app(scope, receive, sender)
  File "C:\Users\Sobre\OneDrive\Desktop\Vroomble\.venv\Lib\site-packages\starlette\routing.py", line 715, in __call__
    await self.middleware_stack(scope, receive, send)
  File "C:\Users\Sobre\OneDrive\Desktop\Vroomble\.venv\Lib\site-packages\starlette\routing.py", line 735, in app
    await route.handle(scope, receive, send)
  File "C:\Users\Sobre\OneDrive\Desktop\Vroomble\.venv\Lib\site-packages\starlette\routing.py", line 288, in handle
    await self.app(scope, receive, send)
  File "C:\Users\Sobre\OneDrive\Desktop\Vroomble\.venv\Lib\site-packages\starlette\routing.py", line 76, in app
    await wrap_app_handling_exceptions(app, request)(scope, receive, send)
  File "C:\Users\Sobre\OneDrive\Desktop\Vroomble\.venv\Lib\site-packages\starlette\_exception_handler.py", line 59, in wrapped_app
    response = await handler(conn, exc)
               ^^^^^^^^^^^^^^^^^^^^^^^^
  File "C:\Users\Sobre\OneDrive\Desktop\Vroomble\src\APIs\vehicle_registration.py", line 170, in validation_exception_handler
    return JSONResponse(
           ^^^^^^^^^^^^^
  File "C:\Users\Sobre\OneDrive\Desktop\Vroomble\.venv\Lib\site-packages\starlette\responses.py", line 181, in __init__
    super().__init__(content, status_code, headers, media_type, background)
  File "C:\Users\Sobre\OneDrive\Desktop\Vroomble\.venv\Lib\site-packages\starlette\responses.py", line 44, in __init__
    self.body = self.render(content)
                ^^^^^^^^^^^^^^^^^^^^
  File "C:\Users\Sobre\OneDrive\Desktop\Vroomble\.venv\Lib\site-packages\starlette\responses.py", line 184, in render
    return json.dumps(
           ^^^^^^^^^^^
  File "C:\Program Files\WindowsApps\PythonSoftwareFoundation.Python.3.11_3.11.2544.0_x64__qbz5n2kfra8p0\Lib\json\__init__.py", line 238, in dumps
    **kw).encode(obj)
          ^^^^^^^^^^^
  File "C:\Program Files\WindowsApps\PythonSoftwareFoundation.Python.3.11_3.11.2544.0_x64__qbz5n2kfra8p0\Lib\json\encoder.py", line 200, in encode
    chunks = self.iterencode(o, _one_shot=True)
             ^^^^^^^^^^^^^^^^^^^^^^^^^^^^^^^^^^
  File "C:\Program Files\WindowsApps\PythonSoftwareFoundation.Python.3.11_3.11.2544.0_x64__qbz5n2kfra8p0\Lib\json\encoder.py", line 258, in iterencode
    return _iterencode(o, 0)
           ^^^^^^^^^^^^^^^^^
  File "C:\Program Files\WindowsApps\PythonSoftwareFoundation.Python.3.11_3.11.2544.0_x64__qbz5n2kfra8p0\Lib\json\encoder.py", line 180, in default
    raise TypeError(f'Object of type {o.__class__.__name__} '
TypeError: Object of type ValueError is not JSON serializable
2025-03-02 01:57:20,380 - ERROR - Validation error: [{'type': 'int_parsing', 'loc': ('body', 'year'), 'msg': 'Input should be a valid integer, unable to parse string as an integer', 'input': ''}, {'type': 'value_error', 'loc': ('body', 'retail_srp'), 'msg': 'Value error, Retail SRP must be positive', 'input': 0, 'ctx': {'error': ValueError('Retail SRP must be positive')}}]
2025-03-02 01:57:20,382 - ERROR - Unhandled exception: Object of type ValueError is not JSON serializable
Traceback (most recent call last):
  File "C:\Users\Sobre\OneDrive\Desktop\Vroomble\.venv\Lib\site-packages\starlette\_exception_handler.py", line 42, in wrapped_app
    await app(scope, receive, sender)
  File "C:\Users\Sobre\OneDrive\Desktop\Vroomble\.venv\Lib\site-packages\starlette\routing.py", line 73, in app
    response = await f(request)
               ^^^^^^^^^^^^^^^^
  File "C:\Users\Sobre\OneDrive\Desktop\Vroomble\.venv\Lib\site-packages\fastapi\routing.py", line 346, in app
    raise validation_error
fastapi.exceptions.RequestValidationError: [{'type': 'int_parsing', 'loc': ('body', 'year'), 'msg': 'Input should be a valid integer, unable to parse string as an integer', 'input': ''}, {'type': 'value_error', 'loc': ('body', 'retail_srp'), 'msg': 'Value error, Retail SRP must be positive', 'input': 0, 'ctx': {'error': ValueError('Retail SRP must be positive')}}]

During handling of the above exception, another exception occurred:

Traceback (most recent call last):
  File "C:\Users\Sobre\OneDrive\Desktop\Vroomble\.venv\Lib\site-packages\starlette\middleware\errors.py", line 165, in __call__
    await self.app(scope, receive, _send)
  File "C:\Users\Sobre\OneDrive\Desktop\Vroomble\.venv\Lib\site-packages\starlette\middleware\cors.py", line 93, in __call__
    await self.simple_response(scope, receive, send, request_headers=headers)
  File "C:\Users\Sobre\OneDrive\Desktop\Vroomble\.venv\Lib\site-packages\starlette\middleware\cors.py", line 144, in simple_response
    await self.app(scope, receive, send)
  File "C:\Users\Sobre\OneDrive\Desktop\Vroomble\.venv\Lib\site-packages\starlette\middleware\exceptions.py", line 62, in __call__
    await wrap_app_handling_exceptions(self.app, conn)(scope, receive, send)
  File "C:\Users\Sobre\OneDrive\Desktop\Vroomble\.venv\Lib\site-packages\starlette\_exception_handler.py", line 53, in wrapped_app
    raise exc
  File "C:\Users\Sobre\OneDrive\Desktop\Vroomble\.venv\Lib\site-packages\starlette\_exception_handler.py", line 42, in wrapped_app
    await app(scope, receive, sender)
  File "C:\Users\Sobre\OneDrive\Desktop\Vroomble\.venv\Lib\site-packages\starlette\routing.py", line 715, in __call__
    await self.middleware_stack(scope, receive, send)
  File "C:\Users\Sobre\OneDrive\Desktop\Vroomble\.venv\Lib\site-packages\starlette\routing.py", line 735, in app
    await route.handle(scope, receive, send)
  File "C:\Users\Sobre\OneDrive\Desktop\Vroomble\.venv\Lib\site-packages\starlette\routing.py", line 288, in handle
    await self.app(scope, receive, send)
  File "C:\Users\Sobre\OneDrive\Desktop\Vroomble\.venv\Lib\site-packages\starlette\routing.py", line 76, in app
    await wrap_app_handling_exceptions(app, request)(scope, receive, send)
  File "C:\Users\Sobre\OneDrive\Desktop\Vroomble\.venv\Lib\site-packages\starlette\_exception_handler.py", line 59, in wrapped_app
    response = await handler(conn, exc)
               ^^^^^^^^^^^^^^^^^^^^^^^^
  File "C:\Users\Sobre\OneDrive\Desktop\Vroomble\src\APIs\vehicle_registration.py", line 170, in validation_exception_handler
    return JSONResponse(
           ^^^^^^^^^^^^^
  File "C:\Users\Sobre\OneDrive\Desktop\Vroomble\.venv\Lib\site-packages\starlette\responses.py", line 181, in __init__
    super().__init__(content, status_code, headers, media_type, background)
  File "C:\Users\Sobre\OneDrive\Desktop\Vroomble\.venv\Lib\site-packages\starlette\responses.py", line 44, in __init__
    self.body = self.render(content)
                ^^^^^^^^^^^^^^^^^^^^
  File "C:\Users\Sobre\OneDrive\Desktop\Vroomble\.venv\Lib\site-packages\starlette\responses.py", line 184, in render
    return json.dumps(
           ^^^^^^^^^^^
  File "C:\Program Files\WindowsApps\PythonSoftwareFoundation.Python.3.11_3.11.2544.0_x64__qbz5n2kfra8p0\Lib\json\__init__.py", line 238, in dumps
    **kw).encode(obj)
          ^^^^^^^^^^^
  File "C:\Program Files\WindowsApps\PythonSoftwareFoundation.Python.3.11_3.11.2544.0_x64__qbz5n2kfra8p0\Lib\json\encoder.py", line 200, in encode
    chunks = self.iterencode(o, _one_shot=True)
             ^^^^^^^^^^^^^^^^^^^^^^^^^^^^^^^^^^
  File "C:\Program Files\WindowsApps\PythonSoftwareFoundation.Python.3.11_3.11.2544.0_x64__qbz5n2kfra8p0\Lib\json\encoder.py", line 258, in iterencode
    return _iterencode(o, 0)
           ^^^^^^^^^^^^^^^^^
  File "C:\Program Files\WindowsApps\PythonSoftwareFoundation.Python.3.11_3.11.2544.0_x64__qbz5n2kfra8p0\Lib\json\encoder.py", line 180, in default
    raise TypeError(f'Object of type {o.__class__.__name__} '
TypeError: Object of type ValueError is not JSON serializable
2025-03-02 02:04:17,407 - INFO - Database table created or already exists.
2025-03-02 02:10:10,129 - ERROR - Validation error: [{'type': 'int_parsing', 'loc': ('body', 'year'), 'msg': 'Input should be a valid integer, unable to parse string as an integer', 'input': ''}, {'type': 'float_parsing', 'loc': ('body', 'retail_srp'), 'msg': 'Input should be a valid number, unable to parse string as a number', 'input': ''}]
2025-03-02 02:10:13,286 - ERROR - Validation error: [{'type': 'int_parsing', 'loc': ('body', 'year'), 'msg': 'Input should be a valid integer, unable to parse string as an integer', 'input': ''}, {'type': 'float_parsing', 'loc': ('body', 'retail_srp'), 'msg': 'Input should be a valid number, unable to parse string as a number', 'input': ''}]
2025-03-02 02:12:40,730 - ERROR - Validation error: [{'type': 'value_error', 'loc': ('body', 'year'), 'msg': 'Value error, Invalid year', 'input': 0, 'ctx': {'error': ValueError('Invalid year')}}, {'type': 'value_error', 'loc': ('body', 'retail_srp'), 'msg': 'Value error, Retail SRP must be positive', 'input': 0, 'ctx': {'error': ValueError('Retail SRP must be positive')}}]
2025-03-02 02:12:40,731 - ERROR - Unhandled exception: Object of type ValueError is not JSON serializable
Traceback (most recent call last):
  File "C:\Users\Sobre\OneDrive\Desktop\Vroomble\.venv\Lib\site-packages\starlette\_exception_handler.py", line 42, in wrapped_app
    await app(scope, receive, sender)
  File "C:\Users\Sobre\OneDrive\Desktop\Vroomble\.venv\Lib\site-packages\starlette\routing.py", line 73, in app
    response = await f(request)
               ^^^^^^^^^^^^^^^^
  File "C:\Users\Sobre\OneDrive\Desktop\Vroomble\.venv\Lib\site-packages\fastapi\routing.py", line 346, in app
    raise validation_error
fastapi.exceptions.RequestValidationError: [{'type': 'value_error', 'loc': ('body', 'year'), 'msg': 'Value error, Invalid year', 'input': 0, 'ctx': {'error': ValueError('Invalid year')}}, {'type': 'value_error', 'loc': ('body', 'retail_srp'), 'msg': 'Value error, Retail SRP must be positive', 'input': 0, 'ctx': {'error': ValueError('Retail SRP must be positive')}}]

During handling of the above exception, another exception occurred:

Traceback (most recent call last):
  File "C:\Users\Sobre\OneDrive\Desktop\Vroomble\.venv\Lib\site-packages\starlette\middleware\errors.py", line 165, in __call__
    await self.app(scope, receive, _send)
  File "C:\Users\Sobre\OneDrive\Desktop\Vroomble\.venv\Lib\site-packages\starlette\middleware\cors.py", line 93, in __call__
    await self.simple_response(scope, receive, send, request_headers=headers)
  File "C:\Users\Sobre\OneDrive\Desktop\Vroomble\.venv\Lib\site-packages\starlette\middleware\cors.py", line 144, in simple_response
    await self.app(scope, receive, send)
  File "C:\Users\Sobre\OneDrive\Desktop\Vroomble\.venv\Lib\site-packages\starlette\middleware\exceptions.py", line 62, in __call__
    await wrap_app_handling_exceptions(self.app, conn)(scope, receive, send)
  File "C:\Users\Sobre\OneDrive\Desktop\Vroomble\.venv\Lib\site-packages\starlette\_exception_handler.py", line 53, in wrapped_app
    raise exc
  File "C:\Users\Sobre\OneDrive\Desktop\Vroomble\.venv\Lib\site-packages\starlette\_exception_handler.py", line 42, in wrapped_app
    await app(scope, receive, sender)
  File "C:\Users\Sobre\OneDrive\Desktop\Vroomble\.venv\Lib\site-packages\starlette\routing.py", line 715, in __call__
    await self.middleware_stack(scope, receive, send)
  File "C:\Users\Sobre\OneDrive\Desktop\Vroomble\.venv\Lib\site-packages\starlette\routing.py", line 735, in app
    await route.handle(scope, receive, send)
  File "C:\Users\Sobre\OneDrive\Desktop\Vroomble\.venv\Lib\site-packages\starlette\routing.py", line 288, in handle
    await self.app(scope, receive, send)
  File "C:\Users\Sobre\OneDrive\Desktop\Vroomble\.venv\Lib\site-packages\starlette\routing.py", line 76, in app
    await wrap_app_handling_exceptions(app, request)(scope, receive, send)
  File "C:\Users\Sobre\OneDrive\Desktop\Vroomble\.venv\Lib\site-packages\starlette\_exception_handler.py", line 59, in wrapped_app
    response = await handler(conn, exc)
               ^^^^^^^^^^^^^^^^^^^^^^^^
  File "C:\Users\Sobre\OneDrive\Desktop\Vroomble\src\APIs\vehicle_registration.py", line 172, in validation_exception_handler
    return JSONResponse(
           ^^^^^^^^^^^^^
  File "C:\Users\Sobre\OneDrive\Desktop\Vroomble\.venv\Lib\site-packages\starlette\responses.py", line 181, in __init__
    super().__init__(content, status_code, headers, media_type, background)
  File "C:\Users\Sobre\OneDrive\Desktop\Vroomble\.venv\Lib\site-packages\starlette\responses.py", line 44, in __init__
    self.body = self.render(content)
                ^^^^^^^^^^^^^^^^^^^^
  File "C:\Users\Sobre\OneDrive\Desktop\Vroomble\.venv\Lib\site-packages\starlette\responses.py", line 184, in render
    return json.dumps(
           ^^^^^^^^^^^
  File "C:\Program Files\WindowsApps\PythonSoftwareFoundation.Python.3.11_3.11.2544.0_x64__qbz5n2kfra8p0\Lib\json\__init__.py", line 238, in dumps
    **kw).encode(obj)
          ^^^^^^^^^^^
  File "C:\Program Files\WindowsApps\PythonSoftwareFoundation.Python.3.11_3.11.2544.0_x64__qbz5n2kfra8p0\Lib\json\encoder.py", line 200, in encode
    chunks = self.iterencode(o, _one_shot=True)
             ^^^^^^^^^^^^^^^^^^^^^^^^^^^^^^^^^^
  File "C:\Program Files\WindowsApps\PythonSoftwareFoundation.Python.3.11_3.11.2544.0_x64__qbz5n2kfra8p0\Lib\json\encoder.py", line 258, in iterencode
    return _iterencode(o, 0)
           ^^^^^^^^^^^^^^^^^
  File "C:\Program Files\WindowsApps\PythonSoftwareFoundation.Python.3.11_3.11.2544.0_x64__qbz5n2kfra8p0\Lib\json\encoder.py", line 180, in default
    raise TypeError(f'Object of type {o.__class__.__name__} '
TypeError: Object of type ValueError is not JSON serializable
2025-03-02 02:12:50,339 - ERROR - Validation error: [{'type': 'value_error', 'loc': ('body', 'year'), 'msg': 'Value error, Invalid year', 'input': 0, 'ctx': {'error': ValueError('Invalid year')}}, {'type': 'value_error', 'loc': ('body', 'retail_srp'), 'msg': 'Value error, Retail SRP must be positive', 'input': 0, 'ctx': {'error': ValueError('Retail SRP must be positive')}}]
2025-03-02 02:12:50,339 - ERROR - Unhandled exception: Object of type ValueError is not JSON serializable
Traceback (most recent call last):
  File "C:\Users\Sobre\OneDrive\Desktop\Vroomble\.venv\Lib\site-packages\starlette\_exception_handler.py", line 42, in wrapped_app
    await app(scope, receive, sender)
  File "C:\Users\Sobre\OneDrive\Desktop\Vroomble\.venv\Lib\site-packages\starlette\routing.py", line 73, in app
    response = await f(request)
               ^^^^^^^^^^^^^^^^
  File "C:\Users\Sobre\OneDrive\Desktop\Vroomble\.venv\Lib\site-packages\fastapi\routing.py", line 346, in app
    raise validation_error
fastapi.exceptions.RequestValidationError: [{'type': 'value_error', 'loc': ('body', 'year'), 'msg': 'Value error, Invalid year', 'input': 0, 'ctx': {'error': ValueError('Invalid year')}}, {'type': 'value_error', 'loc': ('body', 'retail_srp'), 'msg': 'Value error, Retail SRP must be positive', 'input': 0, 'ctx': {'error': ValueError('Retail SRP must be positive')}}]

During handling of the above exception, another exception occurred:

Traceback (most recent call last):
  File "C:\Users\Sobre\OneDrive\Desktop\Vroomble\.venv\Lib\site-packages\starlette\middleware\errors.py", line 165, in __call__
    await self.app(scope, receive, _send)
  File "C:\Users\Sobre\OneDrive\Desktop\Vroomble\.venv\Lib\site-packages\starlette\middleware\cors.py", line 93, in __call__
    await self.simple_response(scope, receive, send, request_headers=headers)
  File "C:\Users\Sobre\OneDrive\Desktop\Vroomble\.venv\Lib\site-packages\starlette\middleware\cors.py", line 144, in simple_response
    await self.app(scope, receive, send)
  File "C:\Users\Sobre\OneDrive\Desktop\Vroomble\.venv\Lib\site-packages\starlette\middleware\exceptions.py", line 62, in __call__
    await wrap_app_handling_exceptions(self.app, conn)(scope, receive, send)
  File "C:\Users\Sobre\OneDrive\Desktop\Vroomble\.venv\Lib\site-packages\starlette\_exception_handler.py", line 53, in wrapped_app
    raise exc
  File "C:\Users\Sobre\OneDrive\Desktop\Vroomble\.venv\Lib\site-packages\starlette\_exception_handler.py", line 42, in wrapped_app
    await app(scope, receive, sender)
  File "C:\Users\Sobre\OneDrive\Desktop\Vroomble\.venv\Lib\site-packages\starlette\routing.py", line 715, in __call__
    await self.middleware_stack(scope, receive, send)
  File "C:\Users\Sobre\OneDrive\Desktop\Vroomble\.venv\Lib\site-packages\starlette\routing.py", line 735, in app
    await route.handle(scope, receive, send)
  File "C:\Users\Sobre\OneDrive\Desktop\Vroomble\.venv\Lib\site-packages\starlette\routing.py", line 288, in handle
    await self.app(scope, receive, send)
  File "C:\Users\Sobre\OneDrive\Desktop\Vroomble\.venv\Lib\site-packages\starlette\routing.py", line 76, in app
    await wrap_app_handling_exceptions(app, request)(scope, receive, send)
  File "C:\Users\Sobre\OneDrive\Desktop\Vroomble\.venv\Lib\site-packages\starlette\_exception_handler.py", line 59, in wrapped_app
    response = await handler(conn, exc)
               ^^^^^^^^^^^^^^^^^^^^^^^^
  File "C:\Users\Sobre\OneDrive\Desktop\Vroomble\src\APIs\vehicle_registration.py", line 172, in validation_exception_handler
    return JSONResponse(
           ^^^^^^^^^^^^^
  File "C:\Users\Sobre\OneDrive\Desktop\Vroomble\.venv\Lib\site-packages\starlette\responses.py", line 181, in __init__
    super().__init__(content, status_code, headers, media_type, background)
  File "C:\Users\Sobre\OneDrive\Desktop\Vroomble\.venv\Lib\site-packages\starlette\responses.py", line 44, in __init__
    self.body = self.render(content)
                ^^^^^^^^^^^^^^^^^^^^
  File "C:\Users\Sobre\OneDrive\Desktop\Vroomble\.venv\Lib\site-packages\starlette\responses.py", line 184, in render
    return json.dumps(
           ^^^^^^^^^^^
  File "C:\Program Files\WindowsApps\PythonSoftwareFoundation.Python.3.11_3.11.2544.0_x64__qbz5n2kfra8p0\Lib\json\__init__.py", line 238, in dumps
    **kw).encode(obj)
          ^^^^^^^^^^^
  File "C:\Program Files\WindowsApps\PythonSoftwareFoundation.Python.3.11_3.11.2544.0_x64__qbz5n2kfra8p0\Lib\json\encoder.py", line 200, in encode
    chunks = self.iterencode(o, _one_shot=True)
             ^^^^^^^^^^^^^^^^^^^^^^^^^^^^^^^^^^
  File "C:\Program Files\WindowsApps\PythonSoftwareFoundation.Python.3.11_3.11.2544.0_x64__qbz5n2kfra8p0\Lib\json\encoder.py", line 258, in iterencode
    return _iterencode(o, 0)
           ^^^^^^^^^^^^^^^^^
  File "C:\Program Files\WindowsApps\PythonSoftwareFoundation.Python.3.11_3.11.2544.0_x64__qbz5n2kfra8p0\Lib\json\encoder.py", line 180, in default
    raise TypeError(f'Object of type {o.__class__.__name__} '
TypeError: Object of type ValueError is not JSON serializable
2025-03-02 02:12:54,203 - ERROR - Validation error: [{'type': 'value_error', 'loc': ('body', 'year'), 'msg': 'Value error, Invalid year', 'input': 0, 'ctx': {'error': ValueError('Invalid year')}}, {'type': 'value_error', 'loc': ('body', 'retail_srp'), 'msg': 'Value error, Retail SRP must be positive', 'input': 0, 'ctx': {'error': ValueError('Retail SRP must be positive')}}]
2025-03-02 02:12:54,203 - ERROR - Unhandled exception: Object of type ValueError is not JSON serializable
Traceback (most recent call last):
  File "C:\Users\Sobre\OneDrive\Desktop\Vroomble\.venv\Lib\site-packages\starlette\_exception_handler.py", line 42, in wrapped_app
    await app(scope, receive, sender)
  File "C:\Users\Sobre\OneDrive\Desktop\Vroomble\.venv\Lib\site-packages\starlette\routing.py", line 73, in app
    response = await f(request)
               ^^^^^^^^^^^^^^^^
  File "C:\Users\Sobre\OneDrive\Desktop\Vroomble\.venv\Lib\site-packages\fastapi\routing.py", line 346, in app
    raise validation_error
fastapi.exceptions.RequestValidationError: [{'type': 'value_error', 'loc': ('body', 'year'), 'msg': 'Value error, Invalid year', 'input': 0, 'ctx': {'error': ValueError('Invalid year')}}, {'type': 'value_error', 'loc': ('body', 'retail_srp'), 'msg': 'Value error, Retail SRP must be positive', 'input': 0, 'ctx': {'error': ValueError('Retail SRP must be positive')}}]

During handling of the above exception, another exception occurred:

Traceback (most recent call last):
  File "C:\Users\Sobre\OneDrive\Desktop\Vroomble\.venv\Lib\site-packages\starlette\middleware\errors.py", line 165, in __call__
    await self.app(scope, receive, _send)
  File "C:\Users\Sobre\OneDrive\Desktop\Vroomble\.venv\Lib\site-packages\starlette\middleware\cors.py", line 93, in __call__
    await self.simple_response(scope, receive, send, request_headers=headers)
  File "C:\Users\Sobre\OneDrive\Desktop\Vroomble\.venv\Lib\site-packages\starlette\middleware\cors.py", line 144, in simple_response
    await self.app(scope, receive, send)
  File "C:\Users\Sobre\OneDrive\Desktop\Vroomble\.venv\Lib\site-packages\starlette\middleware\exceptions.py", line 62, in __call__
    await wrap_app_handling_exceptions(self.app, conn)(scope, receive, send)
  File "C:\Users\Sobre\OneDrive\Desktop\Vroomble\.venv\Lib\site-packages\starlette\_exception_handler.py", line 53, in wrapped_app
    raise exc
  File "C:\Users\Sobre\OneDrive\Desktop\Vroomble\.venv\Lib\site-packages\starlette\_exception_handler.py", line 42, in wrapped_app
    await app(scope, receive, sender)
  File "C:\Users\Sobre\OneDrive\Desktop\Vroomble\.venv\Lib\site-packages\starlette\routing.py", line 715, in __call__
    await self.middleware_stack(scope, receive, send)
  File "C:\Users\Sobre\OneDrive\Desktop\Vroomble\.venv\Lib\site-packages\starlette\routing.py", line 735, in app
    await route.handle(scope, receive, send)
  File "C:\Users\Sobre\OneDrive\Desktop\Vroomble\.venv\Lib\site-packages\starlette\routing.py", line 288, in handle
    await self.app(scope, receive, send)
  File "C:\Users\Sobre\OneDrive\Desktop\Vroomble\.venv\Lib\site-packages\starlette\routing.py", line 76, in app
    await wrap_app_handling_exceptions(app, request)(scope, receive, send)
  File "C:\Users\Sobre\OneDrive\Desktop\Vroomble\.venv\Lib\site-packages\starlette\_exception_handler.py", line 59, in wrapped_app
    response = await handler(conn, exc)
               ^^^^^^^^^^^^^^^^^^^^^^^^
  File "C:\Users\Sobre\OneDrive\Desktop\Vroomble\src\APIs\vehicle_registration.py", line 172, in validation_exception_handler
    return JSONResponse(
           ^^^^^^^^^^^^^
  File "C:\Users\Sobre\OneDrive\Desktop\Vroomble\.venv\Lib\site-packages\starlette\responses.py", line 181, in __init__
    super().__init__(content, status_code, headers, media_type, background)
  File "C:\Users\Sobre\OneDrive\Desktop\Vroomble\.venv\Lib\site-packages\starlette\responses.py", line 44, in __init__
    self.body = self.render(content)
                ^^^^^^^^^^^^^^^^^^^^
  File "C:\Users\Sobre\OneDrive\Desktop\Vroomble\.venv\Lib\site-packages\starlette\responses.py", line 184, in render
    return json.dumps(
           ^^^^^^^^^^^
  File "C:\Program Files\WindowsApps\PythonSoftwareFoundation.Python.3.11_3.11.2544.0_x64__qbz5n2kfra8p0\Lib\json\__init__.py", line 238, in dumps
    **kw).encode(obj)
          ^^^^^^^^^^^
  File "C:\Program Files\WindowsApps\PythonSoftwareFoundation.Python.3.11_3.11.2544.0_x64__qbz5n2kfra8p0\Lib\json\encoder.py", line 200, in encode
    chunks = self.iterencode(o, _one_shot=True)
             ^^^^^^^^^^^^^^^^^^^^^^^^^^^^^^^^^^
  File "C:\Program Files\WindowsApps\PythonSoftwareFoundation.Python.3.11_3.11.2544.0_x64__qbz5n2kfra8p0\Lib\json\encoder.py", line 258, in iterencode
    return _iterencode(o, 0)
           ^^^^^^^^^^^^^^^^^
  File "C:\Program Files\WindowsApps\PythonSoftwareFoundation.Python.3.11_3.11.2544.0_x64__qbz5n2kfra8p0\Lib\json\encoder.py", line 180, in default
    raise TypeError(f'Object of type {o.__class__.__name__} '
TypeError: Object of type ValueError is not JSON serializable
2025-03-02 02:12:56,907 - ERROR - Validation error: [{'type': 'value_error', 'loc': ('body', 'year'), 'msg': 'Value error, Invalid year', 'input': 0, 'ctx': {'error': ValueError('Invalid year')}}, {'type': 'value_error', 'loc': ('body', 'retail_srp'), 'msg': 'Value error, Retail SRP must be positive', 'input': 0, 'ctx': {'error': ValueError('Retail SRP must be positive')}}]
2025-03-02 02:12:56,907 - ERROR - Unhandled exception: Object of type ValueError is not JSON serializable
Traceback (most recent call last):
  File "C:\Users\Sobre\OneDrive\Desktop\Vroomble\.venv\Lib\site-packages\starlette\_exception_handler.py", line 42, in wrapped_app
    await app(scope, receive, sender)
  File "C:\Users\Sobre\OneDrive\Desktop\Vroomble\.venv\Lib\site-packages\starlette\routing.py", line 73, in app
    response = await f(request)
               ^^^^^^^^^^^^^^^^
  File "C:\Users\Sobre\OneDrive\Desktop\Vroomble\.venv\Lib\site-packages\fastapi\routing.py", line 346, in app
    raise validation_error
fastapi.exceptions.RequestValidationError: [{'type': 'value_error', 'loc': ('body', 'year'), 'msg': 'Value error, Invalid year', 'input': 0, 'ctx': {'error': ValueError('Invalid year')}}, {'type': 'value_error', 'loc': ('body', 'retail_srp'), 'msg': 'Value error, Retail SRP must be positive', 'input': 0, 'ctx': {'error': ValueError('Retail SRP must be positive')}}]

During handling of the above exception, another exception occurred:

Traceback (most recent call last):
  File "C:\Users\Sobre\OneDrive\Desktop\Vroomble\.venv\Lib\site-packages\starlette\middleware\errors.py", line 165, in __call__
    await self.app(scope, receive, _send)
  File "C:\Users\Sobre\OneDrive\Desktop\Vroomble\.venv\Lib\site-packages\starlette\middleware\cors.py", line 93, in __call__
    await self.simple_response(scope, receive, send, request_headers=headers)
  File "C:\Users\Sobre\OneDrive\Desktop\Vroomble\.venv\Lib\site-packages\starlette\middleware\cors.py", line 144, in simple_response
    await self.app(scope, receive, send)
  File "C:\Users\Sobre\OneDrive\Desktop\Vroomble\.venv\Lib\site-packages\starlette\middleware\exceptions.py", line 62, in __call__
    await wrap_app_handling_exceptions(self.app, conn)(scope, receive, send)
  File "C:\Users\Sobre\OneDrive\Desktop\Vroomble\.venv\Lib\site-packages\starlette\_exception_handler.py", line 53, in wrapped_app
    raise exc
  File "C:\Users\Sobre\OneDrive\Desktop\Vroomble\.venv\Lib\site-packages\starlette\_exception_handler.py", line 42, in wrapped_app
    await app(scope, receive, sender)
  File "C:\Users\Sobre\OneDrive\Desktop\Vroomble\.venv\Lib\site-packages\starlette\routing.py", line 715, in __call__
    await self.middleware_stack(scope, receive, send)
  File "C:\Users\Sobre\OneDrive\Desktop\Vroomble\.venv\Lib\site-packages\starlette\routing.py", line 735, in app
    await route.handle(scope, receive, send)
  File "C:\Users\Sobre\OneDrive\Desktop\Vroomble\.venv\Lib\site-packages\starlette\routing.py", line 288, in handle
    await self.app(scope, receive, send)
  File "C:\Users\Sobre\OneDrive\Desktop\Vroomble\.venv\Lib\site-packages\starlette\routing.py", line 76, in app
    await wrap_app_handling_exceptions(app, request)(scope, receive, send)
  File "C:\Users\Sobre\OneDrive\Desktop\Vroomble\.venv\Lib\site-packages\starlette\_exception_handler.py", line 59, in wrapped_app
    response = await handler(conn, exc)
               ^^^^^^^^^^^^^^^^^^^^^^^^
  File "C:\Users\Sobre\OneDrive\Desktop\Vroomble\src\APIs\vehicle_registration.py", line 172, in validation_exception_handler
    return JSONResponse(
           ^^^^^^^^^^^^^
  File "C:\Users\Sobre\OneDrive\Desktop\Vroomble\.venv\Lib\site-packages\starlette\responses.py", line 181, in __init__
    super().__init__(content, status_code, headers, media_type, background)
  File "C:\Users\Sobre\OneDrive\Desktop\Vroomble\.venv\Lib\site-packages\starlette\responses.py", line 44, in __init__
    self.body = self.render(content)
                ^^^^^^^^^^^^^^^^^^^^
  File "C:\Users\Sobre\OneDrive\Desktop\Vroomble\.venv\Lib\site-packages\starlette\responses.py", line 184, in render
    return json.dumps(
           ^^^^^^^^^^^
  File "C:\Program Files\WindowsApps\PythonSoftwareFoundation.Python.3.11_3.11.2544.0_x64__qbz5n2kfra8p0\Lib\json\__init__.py", line 238, in dumps
    **kw).encode(obj)
          ^^^^^^^^^^^
  File "C:\Program Files\WindowsApps\PythonSoftwareFoundation.Python.3.11_3.11.2544.0_x64__qbz5n2kfra8p0\Lib\json\encoder.py", line 200, in encode
    chunks = self.iterencode(o, _one_shot=True)
             ^^^^^^^^^^^^^^^^^^^^^^^^^^^^^^^^^^
  File "C:\Program Files\WindowsApps\PythonSoftwareFoundation.Python.3.11_3.11.2544.0_x64__qbz5n2kfra8p0\Lib\json\encoder.py", line 258, in iterencode
    return _iterencode(o, 0)
           ^^^^^^^^^^^^^^^^^
  File "C:\Program Files\WindowsApps\PythonSoftwareFoundation.Python.3.11_3.11.2544.0_x64__qbz5n2kfra8p0\Lib\json\encoder.py", line 180, in default
    raise TypeError(f'Object of type {o.__class__.__name__} '
TypeError: Object of type ValueError is not JSON serializable
2025-03-02 02:12:59,774 - ERROR - Validation error: [{'type': 'value_error', 'loc': ('body', 'year'), 'msg': 'Value error, Invalid year', 'input': 0, 'ctx': {'error': ValueError('Invalid year')}}, {'type': 'value_error', 'loc': ('body', 'retail_srp'), 'msg': 'Value error, Retail SRP must be positive', 'input': 0, 'ctx': {'error': ValueError('Retail SRP must be positive')}}]
2025-03-02 02:12:59,774 - ERROR - Unhandled exception: Object of type ValueError is not JSON serializable
Traceback (most recent call last):
  File "C:\Users\Sobre\OneDrive\Desktop\Vroomble\.venv\Lib\site-packages\starlette\_exception_handler.py", line 42, in wrapped_app
    await app(scope, receive, sender)
  File "C:\Users\Sobre\OneDrive\Desktop\Vroomble\.venv\Lib\site-packages\starlette\routing.py", line 73, in app
    response = await f(request)
               ^^^^^^^^^^^^^^^^
  File "C:\Users\Sobre\OneDrive\Desktop\Vroomble\.venv\Lib\site-packages\fastapi\routing.py", line 346, in app
    raise validation_error
fastapi.exceptions.RequestValidationError: [{'type': 'value_error', 'loc': ('body', 'year'), 'msg': 'Value error, Invalid year', 'input': 0, 'ctx': {'error': ValueError('Invalid year')}}, {'type': 'value_error', 'loc': ('body', 'retail_srp'), 'msg': 'Value error, Retail SRP must be positive', 'input': 0, 'ctx': {'error': ValueError('Retail SRP must be positive')}}]

During handling of the above exception, another exception occurred:

Traceback (most recent call last):
  File "C:\Users\Sobre\OneDrive\Desktop\Vroomble\.venv\Lib\site-packages\starlette\middleware\errors.py", line 165, in __call__
    await self.app(scope, receive, _send)
  File "C:\Users\Sobre\OneDrive\Desktop\Vroomble\.venv\Lib\site-packages\starlette\middleware\cors.py", line 93, in __call__
    await self.simple_response(scope, receive, send, request_headers=headers)
  File "C:\Users\Sobre\OneDrive\Desktop\Vroomble\.venv\Lib\site-packages\starlette\middleware\cors.py", line 144, in simple_response
    await self.app(scope, receive, send)
  File "C:\Users\Sobre\OneDrive\Desktop\Vroomble\.venv\Lib\site-packages\starlette\middleware\exceptions.py", line 62, in __call__
    await wrap_app_handling_exceptions(self.app, conn)(scope, receive, send)
  File "C:\Users\Sobre\OneDrive\Desktop\Vroomble\.venv\Lib\site-packages\starlette\_exception_handler.py", line 53, in wrapped_app
    raise exc
  File "C:\Users\Sobre\OneDrive\Desktop\Vroomble\.venv\Lib\site-packages\starlette\_exception_handler.py", line 42, in wrapped_app
    await app(scope, receive, sender)
  File "C:\Users\Sobre\OneDrive\Desktop\Vroomble\.venv\Lib\site-packages\starlette\routing.py", line 715, in __call__
    await self.middleware_stack(scope, receive, send)
  File "C:\Users\Sobre\OneDrive\Desktop\Vroomble\.venv\Lib\site-packages\starlette\routing.py", line 735, in app
    await route.handle(scope, receive, send)
  File "C:\Users\Sobre\OneDrive\Desktop\Vroomble\.venv\Lib\site-packages\starlette\routing.py", line 288, in handle
    await self.app(scope, receive, send)
  File "C:\Users\Sobre\OneDrive\Desktop\Vroomble\.venv\Lib\site-packages\starlette\routing.py", line 76, in app
    await wrap_app_handling_exceptions(app, request)(scope, receive, send)
  File "C:\Users\Sobre\OneDrive\Desktop\Vroomble\.venv\Lib\site-packages\starlette\_exception_handler.py", line 59, in wrapped_app
    response = await handler(conn, exc)
               ^^^^^^^^^^^^^^^^^^^^^^^^
  File "C:\Users\Sobre\OneDrive\Desktop\Vroomble\src\APIs\vehicle_registration.py", line 172, in validation_exception_handler
    return JSONResponse(
           ^^^^^^^^^^^^^
  File "C:\Users\Sobre\OneDrive\Desktop\Vroomble\.venv\Lib\site-packages\starlette\responses.py", line 181, in __init__
    super().__init__(content, status_code, headers, media_type, background)
  File "C:\Users\Sobre\OneDrive\Desktop\Vroomble\.venv\Lib\site-packages\starlette\responses.py", line 44, in __init__
    self.body = self.render(content)
                ^^^^^^^^^^^^^^^^^^^^
  File "C:\Users\Sobre\OneDrive\Desktop\Vroomble\.venv\Lib\site-packages\starlette\responses.py", line 184, in render
    return json.dumps(
           ^^^^^^^^^^^
  File "C:\Program Files\WindowsApps\PythonSoftwareFoundation.Python.3.11_3.11.2544.0_x64__qbz5n2kfra8p0\Lib\json\__init__.py", line 238, in dumps
    **kw).encode(obj)
          ^^^^^^^^^^^
  File "C:\Program Files\WindowsApps\PythonSoftwareFoundation.Python.3.11_3.11.2544.0_x64__qbz5n2kfra8p0\Lib\json\encoder.py", line 200, in encode
    chunks = self.iterencode(o, _one_shot=True)
             ^^^^^^^^^^^^^^^^^^^^^^^^^^^^^^^^^^
  File "C:\Program Files\WindowsApps\PythonSoftwareFoundation.Python.3.11_3.11.2544.0_x64__qbz5n2kfra8p0\Lib\json\encoder.py", line 258, in iterencode
    return _iterencode(o, 0)
           ^^^^^^^^^^^^^^^^^
  File "C:\Program Files\WindowsApps\PythonSoftwareFoundation.Python.3.11_3.11.2544.0_x64__qbz5n2kfra8p0\Lib\json\encoder.py", line 180, in default
    raise TypeError(f'Object of type {o.__class__.__name__} '
TypeError: Object of type ValueError is not JSON serializable
2025-03-02 02:13:02,454 - ERROR - Validation error: [{'type': 'value_error', 'loc': ('body', 'year'), 'msg': 'Value error, Invalid year', 'input': 0, 'ctx': {'error': ValueError('Invalid year')}}, {'type': 'value_error', 'loc': ('body', 'retail_srp'), 'msg': 'Value error, Retail SRP must be positive', 'input': 0, 'ctx': {'error': ValueError('Retail SRP must be positive')}}]
2025-03-02 02:13:02,454 - ERROR - Unhandled exception: Object of type ValueError is not JSON serializable
Traceback (most recent call last):
  File "C:\Users\Sobre\OneDrive\Desktop\Vroomble\.venv\Lib\site-packages\starlette\_exception_handler.py", line 42, in wrapped_app
    await app(scope, receive, sender)
  File "C:\Users\Sobre\OneDrive\Desktop\Vroomble\.venv\Lib\site-packages\starlette\routing.py", line 73, in app
    response = await f(request)
               ^^^^^^^^^^^^^^^^
  File "C:\Users\Sobre\OneDrive\Desktop\Vroomble\.venv\Lib\site-packages\fastapi\routing.py", line 346, in app
    raise validation_error
fastapi.exceptions.RequestValidationError: [{'type': 'value_error', 'loc': ('body', 'year'), 'msg': 'Value error, Invalid year', 'input': 0, 'ctx': {'error': ValueError('Invalid year')}}, {'type': 'value_error', 'loc': ('body', 'retail_srp'), 'msg': 'Value error, Retail SRP must be positive', 'input': 0, 'ctx': {'error': ValueError('Retail SRP must be positive')}}]

During handling of the above exception, another exception occurred:

Traceback (most recent call last):
  File "C:\Users\Sobre\OneDrive\Desktop\Vroomble\.venv\Lib\site-packages\starlette\middleware\errors.py", line 165, in __call__
    await self.app(scope, receive, _send)
  File "C:\Users\Sobre\OneDrive\Desktop\Vroomble\.venv\Lib\site-packages\starlette\middleware\cors.py", line 93, in __call__
    await self.simple_response(scope, receive, send, request_headers=headers)
  File "C:\Users\Sobre\OneDrive\Desktop\Vroomble\.venv\Lib\site-packages\starlette\middleware\cors.py", line 144, in simple_response
    await self.app(scope, receive, send)
  File "C:\Users\Sobre\OneDrive\Desktop\Vroomble\.venv\Lib\site-packages\starlette\middleware\exceptions.py", line 62, in __call__
    await wrap_app_handling_exceptions(self.app, conn)(scope, receive, send)
  File "C:\Users\Sobre\OneDrive\Desktop\Vroomble\.venv\Lib\site-packages\starlette\_exception_handler.py", line 53, in wrapped_app
    raise exc
  File "C:\Users\Sobre\OneDrive\Desktop\Vroomble\.venv\Lib\site-packages\starlette\_exception_handler.py", line 42, in wrapped_app
    await app(scope, receive, sender)
  File "C:\Users\Sobre\OneDrive\Desktop\Vroomble\.venv\Lib\site-packages\starlette\routing.py", line 715, in __call__
    await self.middleware_stack(scope, receive, send)
  File "C:\Users\Sobre\OneDrive\Desktop\Vroomble\.venv\Lib\site-packages\starlette\routing.py", line 735, in app
    await route.handle(scope, receive, send)
  File "C:\Users\Sobre\OneDrive\Desktop\Vroomble\.venv\Lib\site-packages\starlette\routing.py", line 288, in handle
    await self.app(scope, receive, send)
  File "C:\Users\Sobre\OneDrive\Desktop\Vroomble\.venv\Lib\site-packages\starlette\routing.py", line 76, in app
    await wrap_app_handling_exceptions(app, request)(scope, receive, send)
  File "C:\Users\Sobre\OneDrive\Desktop\Vroomble\.venv\Lib\site-packages\starlette\_exception_handler.py", line 59, in wrapped_app
    response = await handler(conn, exc)
               ^^^^^^^^^^^^^^^^^^^^^^^^
  File "C:\Users\Sobre\OneDrive\Desktop\Vroomble\src\APIs\vehicle_registration.py", line 172, in validation_exception_handler
    return JSONResponse(
           ^^^^^^^^^^^^^
  File "C:\Users\Sobre\OneDrive\Desktop\Vroomble\.venv\Lib\site-packages\starlette\responses.py", line 181, in __init__
    super().__init__(content, status_code, headers, media_type, background)
  File "C:\Users\Sobre\OneDrive\Desktop\Vroomble\.venv\Lib\site-packages\starlette\responses.py", line 44, in __init__
    self.body = self.render(content)
                ^^^^^^^^^^^^^^^^^^^^
  File "C:\Users\Sobre\OneDrive\Desktop\Vroomble\.venv\Lib\site-packages\starlette\responses.py", line 184, in render
    return json.dumps(
           ^^^^^^^^^^^
  File "C:\Program Files\WindowsApps\PythonSoftwareFoundation.Python.3.11_3.11.2544.0_x64__qbz5n2kfra8p0\Lib\json\__init__.py", line 238, in dumps
    **kw).encode(obj)
          ^^^^^^^^^^^
  File "C:\Program Files\WindowsApps\PythonSoftwareFoundation.Python.3.11_3.11.2544.0_x64__qbz5n2kfra8p0\Lib\json\encoder.py", line 200, in encode
    chunks = self.iterencode(o, _one_shot=True)
             ^^^^^^^^^^^^^^^^^^^^^^^^^^^^^^^^^^
  File "C:\Program Files\WindowsApps\PythonSoftwareFoundation.Python.3.11_3.11.2544.0_x64__qbz5n2kfra8p0\Lib\json\encoder.py", line 258, in iterencode
    return _iterencode(o, 0)
           ^^^^^^^^^^^^^^^^^
  File "C:\Program Files\WindowsApps\PythonSoftwareFoundation.Python.3.11_3.11.2544.0_x64__qbz5n2kfra8p0\Lib\json\encoder.py", line 180, in default
    raise TypeError(f'Object of type {o.__class__.__name__} '
TypeError: Object of type ValueError is not JSON serializable
2025-03-02 02:13:48,125 - ERROR - Validation error: [{'type': 'value_error', 'loc': ('body', 'year'), 'msg': 'Value error, Invalid year', 'input': 0, 'ctx': {'error': ValueError('Invalid year')}}, {'type': 'value_error', 'loc': ('body', 'retail_srp'), 'msg': 'Value error, Retail SRP must be positive', 'input': 0, 'ctx': {'error': ValueError('Retail SRP must be positive')}}]
2025-03-02 02:13:48,125 - ERROR - Unhandled exception: Object of type ValueError is not JSON serializable
Traceback (most recent call last):
  File "C:\Users\Sobre\OneDrive\Desktop\Vroomble\.venv\Lib\site-packages\starlette\_exception_handler.py", line 42, in wrapped_app
    await app(scope, receive, sender)
  File "C:\Users\Sobre\OneDrive\Desktop\Vroomble\.venv\Lib\site-packages\starlette\routing.py", line 73, in app
    response = await f(request)
               ^^^^^^^^^^^^^^^^
  File "C:\Users\Sobre\OneDrive\Desktop\Vroomble\.venv\Lib\site-packages\fastapi\routing.py", line 346, in app
    raise validation_error
fastapi.exceptions.RequestValidationError: [{'type': 'value_error', 'loc': ('body', 'year'), 'msg': 'Value error, Invalid year', 'input': 0, 'ctx': {'error': ValueError('Invalid year')}}, {'type': 'value_error', 'loc': ('body', 'retail_srp'), 'msg': 'Value error, Retail SRP must be positive', 'input': 0, 'ctx': {'error': ValueError('Retail SRP must be positive')}}]

During handling of the above exception, another exception occurred:

Traceback (most recent call last):
  File "C:\Users\Sobre\OneDrive\Desktop\Vroomble\.venv\Lib\site-packages\starlette\middleware\errors.py", line 165, in __call__
    await self.app(scope, receive, _send)
  File "C:\Users\Sobre\OneDrive\Desktop\Vroomble\.venv\Lib\site-packages\starlette\middleware\cors.py", line 93, in __call__
    await self.simple_response(scope, receive, send, request_headers=headers)
  File "C:\Users\Sobre\OneDrive\Desktop\Vroomble\.venv\Lib\site-packages\starlette\middleware\cors.py", line 144, in simple_response
    await self.app(scope, receive, send)
  File "C:\Users\Sobre\OneDrive\Desktop\Vroomble\.venv\Lib\site-packages\starlette\middleware\exceptions.py", line 62, in __call__
    await wrap_app_handling_exceptions(self.app, conn)(scope, receive, send)
  File "C:\Users\Sobre\OneDrive\Desktop\Vroomble\.venv\Lib\site-packages\starlette\_exception_handler.py", line 53, in wrapped_app
    raise exc
  File "C:\Users\Sobre\OneDrive\Desktop\Vroomble\.venv\Lib\site-packages\starlette\_exception_handler.py", line 42, in wrapped_app
    await app(scope, receive, sender)
  File "C:\Users\Sobre\OneDrive\Desktop\Vroomble\.venv\Lib\site-packages\starlette\routing.py", line 715, in __call__
    await self.middleware_stack(scope, receive, send)
  File "C:\Users\Sobre\OneDrive\Desktop\Vroomble\.venv\Lib\site-packages\starlette\routing.py", line 735, in app
    await route.handle(scope, receive, send)
  File "C:\Users\Sobre\OneDrive\Desktop\Vroomble\.venv\Lib\site-packages\starlette\routing.py", line 288, in handle
    await self.app(scope, receive, send)
  File "C:\Users\Sobre\OneDrive\Desktop\Vroomble\.venv\Lib\site-packages\starlette\routing.py", line 76, in app
    await wrap_app_handling_exceptions(app, request)(scope, receive, send)
  File "C:\Users\Sobre\OneDrive\Desktop\Vroomble\.venv\Lib\site-packages\starlette\_exception_handler.py", line 59, in wrapped_app
    response = await handler(conn, exc)
               ^^^^^^^^^^^^^^^^^^^^^^^^
  File "C:\Users\Sobre\OneDrive\Desktop\Vroomble\src\APIs\vehicle_registration.py", line 172, in validation_exception_handler
    return JSONResponse(
           ^^^^^^^^^^^^^
  File "C:\Users\Sobre\OneDrive\Desktop\Vroomble\.venv\Lib\site-packages\starlette\responses.py", line 181, in __init__
    super().__init__(content, status_code, headers, media_type, background)
  File "C:\Users\Sobre\OneDrive\Desktop\Vroomble\.venv\Lib\site-packages\starlette\responses.py", line 44, in __init__
    self.body = self.render(content)
                ^^^^^^^^^^^^^^^^^^^^
  File "C:\Users\Sobre\OneDrive\Desktop\Vroomble\.venv\Lib\site-packages\starlette\responses.py", line 184, in render
    return json.dumps(
           ^^^^^^^^^^^
  File "C:\Program Files\WindowsApps\PythonSoftwareFoundation.Python.3.11_3.11.2544.0_x64__qbz5n2kfra8p0\Lib\json\__init__.py", line 238, in dumps
    **kw).encode(obj)
          ^^^^^^^^^^^
  File "C:\Program Files\WindowsApps\PythonSoftwareFoundation.Python.3.11_3.11.2544.0_x64__qbz5n2kfra8p0\Lib\json\encoder.py", line 200, in encode
    chunks = self.iterencode(o, _one_shot=True)
             ^^^^^^^^^^^^^^^^^^^^^^^^^^^^^^^^^^
  File "C:\Program Files\WindowsApps\PythonSoftwareFoundation.Python.3.11_3.11.2544.0_x64__qbz5n2kfra8p0\Lib\json\encoder.py", line 258, in iterencode
    return _iterencode(o, 0)
           ^^^^^^^^^^^^^^^^^
  File "C:\Program Files\WindowsApps\PythonSoftwareFoundation.Python.3.11_3.11.2544.0_x64__qbz5n2kfra8p0\Lib\json\encoder.py", line 180, in default
    raise TypeError(f'Object of type {o.__class__.__name__} '
TypeError: Object of type ValueError is not JSON serializable
2025-03-02 02:17:22,284 - INFO - Database table created or already exists.
2025-03-02 02:17:35,022 - ERROR - Validation error: [{'type': 'value_error', 'loc': ('body', 'year'), 'msg': 'Value error, Invalid year', 'input': 0, 'ctx': {'error': ValueError('Invalid year')}}, {'type': 'value_error', 'loc': ('body', 'retail_srp'), 'msg': 'Value error, Retail SRP must be positive', 'input': 0, 'ctx': {'error': ValueError('Retail SRP must be positive')}}]
2025-03-02 02:17:35,022 - ERROR - Unhandled exception: Object of type ValueError is not JSON serializable
Traceback (most recent call last):
  File "C:\Users\Sobre\OneDrive\Desktop\Vroomble\.venv\Lib\site-packages\starlette\_exception_handler.py", line 42, in wrapped_app
    await app(scope, receive, sender)
  File "C:\Users\Sobre\OneDrive\Desktop\Vroomble\.venv\Lib\site-packages\starlette\routing.py", line 73, in app
    response = await f(request)
               ^^^^^^^^^^^^^^^^
  File "C:\Users\Sobre\OneDrive\Desktop\Vroomble\.venv\Lib\site-packages\fastapi\routing.py", line 346, in app
    raise validation_error
fastapi.exceptions.RequestValidationError: [{'type': 'value_error', 'loc': ('body', 'year'), 'msg': 'Value error, Invalid year', 'input': 0, 'ctx': {'error': ValueError('Invalid year')}}, {'type': 'value_error', 'loc': ('body', 'retail_srp'), 'msg': 'Value error, Retail SRP must be positive', 'input': 0, 'ctx': {'error': ValueError('Retail SRP must be positive')}}]

During handling of the above exception, another exception occurred:

Traceback (most recent call last):
  File "C:\Users\Sobre\OneDrive\Desktop\Vroomble\.venv\Lib\site-packages\starlette\middleware\errors.py", line 165, in __call__
    await self.app(scope, receive, _send)
  File "C:\Users\Sobre\OneDrive\Desktop\Vroomble\.venv\Lib\site-packages\starlette\middleware\cors.py", line 93, in __call__
    await self.simple_response(scope, receive, send, request_headers=headers)
  File "C:\Users\Sobre\OneDrive\Desktop\Vroomble\.venv\Lib\site-packages\starlette\middleware\cors.py", line 144, in simple_response
    await self.app(scope, receive, send)
  File "C:\Users\Sobre\OneDrive\Desktop\Vroomble\.venv\Lib\site-packages\starlette\middleware\exceptions.py", line 62, in __call__
    await wrap_app_handling_exceptions(self.app, conn)(scope, receive, send)
  File "C:\Users\Sobre\OneDrive\Desktop\Vroomble\.venv\Lib\site-packages\starlette\_exception_handler.py", line 53, in wrapped_app
    raise exc
  File "C:\Users\Sobre\OneDrive\Desktop\Vroomble\.venv\Lib\site-packages\starlette\_exception_handler.py", line 42, in wrapped_app
    await app(scope, receive, sender)
  File "C:\Users\Sobre\OneDrive\Desktop\Vroomble\.venv\Lib\site-packages\starlette\routing.py", line 715, in __call__
    await self.middleware_stack(scope, receive, send)
  File "C:\Users\Sobre\OneDrive\Desktop\Vroomble\.venv\Lib\site-packages\starlette\routing.py", line 735, in app
    await route.handle(scope, receive, send)
  File "C:\Users\Sobre\OneDrive\Desktop\Vroomble\.venv\Lib\site-packages\starlette\routing.py", line 288, in handle
    await self.app(scope, receive, send)
  File "C:\Users\Sobre\OneDrive\Desktop\Vroomble\.venv\Lib\site-packages\starlette\routing.py", line 76, in app
    await wrap_app_handling_exceptions(app, request)(scope, receive, send)
  File "C:\Users\Sobre\OneDrive\Desktop\Vroomble\.venv\Lib\site-packages\starlette\_exception_handler.py", line 59, in wrapped_app
    response = await handler(conn, exc)
               ^^^^^^^^^^^^^^^^^^^^^^^^
  File "C:\Users\Sobre\OneDrive\Desktop\Vroomble\src\APIs\vehicle_registration.py", line 172, in validation_exception_handler
    return JSONResponse(
           ^^^^^^^^^^^^^
  File "C:\Users\Sobre\OneDrive\Desktop\Vroomble\.venv\Lib\site-packages\starlette\responses.py", line 181, in __init__
    super().__init__(content, status_code, headers, media_type, background)
  File "C:\Users\Sobre\OneDrive\Desktop\Vroomble\.venv\Lib\site-packages\starlette\responses.py", line 44, in __init__
    self.body = self.render(content)
                ^^^^^^^^^^^^^^^^^^^^
  File "C:\Users\Sobre\OneDrive\Desktop\Vroomble\.venv\Lib\site-packages\starlette\responses.py", line 184, in render
    return json.dumps(
           ^^^^^^^^^^^
  File "C:\Program Files\WindowsApps\PythonSoftwareFoundation.Python.3.11_3.11.2544.0_x64__qbz5n2kfra8p0\Lib\json\__init__.py", line 238, in dumps
    **kw).encode(obj)
          ^^^^^^^^^^^
  File "C:\Program Files\WindowsApps\PythonSoftwareFoundation.Python.3.11_3.11.2544.0_x64__qbz5n2kfra8p0\Lib\json\encoder.py", line 200, in encode
    chunks = self.iterencode(o, _one_shot=True)
             ^^^^^^^^^^^^^^^^^^^^^^^^^^^^^^^^^^
  File "C:\Program Files\WindowsApps\PythonSoftwareFoundation.Python.3.11_3.11.2544.0_x64__qbz5n2kfra8p0\Lib\json\encoder.py", line 258, in iterencode
    return _iterencode(o, 0)
           ^^^^^^^^^^^^^^^^^
  File "C:\Program Files\WindowsApps\PythonSoftwareFoundation.Python.3.11_3.11.2544.0_x64__qbz5n2kfra8p0\Lib\json\encoder.py", line 180, in default
    raise TypeError(f'Object of type {o.__class__.__name__} '
TypeError: Object of type ValueError is not JSON serializable
2025-03-02 02:20:04,008 - INFO - Database table created or already exists.
2025-03-02 08:40:12,272 - INFO - Database table created or already exists.
2025-03-02 10:17:08,627 - INFO - Database table created or already exists.
2025-03-02 10:19:55,246 - INFO - Database and table created successfully (if not already existing).
2025-03-02 10:22:08,438 - INFO - Database and table created successfully (if not already existing).
2025-03-02 10:25:02,177 - INFO - Database and table created successfully (if not already existing).
2025-03-02 10:26:47,810 - INFO - Database and table created successfully (if not already existing).
2025-03-02 10:27:09,702 - INFO - Executing SQL: 
            INSERT INTO cars (Make, Model, Body_Type, Transmission, Drivetrain, Fuel_Type, Year, Retail_SRP, Variant)
            VALUES (?, ?, ?, ?, ?, ?, ?, ?, ?)
         with values ('TOYOTA', 'FORTUNER', 'SUV', 'CVT', 'RWD', 'Diesel', 2014, '1300000.00', 'G')
2025-03-02 10:27:09,706 - INFO - Car added successfully: make='TOYOTA' model='FORTUNER' body_type='SUV' variant='G' transmission='CVT' drivetrain='RWD' fuel_type='Diesel' year=2014 retail_srp=1300000.0
2025-03-02 10:29:37,288 - INFO - Executing SQL: 
            INSERT INTO cars (Make, Model, Body_Type, Transmission, Drivetrain, Fuel_Type, Year, Retail_SRP, Variant)
            VALUES (?, ?, ?, ?, ?, ?, ?, ?, ?)
         with values ('MOTOLITE', 'FORTUNER', 'SUV', 'CVT', 'RWD', '', 2014, '1300000.00', 'G')
2025-03-02 10:29:37,291 - INFO - Car added successfully: make='MOTOLITE' model='FORTUNER' body_type='SUV' variant='G' transmission='CVT' drivetrain='RWD' fuel_type='' year=2014 retail_srp=1300000.0
2025-03-02 10:30:19,010 - INFO - Database and table created successfully (if not already existing).
2025-03-02 10:41:21,948 - INFO - Database and table created successfully (if not already existing).
2025-03-02 11:17:26,347 - INFO - Database and table created successfully (if not already existing).
2025-03-02 11:19:33,832 - INFO - Database and table created successfully (if not already existing).
2025-03-02 11:21:03,829 - ERROR - Unhandled exception: Expecting value: line 1 column 1 (char 0)
Traceback (most recent call last):
  File "C:\Users\Sobre\OneDrive\Desktop\Vroomble\.venv\Lib\site-packages\starlette\middleware\errors.py", line 165, in __call__
    await self.app(scope, receive, _send)
  File "C:\Users\Sobre\OneDrive\Desktop\Vroomble\.venv\Lib\site-packages\starlette\middleware\cors.py", line 93, in __call__
    await self.simple_response(scope, receive, send, request_headers=headers)
  File "C:\Users\Sobre\OneDrive\Desktop\Vroomble\.venv\Lib\site-packages\starlette\middleware\cors.py", line 144, in simple_response
    await self.app(scope, receive, send)
  File "C:\Users\Sobre\OneDrive\Desktop\Vroomble\.venv\Lib\site-packages\starlette\middleware\exceptions.py", line 62, in __call__
    await wrap_app_handling_exceptions(self.app, conn)(scope, receive, send)
  File "C:\Users\Sobre\OneDrive\Desktop\Vroomble\.venv\Lib\site-packages\starlette\_exception_handler.py", line 53, in wrapped_app
    raise exc
  File "C:\Users\Sobre\OneDrive\Desktop\Vroomble\.venv\Lib\site-packages\starlette\_exception_handler.py", line 42, in wrapped_app
    await app(scope, receive, sender)
  File "C:\Users\Sobre\OneDrive\Desktop\Vroomble\.venv\Lib\site-packages\starlette\routing.py", line 715, in __call__
    await self.middleware_stack(scope, receive, send)
  File "C:\Users\Sobre\OneDrive\Desktop\Vroomble\.venv\Lib\site-packages\starlette\routing.py", line 735, in app
    await route.handle(scope, receive, send)
  File "C:\Users\Sobre\OneDrive\Desktop\Vroomble\.venv\Lib\site-packages\starlette\routing.py", line 288, in handle
    await self.app(scope, receive, send)
  File "C:\Users\Sobre\OneDrive\Desktop\Vroomble\.venv\Lib\site-packages\starlette\routing.py", line 76, in app
    await wrap_app_handling_exceptions(app, request)(scope, receive, send)
  File "C:\Users\Sobre\OneDrive\Desktop\Vroomble\.venv\Lib\site-packages\starlette\_exception_handler.py", line 53, in wrapped_app
    raise exc
  File "C:\Users\Sobre\OneDrive\Desktop\Vroomble\.venv\Lib\site-packages\starlette\_exception_handler.py", line 42, in wrapped_app
    await app(scope, receive, sender)
  File "C:\Users\Sobre\OneDrive\Desktop\Vroomble\.venv\Lib\site-packages\starlette\routing.py", line 73, in app
    response = await f(request)
               ^^^^^^^^^^^^^^^^
  File "C:\Users\Sobre\OneDrive\Desktop\Vroomble\.venv\Lib\site-packages\fastapi\routing.py", line 301, in app
    raw_response = await run_endpoint_function(
                   ^^^^^^^^^^^^^^^^^^^^^^^^^^^^
  File "C:\Users\Sobre\OneDrive\Desktop\Vroomble\.venv\Lib\site-packages\fastapi\routing.py", line 212, in run_endpoint_function
    return await dependant.call(**values)
           ^^^^^^^^^^^^^^^^^^^^^^^^^^^^^^
  File "C:\Users\Sobre\OneDrive\Desktop\Vroomble\src\APIs\vehicle_registration.py", line 75, in submit_form
    body = await request.json()
           ^^^^^^^^^^^^^^^^^^^^
  File "C:\Users\Sobre\OneDrive\Desktop\Vroomble\.venv\Lib\site-packages\starlette\requests.py", line 249, in json
    self._json = json.loads(body)
                 ^^^^^^^^^^^^^^^^
  File "C:\Program Files\WindowsApps\PythonSoftwareFoundation.Python.3.11_3.11.2544.0_x64__qbz5n2kfra8p0\Lib\json\__init__.py", line 346, in loads
    return _default_decoder.decode(s)
           ^^^^^^^^^^^^^^^^^^^^^^^^^^
  File "C:\Program Files\WindowsApps\PythonSoftwareFoundation.Python.3.11_3.11.2544.0_x64__qbz5n2kfra8p0\Lib\json\decoder.py", line 337, in decode
    obj, end = self.raw_decode(s, idx=_w(s, 0).end())
               ^^^^^^^^^^^^^^^^^^^^^^^^^^^^^^^^^^^^^^
  File "C:\Program Files\WindowsApps\PythonSoftwareFoundation.Python.3.11_3.11.2544.0_x64__qbz5n2kfra8p0\Lib\json\decoder.py", line 355, in raw_decode
    raise JSONDecodeError("Expecting value", s, err.value) from None
json.decoder.JSONDecodeError: Expecting value: line 1 column 1 (char 0)
2025-03-02 11:21:05,566 - ERROR - Unhandled exception: Expecting value: line 1 column 1 (char 0)
Traceback (most recent call last):
  File "C:\Users\Sobre\OneDrive\Desktop\Vroomble\.venv\Lib\site-packages\starlette\middleware\errors.py", line 165, in __call__
    await self.app(scope, receive, _send)
  File "C:\Users\Sobre\OneDrive\Desktop\Vroomble\.venv\Lib\site-packages\starlette\middleware\cors.py", line 93, in __call__
    await self.simple_response(scope, receive, send, request_headers=headers)
  File "C:\Users\Sobre\OneDrive\Desktop\Vroomble\.venv\Lib\site-packages\starlette\middleware\cors.py", line 144, in simple_response
    await self.app(scope, receive, send)
  File "C:\Users\Sobre\OneDrive\Desktop\Vroomble\.venv\Lib\site-packages\starlette\middleware\exceptions.py", line 62, in __call__
    await wrap_app_handling_exceptions(self.app, conn)(scope, receive, send)
  File "C:\Users\Sobre\OneDrive\Desktop\Vroomble\.venv\Lib\site-packages\starlette\_exception_handler.py", line 53, in wrapped_app
    raise exc
  File "C:\Users\Sobre\OneDrive\Desktop\Vroomble\.venv\Lib\site-packages\starlette\_exception_handler.py", line 42, in wrapped_app
    await app(scope, receive, sender)
  File "C:\Users\Sobre\OneDrive\Desktop\Vroomble\.venv\Lib\site-packages\starlette\routing.py", line 715, in __call__
    await self.middleware_stack(scope, receive, send)
  File "C:\Users\Sobre\OneDrive\Desktop\Vroomble\.venv\Lib\site-packages\starlette\routing.py", line 735, in app
    await route.handle(scope, receive, send)
  File "C:\Users\Sobre\OneDrive\Desktop\Vroomble\.venv\Lib\site-packages\starlette\routing.py", line 288, in handle
    await self.app(scope, receive, send)
  File "C:\Users\Sobre\OneDrive\Desktop\Vroomble\.venv\Lib\site-packages\starlette\routing.py", line 76, in app
    await wrap_app_handling_exceptions(app, request)(scope, receive, send)
  File "C:\Users\Sobre\OneDrive\Desktop\Vroomble\.venv\Lib\site-packages\starlette\_exception_handler.py", line 53, in wrapped_app
    raise exc
  File "C:\Users\Sobre\OneDrive\Desktop\Vroomble\.venv\Lib\site-packages\starlette\_exception_handler.py", line 42, in wrapped_app
    await app(scope, receive, sender)
  File "C:\Users\Sobre\OneDrive\Desktop\Vroomble\.venv\Lib\site-packages\starlette\routing.py", line 73, in app
    response = await f(request)
               ^^^^^^^^^^^^^^^^
  File "C:\Users\Sobre\OneDrive\Desktop\Vroomble\.venv\Lib\site-packages\fastapi\routing.py", line 301, in app
    raw_response = await run_endpoint_function(
                   ^^^^^^^^^^^^^^^^^^^^^^^^^^^^
  File "C:\Users\Sobre\OneDrive\Desktop\Vroomble\.venv\Lib\site-packages\fastapi\routing.py", line 212, in run_endpoint_function
    return await dependant.call(**values)
           ^^^^^^^^^^^^^^^^^^^^^^^^^^^^^^
  File "C:\Users\Sobre\OneDrive\Desktop\Vroomble\src\APIs\vehicle_registration.py", line 75, in submit_form
    body = await request.json()
           ^^^^^^^^^^^^^^^^^^^^
  File "C:\Users\Sobre\OneDrive\Desktop\Vroomble\.venv\Lib\site-packages\starlette\requests.py", line 249, in json
    self._json = json.loads(body)
                 ^^^^^^^^^^^^^^^^
  File "C:\Program Files\WindowsApps\PythonSoftwareFoundation.Python.3.11_3.11.2544.0_x64__qbz5n2kfra8p0\Lib\json\__init__.py", line 346, in loads
    return _default_decoder.decode(s)
           ^^^^^^^^^^^^^^^^^^^^^^^^^^
  File "C:\Program Files\WindowsApps\PythonSoftwareFoundation.Python.3.11_3.11.2544.0_x64__qbz5n2kfra8p0\Lib\json\decoder.py", line 337, in decode
    obj, end = self.raw_decode(s, idx=_w(s, 0).end())
               ^^^^^^^^^^^^^^^^^^^^^^^^^^^^^^^^^^^^^^
  File "C:\Program Files\WindowsApps\PythonSoftwareFoundation.Python.3.11_3.11.2544.0_x64__qbz5n2kfra8p0\Lib\json\decoder.py", line 355, in raw_decode
    raise JSONDecodeError("Expecting value", s, err.value) from None
json.decoder.JSONDecodeError: Expecting value: line 1 column 1 (char 0)
2025-03-02 11:21:05,933 - ERROR - Unhandled exception: Expecting value: line 1 column 1 (char 0)
Traceback (most recent call last):
  File "C:\Users\Sobre\OneDrive\Desktop\Vroomble\.venv\Lib\site-packages\starlette\middleware\errors.py", line 165, in __call__
    await self.app(scope, receive, _send)
  File "C:\Users\Sobre\OneDrive\Desktop\Vroomble\.venv\Lib\site-packages\starlette\middleware\cors.py", line 93, in __call__
    await self.simple_response(scope, receive, send, request_headers=headers)
  File "C:\Users\Sobre\OneDrive\Desktop\Vroomble\.venv\Lib\site-packages\starlette\middleware\cors.py", line 144, in simple_response
    await self.app(scope, receive, send)
  File "C:\Users\Sobre\OneDrive\Desktop\Vroomble\.venv\Lib\site-packages\starlette\middleware\exceptions.py", line 62, in __call__
    await wrap_app_handling_exceptions(self.app, conn)(scope, receive, send)
  File "C:\Users\Sobre\OneDrive\Desktop\Vroomble\.venv\Lib\site-packages\starlette\_exception_handler.py", line 53, in wrapped_app
    raise exc
  File "C:\Users\Sobre\OneDrive\Desktop\Vroomble\.venv\Lib\site-packages\starlette\_exception_handler.py", line 42, in wrapped_app
    await app(scope, receive, sender)
  File "C:\Users\Sobre\OneDrive\Desktop\Vroomble\.venv\Lib\site-packages\starlette\routing.py", line 715, in __call__
    await self.middleware_stack(scope, receive, send)
  File "C:\Users\Sobre\OneDrive\Desktop\Vroomble\.venv\Lib\site-packages\starlette\routing.py", line 735, in app
    await route.handle(scope, receive, send)
  File "C:\Users\Sobre\OneDrive\Desktop\Vroomble\.venv\Lib\site-packages\starlette\routing.py", line 288, in handle
    await self.app(scope, receive, send)
  File "C:\Users\Sobre\OneDrive\Desktop\Vroomble\.venv\Lib\site-packages\starlette\routing.py", line 76, in app
    await wrap_app_handling_exceptions(app, request)(scope, receive, send)
  File "C:\Users\Sobre\OneDrive\Desktop\Vroomble\.venv\Lib\site-packages\starlette\_exception_handler.py", line 53, in wrapped_app
    raise exc
  File "C:\Users\Sobre\OneDrive\Desktop\Vroomble\.venv\Lib\site-packages\starlette\_exception_handler.py", line 42, in wrapped_app
    await app(scope, receive, sender)
  File "C:\Users\Sobre\OneDrive\Desktop\Vroomble\.venv\Lib\site-packages\starlette\routing.py", line 73, in app
    response = await f(request)
               ^^^^^^^^^^^^^^^^
  File "C:\Users\Sobre\OneDrive\Desktop\Vroomble\.venv\Lib\site-packages\fastapi\routing.py", line 301, in app
    raw_response = await run_endpoint_function(
                   ^^^^^^^^^^^^^^^^^^^^^^^^^^^^
  File "C:\Users\Sobre\OneDrive\Desktop\Vroomble\.venv\Lib\site-packages\fastapi\routing.py", line 212, in run_endpoint_function
    return await dependant.call(**values)
           ^^^^^^^^^^^^^^^^^^^^^^^^^^^^^^
  File "C:\Users\Sobre\OneDrive\Desktop\Vroomble\src\APIs\vehicle_registration.py", line 75, in submit_form
    body = await request.json()
           ^^^^^^^^^^^^^^^^^^^^
  File "C:\Users\Sobre\OneDrive\Desktop\Vroomble\.venv\Lib\site-packages\starlette\requests.py", line 249, in json
    self._json = json.loads(body)
                 ^^^^^^^^^^^^^^^^
  File "C:\Program Files\WindowsApps\PythonSoftwareFoundation.Python.3.11_3.11.2544.0_x64__qbz5n2kfra8p0\Lib\json\__init__.py", line 346, in loads
    return _default_decoder.decode(s)
           ^^^^^^^^^^^^^^^^^^^^^^^^^^
  File "C:\Program Files\WindowsApps\PythonSoftwareFoundation.Python.3.11_3.11.2544.0_x64__qbz5n2kfra8p0\Lib\json\decoder.py", line 337, in decode
    obj, end = self.raw_decode(s, idx=_w(s, 0).end())
               ^^^^^^^^^^^^^^^^^^^^^^^^^^^^^^^^^^^^^^
  File "C:\Program Files\WindowsApps\PythonSoftwareFoundation.Python.3.11_3.11.2544.0_x64__qbz5n2kfra8p0\Lib\json\decoder.py", line 355, in raw_decode
    raise JSONDecodeError("Expecting value", s, err.value) from None
json.decoder.JSONDecodeError: Expecting value: line 1 column 1 (char 0)
2025-03-02 11:21:06,606 - ERROR - Unhandled exception: Expecting value: line 1 column 1 (char 0)
Traceback (most recent call last):
  File "C:\Users\Sobre\OneDrive\Desktop\Vroomble\.venv\Lib\site-packages\starlette\middleware\errors.py", line 165, in __call__
    await self.app(scope, receive, _send)
  File "C:\Users\Sobre\OneDrive\Desktop\Vroomble\.venv\Lib\site-packages\starlette\middleware\cors.py", line 93, in __call__
    await self.simple_response(scope, receive, send, request_headers=headers)
  File "C:\Users\Sobre\OneDrive\Desktop\Vroomble\.venv\Lib\site-packages\starlette\middleware\cors.py", line 144, in simple_response
    await self.app(scope, receive, send)
  File "C:\Users\Sobre\OneDrive\Desktop\Vroomble\.venv\Lib\site-packages\starlette\middleware\exceptions.py", line 62, in __call__
    await wrap_app_handling_exceptions(self.app, conn)(scope, receive, send)
  File "C:\Users\Sobre\OneDrive\Desktop\Vroomble\.venv\Lib\site-packages\starlette\_exception_handler.py", line 53, in wrapped_app
    raise exc
  File "C:\Users\Sobre\OneDrive\Desktop\Vroomble\.venv\Lib\site-packages\starlette\_exception_handler.py", line 42, in wrapped_app
    await app(scope, receive, sender)
  File "C:\Users\Sobre\OneDrive\Desktop\Vroomble\.venv\Lib\site-packages\starlette\routing.py", line 715, in __call__
    await self.middleware_stack(scope, receive, send)
  File "C:\Users\Sobre\OneDrive\Desktop\Vroomble\.venv\Lib\site-packages\starlette\routing.py", line 735, in app
    await route.handle(scope, receive, send)
  File "C:\Users\Sobre\OneDrive\Desktop\Vroomble\.venv\Lib\site-packages\starlette\routing.py", line 288, in handle
    await self.app(scope, receive, send)
  File "C:\Users\Sobre\OneDrive\Desktop\Vroomble\.venv\Lib\site-packages\starlette\routing.py", line 76, in app
    await wrap_app_handling_exceptions(app, request)(scope, receive, send)
  File "C:\Users\Sobre\OneDrive\Desktop\Vroomble\.venv\Lib\site-packages\starlette\_exception_handler.py", line 53, in wrapped_app
    raise exc
  File "C:\Users\Sobre\OneDrive\Desktop\Vroomble\.venv\Lib\site-packages\starlette\_exception_handler.py", line 42, in wrapped_app
    await app(scope, receive, sender)
  File "C:\Users\Sobre\OneDrive\Desktop\Vroomble\.venv\Lib\site-packages\starlette\routing.py", line 73, in app
    response = await f(request)
               ^^^^^^^^^^^^^^^^
  File "C:\Users\Sobre\OneDrive\Desktop\Vroomble\.venv\Lib\site-packages\fastapi\routing.py", line 301, in app
    raw_response = await run_endpoint_function(
                   ^^^^^^^^^^^^^^^^^^^^^^^^^^^^
  File "C:\Users\Sobre\OneDrive\Desktop\Vroomble\.venv\Lib\site-packages\fastapi\routing.py", line 212, in run_endpoint_function
    return await dependant.call(**values)
           ^^^^^^^^^^^^^^^^^^^^^^^^^^^^^^
  File "C:\Users\Sobre\OneDrive\Desktop\Vroomble\src\APIs\vehicle_registration.py", line 75, in submit_form
    body = await request.json()
           ^^^^^^^^^^^^^^^^^^^^
  File "C:\Users\Sobre\OneDrive\Desktop\Vroomble\.venv\Lib\site-packages\starlette\requests.py", line 249, in json
    self._json = json.loads(body)
                 ^^^^^^^^^^^^^^^^
  File "C:\Program Files\WindowsApps\PythonSoftwareFoundation.Python.3.11_3.11.2544.0_x64__qbz5n2kfra8p0\Lib\json\__init__.py", line 346, in loads
    return _default_decoder.decode(s)
           ^^^^^^^^^^^^^^^^^^^^^^^^^^
  File "C:\Program Files\WindowsApps\PythonSoftwareFoundation.Python.3.11_3.11.2544.0_x64__qbz5n2kfra8p0\Lib\json\decoder.py", line 337, in decode
    obj, end = self.raw_decode(s, idx=_w(s, 0).end())
               ^^^^^^^^^^^^^^^^^^^^^^^^^^^^^^^^^^^^^^
  File "C:\Program Files\WindowsApps\PythonSoftwareFoundation.Python.3.11_3.11.2544.0_x64__qbz5n2kfra8p0\Lib\json\decoder.py", line 355, in raw_decode
    raise JSONDecodeError("Expecting value", s, err.value) from None
json.decoder.JSONDecodeError: Expecting value: line 1 column 1 (char 0)
2025-03-02 11:24:34,265 - INFO - Database and table created successfully (if not already existing).
2025-03-02 11:25:16,160 - INFO - Executing SQL: 
            INSERT INTO cars (Make, Model, Body_Type, Transmission, Drivetrain, Fuel_Type, Year, Retail_SRP, Variant)
            VALUES (?, ?, ?, ?, ?, ?, ?, ?, ?)
         with values ('TOYOTA', 'FORTUNER', 'SUV', 'CVT', 'RWD', 'Diesel', 2014, '1300000.00', 'G')
2025-03-02 11:25:16,163 - INFO - Car added successfully: make='TOYOTA' model='FORTUNER' body_type='SUV' variant='G' transmission='CVT' drivetrain='RWD' fuel_type='Diesel' year=2014 retail_srp=1300000.0
2025-03-02 11:27:04,624 - INFO - Database and table created successfully (if not already existing).
2025-03-02 11:27:09,496 - INFO - Database and table created successfully (if not already existing).
2025-03-02 11:27:33,202 - INFO - Entering create_car_form function...
2025-03-02 11:27:33,204 - INFO - Executing SQL: 
            INSERT INTO cars (Make, Model, Body_Type, Transmission, Drivetrain, Fuel_Type, Year, Retail_SRP, Variant)
            VALUES (?, ?, ?, ?, ?, ?, ?, ?, ?)
         with values ('TOYOTA', 'FORTUNER', 'SUV', 'CVT', 'RWD', 'Diesel', 2014, '1300000.00', 'G')
2025-03-02 11:27:33,205 - INFO - Car added successfully: make='TOYOTA' model='FORTUNER' body_type='SUV' variant='G' transmission='CVT' drivetrain='RWD' fuel_type='Diesel' year=2014 retail_srp=1300000.0
2025-03-02 11:28:11,140 - INFO - Entering create_car_form function...
2025-03-02 11:28:11,142 - INFO - Executing SQL: 
            INSERT INTO cars (Make, Model, Body_Type, Transmission, Drivetrain, Fuel_Type, Year, Retail_SRP, Variant)
            VALUES (?, ?, ?, ?, ?, ?, ?, ?, ?)
         with values ('TOYOTA', 'FORTUNER', 'SUV', 'CVT', 'RWD', 'Diesel', 2014, '1300000.00', 'G')
2025-03-02 11:28:11,145 - INFO - Car added successfully: make='TOYOTA' model='FORTUNER' body_type='SUV' variant='G' transmission='CVT' drivetrain='RWD' fuel_type='Diesel' year=2014 retail_srp=1300000.0
2025-03-02 11:35:39,244 - INFO - Database and table created successfully (if not already existing).
2025-03-02 11:36:08,738 - INFO - Entering create_car_form function...
2025-03-02 11:36:08,740 - INFO - Executing SQL: 
            INSERT INTO cars (Make, Model, Body_Type, Transmission, Drivetrain, Fuel_Type, Year, Retail_SRP, Variant)
            VALUES (?, ?, ?, ?, ?, ?, ?, ?, ?)
         with values ('TOYOTA', 'FORTUNER', 'SUV', 'Automatic', 'RWD', 'Diesel', 2014, '1300000.00', 'G')
2025-03-02 11:36:08,743 - INFO - Car added successfully: make='TOYOTA' model='FORTUNER' body_type='SUV' variant='G' transmission='Automatic' drivetrain='RWD' fuel_type='Diesel' year=2014 retail_srp=1300000.0
2025-03-02 11:39:29,132 - INFO - Database and table created successfully (if not already existing).
2025-03-02 11:39:50,371 - INFO - Entering create_car_form function...
2025-03-02 11:39:50,371 - INFO - Executing SQL: 
            INSERT INTO cars (Make, Model, Body_Type, Transmission, Drivetrain, Fuel_Type, Year, Retail_SRP, Variant)
            VALUES (?, ?, ?, ?, ?, ?, ?, ?, ?)
         with values ('TOYOTA', 'FORTUNER', 'SUV', 'CVT', 'RWD', 'Diesel', 2014, '1300000.00', 'G')
2025-03-02 11:39:50,372 - ERROR - Database error: non-deterministic use of strftime() in a CHECK constraint
2025-03-02 11:41:33,236 - INFO - Database and table created successfully (if not already existing).
2025-03-02 11:41:49,913 - INFO - Entering create_car_form function...
2025-03-02 11:41:49,913 - INFO - Executing SQL: 
            INSERT INTO cars (Make, Model, Body_Type, Transmission, Drivetrain, Fuel_Type, Year, Retail_SRP, Variant)
            VALUES (?, ?, ?, ?, ?, ?, ?, ?, ?)
         with values ('TOYOTA', 'FORTUNER', 'SUV', 'CVT', 'RWD', 'Diesel', 2014, '1300000.00', 'G')
2025-03-02 11:41:49,918 - INFO - Car added successfully: make='TOYOTA' model='FORTUNER' body_type='SUV' variant='G' transmission='CVT' drivetrain='RWD' fuel_type='Diesel' year=2014 retail_srp=1300000.0
2025-03-02 11:45:05,673 - INFO - Entering create_car_form function...
2025-03-02 11:45:05,674 - INFO - Executing SQL: 
            INSERT INTO cars (Make, Model, Body_Type, Transmission, Drivetrain, Fuel_Type, Year, Retail_SRP, Variant)
            VALUES (?, ?, ?, ?, ?, ?, ?, ?, ?)
         with values ('MITSUBISHI', 'EVO X', 'Sedan', '', 'AWD', 'Unleaded', 2008, '2200000.00', 'MR')
2025-03-02 11:45:05,676 - INFO - Car added successfully: make='MITSUBISHI' model='EVO X' body_type='Sedan' variant='MR' transmission='' drivetrain='AWD' fuel_type='Unleaded' year=2008 retail_srp=2200000.0
2025-03-02 12:27:12,110 - INFO - Entering create_car_form function...
2025-03-02 12:27:12,110 - INFO - Executing SQL: 
            INSERT INTO cars (Make, Model, Body_Type, Transmission, Drivetrain, Fuel_Type, Year, Retail_SRP, Variant)
            VALUES (?, ?, ?, ?, ?, ?, ?, ?, ?)
         with values ('HYUNDAI', 'REINA', 'Sedan', 'Automatic', 'FWD', 'Unleaded', 2021, '700000.00', '')
2025-03-02 12:27:12,114 - INFO - Car added successfully: make='HYUNDAI' model='REINA' body_type='Sedan' variant='' transmission='Automatic' drivetrain='FWD' fuel_type='Unleaded' year=2021 retail_srp=700000.0
2025-03-02 23:54:33,679 - INFO - Database and table created successfully (if not already existing).
2025-03-03 00:00:17,792 - ERROR - Validation error: [{'type': 'value_error', 'loc': ('body', 'year'), 'msg': 'Value error, Invalid year', 'input': 0, 'ctx': {'error': ValueError('Invalid year')}}]
2025-03-03 00:00:17,792 - ERROR - Unhandled exception: Object of type ValueError is not JSON serializable
Traceback (most recent call last):
  File "C:\Users\Sobre\OneDrive\Desktop\Vroomble\.venv\Lib\site-packages\starlette\_exception_handler.py", line 42, in wrapped_app
    await app(scope, receive, sender)
  File "C:\Users\Sobre\OneDrive\Desktop\Vroomble\.venv\Lib\site-packages\starlette\routing.py", line 73, in app
    response = await f(request)
               ^^^^^^^^^^^^^^^^
  File "C:\Users\Sobre\OneDrive\Desktop\Vroomble\.venv\Lib\site-packages\fastapi\routing.py", line 346, in app
    raise validation_error
fastapi.exceptions.RequestValidationError: [{'type': 'value_error', 'loc': ('body', 'year'), 'msg': 'Value error, Invalid year', 'input': 0, 'ctx': {'error': ValueError('Invalid year')}}]

During handling of the above exception, another exception occurred:

Traceback (most recent call last):
  File "C:\Users\Sobre\OneDrive\Desktop\Vroomble\.venv\Lib\site-packages\starlette\middleware\errors.py", line 165, in __call__
    await self.app(scope, receive, _send)
  File "C:\Users\Sobre\OneDrive\Desktop\Vroomble\.venv\Lib\site-packages\starlette\middleware\cors.py", line 93, in __call__
    await self.simple_response(scope, receive, send, request_headers=headers)
  File "C:\Users\Sobre\OneDrive\Desktop\Vroomble\.venv\Lib\site-packages\starlette\middleware\cors.py", line 144, in simple_response
    await self.app(scope, receive, send)
  File "C:\Users\Sobre\OneDrive\Desktop\Vroomble\.venv\Lib\site-packages\starlette\middleware\exceptions.py", line 62, in __call__
    await wrap_app_handling_exceptions(self.app, conn)(scope, receive, send)
  File "C:\Users\Sobre\OneDrive\Desktop\Vroomble\.venv\Lib\site-packages\starlette\_exception_handler.py", line 53, in wrapped_app
    raise exc
  File "C:\Users\Sobre\OneDrive\Desktop\Vroomble\.venv\Lib\site-packages\starlette\_exception_handler.py", line 42, in wrapped_app
    await app(scope, receive, sender)
  File "C:\Users\Sobre\OneDrive\Desktop\Vroomble\.venv\Lib\site-packages\starlette\routing.py", line 715, in __call__
    await self.middleware_stack(scope, receive, send)
  File "C:\Users\Sobre\OneDrive\Desktop\Vroomble\.venv\Lib\site-packages\starlette\routing.py", line 735, in app
    await route.handle(scope, receive, send)
  File "C:\Users\Sobre\OneDrive\Desktop\Vroomble\.venv\Lib\site-packages\starlette\routing.py", line 288, in handle
    await self.app(scope, receive, send)
  File "C:\Users\Sobre\OneDrive\Desktop\Vroomble\.venv\Lib\site-packages\starlette\routing.py", line 76, in app
    await wrap_app_handling_exceptions(app, request)(scope, receive, send)
  File "C:\Users\Sobre\OneDrive\Desktop\Vroomble\.venv\Lib\site-packages\starlette\_exception_handler.py", line 59, in wrapped_app
    response = await handler(conn, exc)
               ^^^^^^^^^^^^^^^^^^^^^^^^
  File "C:\Users\Sobre\OneDrive\Desktop\Vroomble\src\APIs\vehicle_registration.py", line 191, in validation_exception_handler
    return JSONResponse(
           ^^^^^^^^^^^^^
  File "C:\Users\Sobre\OneDrive\Desktop\Vroomble\.venv\Lib\site-packages\starlette\responses.py", line 181, in __init__
    super().__init__(content, status_code, headers, media_type, background)
  File "C:\Users\Sobre\OneDrive\Desktop\Vroomble\.venv\Lib\site-packages\starlette\responses.py", line 44, in __init__
    self.body = self.render(content)
                ^^^^^^^^^^^^^^^^^^^^
  File "C:\Users\Sobre\OneDrive\Desktop\Vroomble\.venv\Lib\site-packages\starlette\responses.py", line 184, in render
    return json.dumps(
           ^^^^^^^^^^^
  File "C:\Program Files\WindowsApps\PythonSoftwareFoundation.Python.3.11_3.11.2544.0_x64__qbz5n2kfra8p0\Lib\json\__init__.py", line 238, in dumps
    **kw).encode(obj)
          ^^^^^^^^^^^
  File "C:\Program Files\WindowsApps\PythonSoftwareFoundation.Python.3.11_3.11.2544.0_x64__qbz5n2kfra8p0\Lib\json\encoder.py", line 200, in encode
    chunks = self.iterencode(o, _one_shot=True)
             ^^^^^^^^^^^^^^^^^^^^^^^^^^^^^^^^^^
  File "C:\Program Files\WindowsApps\PythonSoftwareFoundation.Python.3.11_3.11.2544.0_x64__qbz5n2kfra8p0\Lib\json\encoder.py", line 258, in iterencode
    return _iterencode(o, 0)
           ^^^^^^^^^^^^^^^^^
  File "C:\Program Files\WindowsApps\PythonSoftwareFoundation.Python.3.11_3.11.2544.0_x64__qbz5n2kfra8p0\Lib\json\encoder.py", line 180, in default
    raise TypeError(f'Object of type {o.__class__.__name__} '
TypeError: Object of type ValueError is not JSON serializable
2025-03-03 00:00:29,647 - INFO - Entering create_car_form function...
2025-03-03 00:00:29,650 - INFO - Executing SQL: 
            INSERT INTO cars (Make, Model, Body_Type, Transmission, Drivetrain, Fuel_Type, Year, Retail_SRP, Variant)
            VALUES (?, ?, ?, ?, ?, ?, ?, ?, ?)
         with values ('ISUZU', 'MUX', 'SUV', 'Automatic', 'RWD', 'Diesel', 2025, '1715000.00', 'LS')
2025-03-03 00:00:35,227 - ERROR - Database error: database is locked
2025-03-03 00:00:45,009 - INFO - Entering create_car_form function...
2025-03-03 00:00:45,009 - INFO - Executing SQL: 
            INSERT INTO cars (Make, Model, Body_Type, Transmission, Drivetrain, Fuel_Type, Year, Retail_SRP, Variant)
            VALUES (?, ?, ?, ?, ?, ?, ?, ?, ?)
         with values ('ISUZU', 'MUX', 'SUV', 'Automatic', 'RWD', 'Diesel', 2025, '1715000.00', 'LS')
2025-03-03 00:00:50,589 - ERROR - Database error: database is locked
2025-03-03 00:02:50,311 - INFO - Entering create_car_form function...
2025-03-03 00:02:50,311 - INFO - Executing SQL: 
            INSERT INTO cars (Make, Model, Body_Type, Transmission, Drivetrain, Fuel_Type, Year, Retail_SRP, Variant)
            VALUES (?, ?, ?, ?, ?, ?, ?, ?, ?)
         with values ('ISUZU', 'MUX', 'SUV', 'Automatic', 'RWD', 'Diesel', 2025, '1715000.00', 'LS')
2025-03-03 00:02:55,914 - ERROR - Database error: database is locked
2025-03-03 00:03:57,323 - INFO - Database and table created successfully (if not already existing).
2025-03-03 00:36:52,719 - INFO - Database and table created successfully (if not already existing).
2025-03-03 00:40:47,451 - INFO - Database and table created successfully (if not already existing).
2025-03-03 00:54:44,305 - INFO - Database and table created successfully (if not already existing).
2025-03-03 00:57:38,571 - INFO - Entering create_car_form function...
2025-03-03 00:57:38,571 - INFO - Executing SQL: 
            INSERT INTO cars (Make, Model, Body_Type, Transmission, Drivetrain, Fuel_Type, Year, Retail_SRP, Variant)
            VALUES (?, ?, ?, ?, ?, ?, ?, ?, ?)
         with values ('ISUZU', 'MUX', 'SUV', 'Automatic', 'RWD', 'Diesel', 2025, '1715000.00', 'LS')
2025-03-03 00:57:44,160 - ERROR - Database error: database is locked
2025-03-03 00:58:12,832 - INFO - Entering create_car_form function...
2025-03-03 00:58:12,832 - INFO - Executing SQL: 
            INSERT INTO cars (Make, Model, Body_Type, Transmission, Drivetrain, Fuel_Type, Year, Retail_SRP, Variant)
            VALUES (?, ?, ?, ?, ?, ?, ?, ?, ?)
         with values ('ISUZU', 'MUX', 'SUV', 'Automatic', 'RWD', 'Diesel', 2025, '1715000.00', 'LS')
2025-03-03 00:58:12,836 - INFO - Car added successfully: make='ISUZU' model='MUX' body_type='SUV' variant='LS' transmission='Automatic' drivetrain='RWD' fuel_type='Diesel' year=2025 retail_srp=1715000.0
2025-03-03 01:01:26,916 - INFO - Entering create_car_form function...
2025-03-03 01:01:26,916 - INFO - Executing SQL: 
            INSERT INTO cars (Make, Model, Body_Type, Transmission, Drivetrain, Fuel_Type, Year, Retail_SRP, Variant)
            VALUES (?, ?, ?, ?, ?, ?, ?, ?, ?)
         with values ('RAM', '1500', 'Pickup Truck', 'Automatic', '4WD', 'Unleaded', 2025, '5250000.00', 'Rebel')
2025-03-03 01:01:26,920 - INFO - Car added successfully: make='RAM' model='1500' body_type='Pickup Truck' variant='Rebel' transmission='Automatic' drivetrain='4WD' fuel_type='Unleaded' year=2025 retail_srp=5250000.0
2025-03-03 01:03:19,017 - ERROR - Validation error: [{'type': 'float_type', 'loc': ('body', 'retail_srp'), 'msg': 'Input should be a valid number', 'input': None}]
2025-03-03 01:03:27,274 - INFO - Entering create_car_form function...
2025-03-03 01:03:27,276 - INFO - Executing SQL: 
            INSERT INTO cars (Make, Model, Body_Type, Transmission, Drivetrain, Fuel_Type, Year, Retail_SRP, Variant)
            VALUES (?, ?, ?, ?, ?, ?, ?, ?, ?)
         with values ('Chevrolet', 'Suburvan', 'SUV', 'Automatic', '4WD', 'Unleaded', 2024, '8634888.00', 'Z71')
2025-03-03 01:03:27,277 - INFO - Car added successfully: make='Chevrolet' model='Suburvan' body_type='SUV' variant='Z71' transmission='Automatic' drivetrain='4WD' fuel_type='Unleaded' year=2024 retail_srp=8634888.0
2025-03-04 22:57:12,687 - DEBUG - registered 'bcrypt' handler: <class 'passlib.handlers.bcrypt.bcrypt'>
2025-03-04 22:57:12,698 - INFO - Local database table 'users' created (if not already existing).
2025-03-04 22:58:05,802 - DEBUG - bcrypt 'builtin' backend not enabled via $PASSLIB_BUILTIN_BCRYPT
2025-03-04 22:58:05,803 - ERROR - Error during registration: bcrypt: no backends available -- recommend you install one (e.g. 'pip install bcrypt')
Traceback (most recent call last):
  File "C:\Users\Sobre\OneDrive\Desktop\Vroomble\src\APIs\register.py", line 78, in register_user
    hashed_password = hash_password(registration_data.password)
                      ^^^^^^^^^^^^^^^^^^^^^^^^^^^^^^^^^^^^^^^^^
  File "C:\Users\Sobre\OneDrive\Desktop\Vroomble\src\APIs\register.py", line 45, in hash_password
    return pwd_context.hash(password)
           ^^^^^^^^^^^^^^^^^^^^^^^^^^
  File "C:\Users\Sobre\OneDrive\Desktop\Vroomble\.venv\Lib\site-packages\passlib\context.py", line 2258, in hash
    return record.hash(secret, **kwds)
           ^^^^^^^^^^^^^^^^^^^^^^^^^^^
  File "C:\Users\Sobre\OneDrive\Desktop\Vroomble\.venv\Lib\site-packages\passlib\utils\handlers.py", line 779, in hash
    self.checksum = self._calc_checksum(secret)
                    ^^^^^^^^^^^^^^^^^^^^^^^^^^^
  File "C:\Users\Sobre\OneDrive\Desktop\Vroomble\.venv\Lib\site-packages\passlib\handlers\bcrypt.py", line 591, in _calc_checksum
    self._stub_requires_backend()
  File "C:\Users\Sobre\OneDrive\Desktop\Vroomble\.venv\Lib\site-packages\passlib\utils\handlers.py", line 2254, in _stub_requires_backend
    cls.set_backend()
  File "C:\Users\Sobre\OneDrive\Desktop\Vroomble\.venv\Lib\site-packages\passlib\utils\handlers.py", line 2156, in set_backend
    return owner.set_backend(name, dryrun=dryrun)
           ^^^^^^^^^^^^^^^^^^^^^^^^^^^^^^^^^^^^^^
  File "C:\Users\Sobre\OneDrive\Desktop\Vroomble\.venv\Lib\site-packages\passlib\utils\handlers.py", line 2176, in set_backend
    raise default_error
passlib.exc.MissingBackendError: bcrypt: no backends available -- recommend you install one (e.g. 'pip install bcrypt')
2025-03-04 22:59:07,532 - DEBUG - registered 'bcrypt' handler: <class 'passlib.handlers.bcrypt.bcrypt'>
2025-03-04 22:59:07,536 - INFO - Local database table 'users' created (if not already existing).
2025-03-04 22:59:11,721 - DEBUG - bcrypt 'builtin' backend not enabled via $PASSLIB_BUILTIN_BCRYPT
2025-03-04 22:59:11,721 - ERROR - Error during registration: bcrypt: no backends available -- recommend you install one (e.g. 'pip install bcrypt')
Traceback (most recent call last):
  File "C:\Users\Sobre\OneDrive\Desktop\Vroomble\src\APIs\register.py", line 78, in register_user
    hashed_password = hash_password(registration_data.password)
                      ^^^^^^^^^^^^^^^^^^^^^^^^^^^^^^^^^^^^^^^^^
  File "C:\Users\Sobre\OneDrive\Desktop\Vroomble\src\APIs\register.py", line 45, in hash_password
    return pwd_context.hash(password)
           ^^^^^^^^^^^^^^^^^^^^^^^^^^
  File "C:\Users\Sobre\OneDrive\Desktop\Vroomble\.venv\Lib\site-packages\passlib\context.py", line 2258, in hash
    return record.hash(secret, **kwds)
           ^^^^^^^^^^^^^^^^^^^^^^^^^^^
  File "C:\Users\Sobre\OneDrive\Desktop\Vroomble\.venv\Lib\site-packages\passlib\utils\handlers.py", line 779, in hash
    self.checksum = self._calc_checksum(secret)
                    ^^^^^^^^^^^^^^^^^^^^^^^^^^^
  File "C:\Users\Sobre\OneDrive\Desktop\Vroomble\.venv\Lib\site-packages\passlib\handlers\bcrypt.py", line 591, in _calc_checksum
    self._stub_requires_backend()
  File "C:\Users\Sobre\OneDrive\Desktop\Vroomble\.venv\Lib\site-packages\passlib\utils\handlers.py", line 2254, in _stub_requires_backend
    cls.set_backend()
  File "C:\Users\Sobre\OneDrive\Desktop\Vroomble\.venv\Lib\site-packages\passlib\utils\handlers.py", line 2156, in set_backend
    return owner.set_backend(name, dryrun=dryrun)
           ^^^^^^^^^^^^^^^^^^^^^^^^^^^^^^^^^^^^^^
  File "C:\Users\Sobre\OneDrive\Desktop\Vroomble\.venv\Lib\site-packages\passlib\utils\handlers.py", line 2176, in set_backend
    raise default_error
passlib.exc.MissingBackendError: bcrypt: no backends available -- recommend you install one (e.g. 'pip install bcrypt')
2025-03-04 22:59:31,446 - DEBUG - registered 'bcrypt' handler: <class 'passlib.handlers.bcrypt.bcrypt'>
2025-03-04 22:59:31,447 - INFO - Local database table 'users' created (if not already existing).
2025-03-04 22:59:35,171 - WARNING - (trapped) error reading bcrypt version
Traceback (most recent call last):
  File "C:\Users\Sobre\OneDrive\Desktop\Vroomble\.venv\Lib\site-packages\passlib\handlers\bcrypt.py", line 620, in _load_backend_mixin
    version = _bcrypt.__about__.__version__
              ^^^^^^^^^^^^^^^^^
AttributeError: module 'bcrypt' has no attribute '__about__'
2025-03-04 22:59:35,172 - DEBUG - detected 'bcrypt' backend, version '<unknown>'
2025-03-04 22:59:35,172 - DEBUG - 'bcrypt' backend lacks $2$ support, enabling workaround
2025-03-04 23:05:47,629 - ERROR - Database error during user registration: UNIQUE constraint failed: users.email
2025-03-04 23:07:24,914 - ERROR - Database error during user registration: database is locked
2025-03-04 23:07:25,326 - ERROR - Database error during user registration: UNIQUE constraint failed: users.email
2025-03-04 23:12:07,707 - DEBUG - registered 'bcrypt' handler: <class 'passlib.handlers.bcrypt.bcrypt'>
2025-03-04 23:12:07,707 - ERROR - Error connecting to cloud database: connect() got an unexpected keyword argument 'token'
2025-03-04 23:13:29,072 - DEBUG - registered 'bcrypt' handler: <class 'passlib.handlers.bcrypt.bcrypt'>
2025-03-04 23:13:29,073 - ERROR - Error connecting to cloud database: connect() got an unexpected keyword argument 'token'
2025-03-04 23:13:47,530 - DEBUG - registered 'bcrypt' handler: <class 'passlib.handlers.bcrypt.bcrypt'>
2025-03-04 23:13:47,530 - ERROR - Error connecting to cloud database: connect() got an unexpected keyword argument 'token'
2025-03-04 23:17:47,180 - DEBUG - registered 'bcrypt' handler: <class 'passlib.handlers.bcrypt.bcrypt'>
2025-03-04 23:17:47,537 - DEBUG - cannot commit - no transaction is active
2025-03-04 23:17:47,538 - INFO - Cloud database table 'users' created (if not already existing).
2025-03-04 23:21:06,682 - WARNING - (trapped) error reading bcrypt version
Traceback (most recent call last):
  File "C:\Users\Sobre\OneDrive\Desktop\Vroomble\.venv\Lib\site-packages\passlib\handlers\bcrypt.py", line 620, in _load_backend_mixin
    version = _bcrypt.__about__.__version__
              ^^^^^^^^^^^^^^^^^
AttributeError: module 'bcrypt' has no attribute '__about__'
2025-03-04 23:21:06,684 - DEBUG - detected 'bcrypt' backend, version '<unknown>'
2025-03-04 23:21:06,684 - DEBUG - 'bcrypt' backend lacks $2$ support, enabling workaround
2025-03-04 23:21:07,266 - DEBUG - cannot commit - no transaction is active
2025-03-04 23:25:54,197 - ERROR - Error during registration: UNIQUE constraint failed: users.email
Traceback (most recent call last):
  File "C:\Users\Sobre\OneDrive\Desktop\Vroomble\src\APIs\register.py", line 99, in register_user
    cursor.execute(
  File "C:\Users\Sobre\OneDrive\Desktop\Vroomble\.venv\Lib\site-packages\sqlitecloud\dbapi2.py", line 583, in execute
    result = self._driver.execute_statement(
             ^^^^^^^^^^^^^^^^^^^^^^^^^^^^^^^
  File "C:\Users\Sobre\OneDrive\Desktop\Vroomble\.venv\Lib\site-packages\sqlitecloud\driver.py", line 109, in execute_statement
    result = self._internal_run_command(connection, command)
             ^^^^^^^^^^^^^^^^^^^^^^^^^^^^^^^^^^^^^^^^^^^^^^^
  File "C:\Users\Sobre\OneDrive\Desktop\Vroomble\.venv\Lib\site-packages\sqlitecloud\driver.py", line 482, in _internal_run_command
    return self._internal_socket_read(connection, main_socket)
           ^^^^^^^^^^^^^^^^^^^^^^^^^^^^^^^^^^^^^^^^^^^^^^^^^^^
  File "C:\Users\Sobre\OneDrive\Desktop\Vroomble\.venv\Lib\site-packages\sqlitecloud\driver.py", line 590, in _internal_socket_read
    return self._internal_parse_buffer(connection, buffer, len(buffer))
           ^^^^^^^^^^^^^^^^^^^^^^^^^^^^^^^^^^^^^^^^^^^^^^^^^^^^^^^^^^^^
  File "C:\Users\Sobre\OneDrive\Desktop\Vroomble\.venv\Lib\site-packages\sqlitecloud\driver.py", line 731, in _internal_parse_buffer
    raise get_sqlitecloud_error_with_extended_code(
sqlitecloud.exceptions.SQLiteCloudIntegrityError: UNIQUE constraint failed: users.email
2025-03-04 23:26:46,857 - DEBUG - cannot commit - no transaction is active
2025-03-09 01:37:41,129 - ERROR - Error initializing SQLite Cloud database table: Unable to find command USE DATABASE Vroomble Database;SET CLIENT KEY COMPRESSION TO 1;.
2025-03-09 01:44:03,285 - DEBUG - registered 'bcrypt' handler: <class 'passlib.handlers.bcrypt.bcrypt'>
2025-03-09 01:44:03,615 - ERROR - Error connecting to cloud database: Unable to find command USE DATABASE Vroomble Database;SET CLIENT KEY COMPRESSION TO 1;.
2025-03-09 01:44:27,596 - DEBUG - registered 'bcrypt' handler: <class 'passlib.handlers.bcrypt.bcrypt'>
2025-03-09 01:51:17,936 - INFO - Entering create_car_form function...
2025-03-09 01:51:18,136 - ERROR - SQLite Cloud database error during car creation: Unable to find command USE DATABASE Vroomble Database;SET CLIENT KEY COMPRESSION TO 1;.
2025-03-09 02:28:11,604 - INFO - Entering create_car_form function...
2025-03-09 02:28:11,943 - ERROR - SQLite Cloud database error during car creation: Unable to find command USE DATABASE Vroomble Database;SET CLIENT KEY COMPRESSION TO 1;.
2025-03-09 02:30:01,479 - INFO - Entering create_car_form function...
2025-03-09 02:30:01,699 - ERROR - SQLite Cloud database error during car creation: Unable to find command USE DATABASE Vroomble Database;SET CLIENT KEY COMPRESSION TO 1;.
2025-03-09 02:35:16,771 - INFO - Entering create_car_form function...
2025-03-09 02:35:16,955 - ERROR - SQLite Cloud database error during car creation: Unable to find command USE DATABASE Vroomble Database;SET CLIENT KEY COMPRESSION TO 1;.
2025-03-09 02:39:28,230 - INFO - Entering create_car_form function...
2025-03-09 02:39:28,231 - ERROR - Unhandled exception: name 'DATABASE_URL' is not defined
Traceback (most recent call last):
  File "C:\Users\Sobre\OneDrive\Desktop\Vroomble\.venv\Lib\site-packages\starlette\middleware\errors.py", line 165, in __call__
    await self.app(scope, receive, _send)
  File "C:\Users\Sobre\OneDrive\Desktop\Vroomble\.venv\Lib\site-packages\starlette\middleware\cors.py", line 93, in __call__
    await self.simple_response(scope, receive, send, request_headers=headers)
  File "C:\Users\Sobre\OneDrive\Desktop\Vroomble\.venv\Lib\site-packages\starlette\middleware\cors.py", line 144, in simple_response
    await self.app(scope, receive, send)
  File "C:\Users\Sobre\OneDrive\Desktop\Vroomble\.venv\Lib\site-packages\starlette\middleware\exceptions.py", line 62, in __call__
    await wrap_app_handling_exceptions(self.app, conn)(scope, receive, send)
  File "C:\Users\Sobre\OneDrive\Desktop\Vroomble\.venv\Lib\site-packages\starlette\_exception_handler.py", line 53, in wrapped_app
    raise exc
  File "C:\Users\Sobre\OneDrive\Desktop\Vroomble\.venv\Lib\site-packages\starlette\_exception_handler.py", line 42, in wrapped_app
    await app(scope, receive, sender)
  File "C:\Users\Sobre\OneDrive\Desktop\Vroomble\.venv\Lib\site-packages\starlette\routing.py", line 715, in __call__
    await self.middleware_stack(scope, receive, send)
  File "C:\Users\Sobre\OneDrive\Desktop\Vroomble\.venv\Lib\site-packages\starlette\routing.py", line 735, in app
    await route.handle(scope, receive, send)
  File "C:\Users\Sobre\OneDrive\Desktop\Vroomble\.venv\Lib\site-packages\starlette\routing.py", line 288, in handle
    await self.app(scope, receive, send)
  File "C:\Users\Sobre\OneDrive\Desktop\Vroomble\.venv\Lib\site-packages\starlette\routing.py", line 76, in app
    await wrap_app_handling_exceptions(app, request)(scope, receive, send)
  File "C:\Users\Sobre\OneDrive\Desktop\Vroomble\.venv\Lib\site-packages\starlette\_exception_handler.py", line 53, in wrapped_app
    raise exc
  File "C:\Users\Sobre\OneDrive\Desktop\Vroomble\.venv\Lib\site-packages\starlette\_exception_handler.py", line 42, in wrapped_app
    await app(scope, receive, sender)
  File "C:\Users\Sobre\OneDrive\Desktop\Vroomble\.venv\Lib\site-packages\starlette\routing.py", line 73, in app
    response = await f(request)
               ^^^^^^^^^^^^^^^^
  File "C:\Users\Sobre\OneDrive\Desktop\Vroomble\.venv\Lib\site-packages\fastapi\routing.py", line 301, in app
    raw_response = await run_endpoint_function(
                   ^^^^^^^^^^^^^^^^^^^^^^^^^^^^
  File "C:\Users\Sobre\OneDrive\Desktop\Vroomble\.venv\Lib\site-packages\fastapi\routing.py", line 212, in run_endpoint_function
    return await dependant.call(**values)
           ^^^^^^^^^^^^^^^^^^^^^^^^^^^^^^
  File "C:\Users\Sobre\OneDrive\Desktop\Vroomble\src\APIs\vehicle_registration.py", line 148, in create_car_form
    with sqlitecloud.connect(DATABASE_URL) as conn:
                             ^^^^^^^^^^^^
NameError: name 'DATABASE_URL' is not defined
2025-03-09 11:43:32,769 - INFO - Entering create_car_form function...
2025-03-09 11:43:32,769 - ERROR - Unhandled exception: name 'DATABASE_URL' is not defined
Traceback (most recent call last):
  File "C:\Users\Sobre\OneDrive\Desktop\Vroomble\.venv\Lib\site-packages\starlette\middleware\errors.py", line 165, in __call__
    await self.app(scope, receive, _send)
  File "C:\Users\Sobre\OneDrive\Desktop\Vroomble\.venv\Lib\site-packages\starlette\middleware\cors.py", line 93, in __call__
    await self.simple_response(scope, receive, send, request_headers=headers)
  File "C:\Users\Sobre\OneDrive\Desktop\Vroomble\.venv\Lib\site-packages\starlette\middleware\cors.py", line 144, in simple_response
    await self.app(scope, receive, send)
  File "C:\Users\Sobre\OneDrive\Desktop\Vroomble\.venv\Lib\site-packages\starlette\middleware\exceptions.py", line 62, in __call__
    await wrap_app_handling_exceptions(self.app, conn)(scope, receive, send)
  File "C:\Users\Sobre\OneDrive\Desktop\Vroomble\.venv\Lib\site-packages\starlette\_exception_handler.py", line 53, in wrapped_app
    raise exc
  File "C:\Users\Sobre\OneDrive\Desktop\Vroomble\.venv\Lib\site-packages\starlette\_exception_handler.py", line 42, in wrapped_app
    await app(scope, receive, sender)
  File "C:\Users\Sobre\OneDrive\Desktop\Vroomble\.venv\Lib\site-packages\starlette\routing.py", line 715, in __call__
    await self.middleware_stack(scope, receive, send)
  File "C:\Users\Sobre\OneDrive\Desktop\Vroomble\.venv\Lib\site-packages\starlette\routing.py", line 735, in app
    await route.handle(scope, receive, send)
  File "C:\Users\Sobre\OneDrive\Desktop\Vroomble\.venv\Lib\site-packages\starlette\routing.py", line 288, in handle
    await self.app(scope, receive, send)
  File "C:\Users\Sobre\OneDrive\Desktop\Vroomble\.venv\Lib\site-packages\starlette\routing.py", line 76, in app
    await wrap_app_handling_exceptions(app, request)(scope, receive, send)
  File "C:\Users\Sobre\OneDrive\Desktop\Vroomble\.venv\Lib\site-packages\starlette\_exception_handler.py", line 53, in wrapped_app
    raise exc
  File "C:\Users\Sobre\OneDrive\Desktop\Vroomble\.venv\Lib\site-packages\starlette\_exception_handler.py", line 42, in wrapped_app
    await app(scope, receive, sender)
  File "C:\Users\Sobre\OneDrive\Desktop\Vroomble\.venv\Lib\site-packages\starlette\routing.py", line 73, in app
    response = await f(request)
               ^^^^^^^^^^^^^^^^
  File "C:\Users\Sobre\OneDrive\Desktop\Vroomble\.venv\Lib\site-packages\fastapi\routing.py", line 301, in app
    raw_response = await run_endpoint_function(
                   ^^^^^^^^^^^^^^^^^^^^^^^^^^^^
  File "C:\Users\Sobre\OneDrive\Desktop\Vroomble\.venv\Lib\site-packages\fastapi\routing.py", line 212, in run_endpoint_function
    return await dependant.call(**values)
           ^^^^^^^^^^^^^^^^^^^^^^^^^^^^^^
  File "C:\Users\Sobre\OneDrive\Desktop\Vroomble\src\APIs\vehicle_registration.py", line 148, in create_car_form
    with sqlitecloud.connect(DATABASE_URL) as conn:
                             ^^^^^^^^^^^^
NameError: name 'DATABASE_URL' is not defined
2025-03-09 12:03:27,232 - ERROR - \u274c SQLite Cloud database table initialization error: Database Vroomble%20Dataset does not exist.
2025-03-11 09:24:30,805 - ERROR - \u274c Error initializing SQLite Cloud database table: Invalid APIKEY.
2025-03-11 09:25:07,988 - ERROR - \u274c Error initializing SQLite Cloud database table: Invalid APIKEY.
2025-03-11 09:26:23,261 - ERROR - \u274c Error initializing SQLite Cloud database table: Invalid APIKEY.
2025-03-11 09:26:57,777 - ERROR - \u274c Error initializing SQLite Cloud database table: Invalid APIKEY.
2025-03-11 09:27:30,337 - ERROR - \u274c Error initializing SQLite Cloud database table: Invalid APIKEY.
2025-03-11 09:27:46,608 - ERROR - \u274c Error initializing SQLite Cloud database table: Invalid APIKEY.
2025-03-11 09:33:53,665 - ERROR - \u274c Error initializing SQLite Cloud database table: Invalid APIKEY.
2025-03-11 17:51:33,718 - DEBUG - cannot commit - no transaction is active
2025-03-11 17:51:33,719 - INFO - \u2705 'cars' table initialized in SQLite Cloud.
2025-03-11 17:51:33,778 - DEBUG - cannot commit - no transaction is active
2025-03-11 17:52:25,317 - DEBUG - cannot commit - no transaction is active
2025-03-11 17:52:25,318 - INFO - \u2705 'cars' table initialized in SQLite Cloud.
2025-03-11 17:52:25,371 - DEBUG - cannot commit - no transaction is active
2025-03-11 17:52:29,848 - DEBUG - cannot rollback - no transaction is active
2025-03-11 17:52:29,849 - ERROR - Rolling back transaction - error 'no such column: deleted_at'
Traceback (most recent call last):
  File "C:\Users\456\Desktop\setj\src\APIs\vehicle_registration.py", line 140, in get_vehicles
    cursor.execute(
    ~~~~~~~~~~~~~~^
        "SELECT CarID, Make, Model, COALESCE(Variant, 'N/A'), COALESCE(Drivetrain, 'Unknown'), Year FROM cars WHERE deleted_at IS NULL"
        ^^^^^^^^^^^^^^^^^^^^^^^^^^^^^^^^^^^^^^^^^^^^^^^^^^^^^^^^^^^^^^^^^^^^^^^^^^^^^^^^^^^^^^^^^^^^^^^^^^^^^^^^^^^^^^^^^^^^^^^^^^^^^^^
    )
    ^
  File "C:\Users\456\AppData\Local\Programs\Python\Python313\Lib\site-packages\sqlitecloud\dbapi2.py", line 583, in execute
    result = self._driver.execute_statement(
        sql, parameters, self.connection.sqlitecloud_connection
    )
  File "C:\Users\456\AppData\Local\Programs\Python\Python313\Lib\site-packages\sqlitecloud\driver.py", line 109, in execute_statement
    result = self._internal_run_command(connection, command)
  File "C:\Users\456\AppData\Local\Programs\Python\Python313\Lib\site-packages\sqlitecloud\driver.py", line 482, in _internal_run_command
    return self._internal_socket_read(connection, main_socket)
           ~~~~~~~~~~~~~~~~~~~~~~~~~~^^^^^^^^^^^^^^^^^^^^^^^^^
  File "C:\Users\456\AppData\Local\Programs\Python\Python313\Lib\site-packages\sqlitecloud\driver.py", line 590, in _internal_socket_read
    return self._internal_parse_buffer(connection, buffer, len(buffer))
           ~~~~~~~~~~~~~~~~~~~~~~~~~~~^^^^^^^^^^^^^^^^^^^^^^^^^^^^^^^^^
  File "C:\Users\456\AppData\Local\Programs\Python\Python313\Lib\site-packages\sqlitecloud\driver.py", line 731, in _internal_parse_buffer
    raise get_sqlitecloud_error_with_extended_code(
        errmsg.decode(), errcode, xerrcode
    )(errmsg.decode(), errcode, xerrcode)
sqlitecloud.exceptions.SQLiteCloudOperationalError: no such column: deleted_at
2025-03-11 17:52:29,856 - ERROR - \u274c Error fetching vehicles: no such column: deleted_at
2025-03-11 17:52:30,484 - DEBUG - cannot rollback - no transaction is active
2025-03-11 17:52:30,484 - ERROR - Rolling back transaction - error 'no such column: deleted_at'
Traceback (most recent call last):
  File "C:\Users\456\Desktop\setj\src\APIs\vehicle_registration.py", line 140, in get_vehicles
    cursor.execute(
    ~~~~~~~~~~~~~~^
        "SELECT CarID, Make, Model, COALESCE(Variant, 'N/A'), COALESCE(Drivetrain, 'Unknown'), Year FROM cars WHERE deleted_at IS NULL"
        ^^^^^^^^^^^^^^^^^^^^^^^^^^^^^^^^^^^^^^^^^^^^^^^^^^^^^^^^^^^^^^^^^^^^^^^^^^^^^^^^^^^^^^^^^^^^^^^^^^^^^^^^^^^^^^^^^^^^^^^^^^^^^^^
    )
    ^
  File "C:\Users\456\AppData\Local\Programs\Python\Python313\Lib\site-packages\sqlitecloud\dbapi2.py", line 583, in execute
    result = self._driver.execute_statement(
        sql, parameters, self.connection.sqlitecloud_connection
    )
  File "C:\Users\456\AppData\Local\Programs\Python\Python313\Lib\site-packages\sqlitecloud\driver.py", line 109, in execute_statement
    result = self._internal_run_command(connection, command)
  File "C:\Users\456\AppData\Local\Programs\Python\Python313\Lib\site-packages\sqlitecloud\driver.py", line 482, in _internal_run_command
    return self._internal_socket_read(connection, main_socket)
           ~~~~~~~~~~~~~~~~~~~~~~~~~~^^^^^^^^^^^^^^^^^^^^^^^^^
  File "C:\Users\456\AppData\Local\Programs\Python\Python313\Lib\site-packages\sqlitecloud\driver.py", line 590, in _internal_socket_read
    return self._internal_parse_buffer(connection, buffer, len(buffer))
           ~~~~~~~~~~~~~~~~~~~~~~~~~~~^^^^^^^^^^^^^^^^^^^^^^^^^^^^^^^^^
  File "C:\Users\456\AppData\Local\Programs\Python\Python313\Lib\site-packages\sqlitecloud\driver.py", line 731, in _internal_parse_buffer
    raise get_sqlitecloud_error_with_extended_code(
        errmsg.decode(), errcode, xerrcode
    )(errmsg.decode(), errcode, xerrcode)
sqlitecloud.exceptions.SQLiteCloudOperationalError: no such column: deleted_at
2025-03-11 17:52:30,488 - ERROR - \u274c Error fetching vehicles: no such column: deleted_at
2025-03-12 14:25:36,418 - DEBUG - registered 'bcrypt' handler: <class 'passlib.handlers.bcrypt.bcrypt'>
2025-03-12 14:25:38,269 - DEBUG - cannot commit - no transaction is active
2025-03-12 14:25:38,395 - DEBUG - cannot commit - no transaction is active
2025-03-16 02:01:24,783 - ERROR - \u274c Error initializing SQLite Cloud database table: An error occurred while initializing the socket.
2025-03-16 02:01:33,455 - ERROR - \u274c Error initializing SQLite Cloud database table: An error occurred while initializing the socket.
2025-03-16 02:01:42,258 - DEBUG - cannot commit - no transaction is active
2025-03-16 02:01:42,258 - INFO - \u2705 SQLite Cloud Database table 'cars' initialized.
2025-03-16 02:01:42,298 - DEBUG - cannot commit - no transaction is active
2025-03-16 02:02:41,912 - DEBUG - registered 'bcrypt' handler: <class 'passlib.handlers.bcrypt.bcrypt'>
2025-03-16 02:02:42,022 - ERROR - \u274c Error connecting to cloud database: An error occurred while initializing the socket.
