2025-03-02 01:53:56,800 - INFO - Database table created or already exists.
2025-03-02 01:57:02,574 - ERROR - Validation error: [{'type': 'int_parsing', 'loc': ('body', 'year'), 'msg': 'Input should be a valid integer, unable to parse string as an integer', 'input': ''}, {'type': 'value_error', 'loc': ('body', 'retail_srp'), 'msg': 'Value error, Retail SRP must be positive', 'input': 0, 'ctx': {'error': ValueError('Retail SRP must be positive')}}]
2025-03-02 01:57:02,574 - ERROR - Unhandled exception: Object of type ValueError is not JSON serializable
Traceback (most recent call last):
  File "C:\Users\Sobre\OneDrive\Desktop\Vroomble\.venv\Lib\site-packages\starlette\_exception_handler.py", line 42, in wrapped_app
    await app(scope, receive, sender)
  File "C:\Users\Sobre\OneDrive\Desktop\Vroomble\.venv\Lib\site-packages\starlette\routing.py", line 73, in app
    response = await f(request)
               ^^^^^^^^^^^^^^^^
  File "C:\Users\Sobre\OneDrive\Desktop\Vroomble\.venv\Lib\site-packages\fastapi\routing.py", line 346, in app
    raise validation_error
fastapi.exceptions.RequestValidationError: [{'type': 'int_parsing', 'loc': ('body', 'year'), 'msg': 'Input should be a valid integer, unable to parse string as an integer', 'input': ''}, {'type': 'value_error', 'loc': ('body', 'retail_srp'), 'msg': 'Value error, Retail SRP must be positive', 'input': 0, 'ctx': {'error': ValueError('Retail SRP must be positive')}}]

During handling of the above exception, another exception occurred:

Traceback (most recent call last):
  File "C:\Users\Sobre\OneDrive\Desktop\Vroomble\.venv\Lib\site-packages\starlette\middleware\errors.py", line 165, in __call__
    await self.app(scope, receive, _send)
  File "C:\Users\Sobre\OneDrive\Desktop\Vroomble\.venv\Lib\site-packages\starlette\middleware\cors.py", line 93, in __call__
    await self.simple_response(scope, receive, send, request_headers=headers)
  File "C:\Users\Sobre\OneDrive\Desktop\Vroomble\.venv\Lib\site-packages\starlette\middleware\cors.py", line 144, in simple_response
    await self.app(scope, receive, send)
  File "C:\Users\Sobre\OneDrive\Desktop\Vroomble\.venv\Lib\site-packages\starlette\middleware\exceptions.py", line 62, in __call__
    await wrap_app_handling_exceptions(self.app, conn)(scope, receive, send)
  File "C:\Users\Sobre\OneDrive\Desktop\Vroomble\.venv\Lib\site-packages\starlette\_exception_handler.py", line 53, in wrapped_app
    raise exc
  File "C:\Users\Sobre\OneDrive\Desktop\Vroomble\.venv\Lib\site-packages\starlette\_exception_handler.py", line 42, in wrapped_app
    await app(scope, receive, sender)
  File "C:\Users\Sobre\OneDrive\Desktop\Vroomble\.venv\Lib\site-packages\starlette\routing.py", line 715, in __call__
    await self.middleware_stack(scope, receive, send)
  File "C:\Users\Sobre\OneDrive\Desktop\Vroomble\.venv\Lib\site-packages\starlette\routing.py", line 735, in app
    await route.handle(scope, receive, send)
  File "C:\Users\Sobre\OneDrive\Desktop\Vroomble\.venv\Lib\site-packages\starlette\routing.py", line 288, in handle
    await self.app(scope, receive, send)
  File "C:\Users\Sobre\OneDrive\Desktop\Vroomble\.venv\Lib\site-packages\starlette\routing.py", line 76, in app
    await wrap_app_handling_exceptions(app, request)(scope, receive, send)
  File "C:\Users\Sobre\OneDrive\Desktop\Vroomble\.venv\Lib\site-packages\starlette\_exception_handler.py", line 59, in wrapped_app
    response = await handler(conn, exc)
               ^^^^^^^^^^^^^^^^^^^^^^^^
  File "C:\Users\Sobre\OneDrive\Desktop\Vroomble\src\APIs\vehicle_registration.py", line 170, in validation_exception_handler
    return JSONResponse(
           ^^^^^^^^^^^^^
  File "C:\Users\Sobre\OneDrive\Desktop\Vroomble\.venv\Lib\site-packages\starlette\responses.py", line 181, in __init__
    super().__init__(content, status_code, headers, media_type, background)
  File "C:\Users\Sobre\OneDrive\Desktop\Vroomble\.venv\Lib\site-packages\starlette\responses.py", line 44, in __init__
    self.body = self.render(content)
                ^^^^^^^^^^^^^^^^^^^^
  File "C:\Users\Sobre\OneDrive\Desktop\Vroomble\.venv\Lib\site-packages\starlette\responses.py", line 184, in render
    return json.dumps(
           ^^^^^^^^^^^
  File "C:\Program Files\WindowsApps\PythonSoftwareFoundation.Python.3.11_3.11.2544.0_x64__qbz5n2kfra8p0\Lib\json\__init__.py", line 238, in dumps
    **kw).encode(obj)
          ^^^^^^^^^^^
  File "C:\Program Files\WindowsApps\PythonSoftwareFoundation.Python.3.11_3.11.2544.0_x64__qbz5n2kfra8p0\Lib\json\encoder.py", line 200, in encode
    chunks = self.iterencode(o, _one_shot=True)
             ^^^^^^^^^^^^^^^^^^^^^^^^^^^^^^^^^^
  File "C:\Program Files\WindowsApps\PythonSoftwareFoundation.Python.3.11_3.11.2544.0_x64__qbz5n2kfra8p0\Lib\json\encoder.py", line 258, in iterencode
    return _iterencode(o, 0)
           ^^^^^^^^^^^^^^^^^
  File "C:\Program Files\WindowsApps\PythonSoftwareFoundation.Python.3.11_3.11.2544.0_x64__qbz5n2kfra8p0\Lib\json\encoder.py", line 180, in default
    raise TypeError(f'Object of type {o.__class__.__name__} '
TypeError: Object of type ValueError is not JSON serializable
2025-03-02 01:57:10,637 - ERROR - Validation error: [{'type': 'int_parsing', 'loc': ('body', 'year'), 'msg': 'Input should be a valid integer, unable to parse string as an integer', 'input': ''}, {'type': 'value_error', 'loc': ('body', 'retail_srp'), 'msg': 'Value error, Retail SRP must be positive', 'input': 0, 'ctx': {'error': ValueError('Retail SRP must be positive')}}]
2025-03-02 01:57:10,637 - ERROR - Unhandled exception: Object of type ValueError is not JSON serializable
Traceback (most recent call last):
  File "C:\Users\Sobre\OneDrive\Desktop\Vroomble\.venv\Lib\site-packages\starlette\_exception_handler.py", line 42, in wrapped_app
    await app(scope, receive, sender)
  File "C:\Users\Sobre\OneDrive\Desktop\Vroomble\.venv\Lib\site-packages\starlette\routing.py", line 73, in app
    response = await f(request)
               ^^^^^^^^^^^^^^^^
  File "C:\Users\Sobre\OneDrive\Desktop\Vroomble\.venv\Lib\site-packages\fastapi\routing.py", line 346, in app
    raise validation_error
fastapi.exceptions.RequestValidationError: [{'type': 'int_parsing', 'loc': ('body', 'year'), 'msg': 'Input should be a valid integer, unable to parse string as an integer', 'input': ''}, {'type': 'value_error', 'loc': ('body', 'retail_srp'), 'msg': 'Value error, Retail SRP must be positive', 'input': 0, 'ctx': {'error': ValueError('Retail SRP must be positive')}}]

During handling of the above exception, another exception occurred:

Traceback (most recent call last):
  File "C:\Users\Sobre\OneDrive\Desktop\Vroomble\.venv\Lib\site-packages\starlette\middleware\errors.py", line 165, in __call__
    await self.app(scope, receive, _send)
  File "C:\Users\Sobre\OneDrive\Desktop\Vroomble\.venv\Lib\site-packages\starlette\middleware\cors.py", line 93, in __call__
    await self.simple_response(scope, receive, send, request_headers=headers)
  File "C:\Users\Sobre\OneDrive\Desktop\Vroomble\.venv\Lib\site-packages\starlette\middleware\cors.py", line 144, in simple_response
    await self.app(scope, receive, send)
  File "C:\Users\Sobre\OneDrive\Desktop\Vroomble\.venv\Lib\site-packages\starlette\middleware\exceptions.py", line 62, in __call__
    await wrap_app_handling_exceptions(self.app, conn)(scope, receive, send)
  File "C:\Users\Sobre\OneDrive\Desktop\Vroomble\.venv\Lib\site-packages\starlette\_exception_handler.py", line 53, in wrapped_app
    raise exc
  File "C:\Users\Sobre\OneDrive\Desktop\Vroomble\.venv\Lib\site-packages\starlette\_exception_handler.py", line 42, in wrapped_app
    await app(scope, receive, sender)
  File "C:\Users\Sobre\OneDrive\Desktop\Vroomble\.venv\Lib\site-packages\starlette\routing.py", line 715, in __call__
    await self.middleware_stack(scope, receive, send)
  File "C:\Users\Sobre\OneDrive\Desktop\Vroomble\.venv\Lib\site-packages\starlette\routing.py", line 735, in app
    await route.handle(scope, receive, send)
  File "C:\Users\Sobre\OneDrive\Desktop\Vroomble\.venv\Lib\site-packages\starlette\routing.py", line 288, in handle
    await self.app(scope, receive, send)
  File "C:\Users\Sobre\OneDrive\Desktop\Vroomble\.venv\Lib\site-packages\starlette\routing.py", line 76, in app
    await wrap_app_handling_exceptions(app, request)(scope, receive, send)
  File "C:\Users\Sobre\OneDrive\Desktop\Vroomble\.venv\Lib\site-packages\starlette\_exception_handler.py", line 59, in wrapped_app
    response = await handler(conn, exc)
               ^^^^^^^^^^^^^^^^^^^^^^^^
  File "C:\Users\Sobre\OneDrive\Desktop\Vroomble\src\APIs\vehicle_registration.py", line 170, in validation_exception_handler
    return JSONResponse(
           ^^^^^^^^^^^^^
  File "C:\Users\Sobre\OneDrive\Desktop\Vroomble\.venv\Lib\site-packages\starlette\responses.py", line 181, in __init__
    super().__init__(content, status_code, headers, media_type, background)
  File "C:\Users\Sobre\OneDrive\Desktop\Vroomble\.venv\Lib\site-packages\starlette\responses.py", line 44, in __init__
    self.body = self.render(content)
                ^^^^^^^^^^^^^^^^^^^^
  File "C:\Users\Sobre\OneDrive\Desktop\Vroomble\.venv\Lib\site-packages\starlette\responses.py", line 184, in render
    return json.dumps(
           ^^^^^^^^^^^
  File "C:\Program Files\WindowsApps\PythonSoftwareFoundation.Python.3.11_3.11.2544.0_x64__qbz5n2kfra8p0\Lib\json\__init__.py", line 238, in dumps
    **kw).encode(obj)
          ^^^^^^^^^^^
  File "C:\Program Files\WindowsApps\PythonSoftwareFoundation.Python.3.11_3.11.2544.0_x64__qbz5n2kfra8p0\Lib\json\encoder.py", line 200, in encode
    chunks = self.iterencode(o, _one_shot=True)
             ^^^^^^^^^^^^^^^^^^^^^^^^^^^^^^^^^^
  File "C:\Program Files\WindowsApps\PythonSoftwareFoundation.Python.3.11_3.11.2544.0_x64__qbz5n2kfra8p0\Lib\json\encoder.py", line 258, in iterencode
    return _iterencode(o, 0)
           ^^^^^^^^^^^^^^^^^
  File "C:\Program Files\WindowsApps\PythonSoftwareFoundation.Python.3.11_3.11.2544.0_x64__qbz5n2kfra8p0\Lib\json\encoder.py", line 180, in default
    raise TypeError(f'Object of type {o.__class__.__name__} '
TypeError: Object of type ValueError is not JSON serializable
2025-03-02 01:57:17,118 - ERROR - Validation error: [{'type': 'int_parsing', 'loc': ('body', 'year'), 'msg': 'Input should be a valid integer, unable to parse string as an integer', 'input': ''}, {'type': 'value_error', 'loc': ('body', 'retail_srp'), 'msg': 'Value error, Retail SRP must be positive', 'input': 0, 'ctx': {'error': ValueError('Retail SRP must be positive')}}]
2025-03-02 01:57:17,118 - ERROR - Unhandled exception: Object of type ValueError is not JSON serializable
Traceback (most recent call last):
  File "C:\Users\Sobre\OneDrive\Desktop\Vroomble\.venv\Lib\site-packages\starlette\_exception_handler.py", line 42, in wrapped_app
    await app(scope, receive, sender)
  File "C:\Users\Sobre\OneDrive\Desktop\Vroomble\.venv\Lib\site-packages\starlette\routing.py", line 73, in app
    response = await f(request)
               ^^^^^^^^^^^^^^^^
  File "C:\Users\Sobre\OneDrive\Desktop\Vroomble\.venv\Lib\site-packages\fastapi\routing.py", line 346, in app
    raise validation_error
fastapi.exceptions.RequestValidationError: [{'type': 'int_parsing', 'loc': ('body', 'year'), 'msg': 'Input should be a valid integer, unable to parse string as an integer', 'input': ''}, {'type': 'value_error', 'loc': ('body', 'retail_srp'), 'msg': 'Value error, Retail SRP must be positive', 'input': 0, 'ctx': {'error': ValueError('Retail SRP must be positive')}}]

During handling of the above exception, another exception occurred:

Traceback (most recent call last):
  File "C:\Users\Sobre\OneDrive\Desktop\Vroomble\.venv\Lib\site-packages\starlette\middleware\errors.py", line 165, in __call__
    await self.app(scope, receive, _send)
  File "C:\Users\Sobre\OneDrive\Desktop\Vroomble\.venv\Lib\site-packages\starlette\middleware\cors.py", line 93, in __call__
    await self.simple_response(scope, receive, send, request_headers=headers)
  File "C:\Users\Sobre\OneDrive\Desktop\Vroomble\.venv\Lib\site-packages\starlette\middleware\cors.py", line 144, in simple_response
    await self.app(scope, receive, send)
  File "C:\Users\Sobre\OneDrive\Desktop\Vroomble\.venv\Lib\site-packages\starlette\middleware\exceptions.py", line 62, in __call__
    await wrap_app_handling_exceptions(self.app, conn)(scope, receive, send)
  File "C:\Users\Sobre\OneDrive\Desktop\Vroomble\.venv\Lib\site-packages\starlette\_exception_handler.py", line 53, in wrapped_app
    raise exc
  File "C:\Users\Sobre\OneDrive\Desktop\Vroomble\.venv\Lib\site-packages\starlette\_exception_handler.py", line 42, in wrapped_app
    await app(scope, receive, sender)
  File "C:\Users\Sobre\OneDrive\Desktop\Vroomble\.venv\Lib\site-packages\starlette\routing.py", line 715, in __call__
    await self.middleware_stack(scope, receive, send)
  File "C:\Users\Sobre\OneDrive\Desktop\Vroomble\.venv\Lib\site-packages\starlette\routing.py", line 735, in app
    await route.handle(scope, receive, send)
  File "C:\Users\Sobre\OneDrive\Desktop\Vroomble\.venv\Lib\site-packages\starlette\routing.py", line 288, in handle
    await self.app(scope, receive, send)
  File "C:\Users\Sobre\OneDrive\Desktop\Vroomble\.venv\Lib\site-packages\starlette\routing.py", line 76, in app
    await wrap_app_handling_exceptions(app, request)(scope, receive, send)
  File "C:\Users\Sobre\OneDrive\Desktop\Vroomble\.venv\Lib\site-packages\starlette\_exception_handler.py", line 59, in wrapped_app
    response = await handler(conn, exc)
               ^^^^^^^^^^^^^^^^^^^^^^^^
  File "C:\Users\Sobre\OneDrive\Desktop\Vroomble\src\APIs\vehicle_registration.py", line 170, in validation_exception_handler
    return JSONResponse(
           ^^^^^^^^^^^^^
  File "C:\Users\Sobre\OneDrive\Desktop\Vroomble\.venv\Lib\site-packages\starlette\responses.py", line 181, in __init__
    super().__init__(content, status_code, headers, media_type, background)
  File "C:\Users\Sobre\OneDrive\Desktop\Vroomble\.venv\Lib\site-packages\starlette\responses.py", line 44, in __init__
    self.body = self.render(content)
                ^^^^^^^^^^^^^^^^^^^^
  File "C:\Users\Sobre\OneDrive\Desktop\Vroomble\.venv\Lib\site-packages\starlette\responses.py", line 184, in render
    return json.dumps(
           ^^^^^^^^^^^
  File "C:\Program Files\WindowsApps\PythonSoftwareFoundation.Python.3.11_3.11.2544.0_x64__qbz5n2kfra8p0\Lib\json\__init__.py", line 238, in dumps
    **kw).encode(obj)
          ^^^^^^^^^^^
  File "C:\Program Files\WindowsApps\PythonSoftwareFoundation.Python.3.11_3.11.2544.0_x64__qbz5n2kfra8p0\Lib\json\encoder.py", line 200, in encode
    chunks = self.iterencode(o, _one_shot=True)
             ^^^^^^^^^^^^^^^^^^^^^^^^^^^^^^^^^^
  File "C:\Program Files\WindowsApps\PythonSoftwareFoundation.Python.3.11_3.11.2544.0_x64__qbz5n2kfra8p0\Lib\json\encoder.py", line 258, in iterencode
    return _iterencode(o, 0)
           ^^^^^^^^^^^^^^^^^
  File "C:\Program Files\WindowsApps\PythonSoftwareFoundation.Python.3.11_3.11.2544.0_x64__qbz5n2kfra8p0\Lib\json\encoder.py", line 180, in default
    raise TypeError(f'Object of type {o.__class__.__name__} '
TypeError: Object of type ValueError is not JSON serializable
2025-03-02 01:57:20,380 - ERROR - Validation error: [{'type': 'int_parsing', 'loc': ('body', 'year'), 'msg': 'Input should be a valid integer, unable to parse string as an integer', 'input': ''}, {'type': 'value_error', 'loc': ('body', 'retail_srp'), 'msg': 'Value error, Retail SRP must be positive', 'input': 0, 'ctx': {'error': ValueError('Retail SRP must be positive')}}]
2025-03-02 01:57:20,382 - ERROR - Unhandled exception: Object of type ValueError is not JSON serializable
Traceback (most recent call last):
  File "C:\Users\Sobre\OneDrive\Desktop\Vroomble\.venv\Lib\site-packages\starlette\_exception_handler.py", line 42, in wrapped_app
    await app(scope, receive, sender)
  File "C:\Users\Sobre\OneDrive\Desktop\Vroomble\.venv\Lib\site-packages\starlette\routing.py", line 73, in app
    response = await f(request)
               ^^^^^^^^^^^^^^^^
  File "C:\Users\Sobre\OneDrive\Desktop\Vroomble\.venv\Lib\site-packages\fastapi\routing.py", line 346, in app
    raise validation_error
fastapi.exceptions.RequestValidationError: [{'type': 'int_parsing', 'loc': ('body', 'year'), 'msg': 'Input should be a valid integer, unable to parse string as an integer', 'input': ''}, {'type': 'value_error', 'loc': ('body', 'retail_srp'), 'msg': 'Value error, Retail SRP must be positive', 'input': 0, 'ctx': {'error': ValueError('Retail SRP must be positive')}}]

During handling of the above exception, another exception occurred:

Traceback (most recent call last):
  File "C:\Users\Sobre\OneDrive\Desktop\Vroomble\.venv\Lib\site-packages\starlette\middleware\errors.py", line 165, in __call__
    await self.app(scope, receive, _send)
  File "C:\Users\Sobre\OneDrive\Desktop\Vroomble\.venv\Lib\site-packages\starlette\middleware\cors.py", line 93, in __call__
    await self.simple_response(scope, receive, send, request_headers=headers)
  File "C:\Users\Sobre\OneDrive\Desktop\Vroomble\.venv\Lib\site-packages\starlette\middleware\cors.py", line 144, in simple_response
    await self.app(scope, receive, send)
  File "C:\Users\Sobre\OneDrive\Desktop\Vroomble\.venv\Lib\site-packages\starlette\middleware\exceptions.py", line 62, in __call__
    await wrap_app_handling_exceptions(self.app, conn)(scope, receive, send)
  File "C:\Users\Sobre\OneDrive\Desktop\Vroomble\.venv\Lib\site-packages\starlette\_exception_handler.py", line 53, in wrapped_app
    raise exc
  File "C:\Users\Sobre\OneDrive\Desktop\Vroomble\.venv\Lib\site-packages\starlette\_exception_handler.py", line 42, in wrapped_app
    await app(scope, receive, sender)
  File "C:\Users\Sobre\OneDrive\Desktop\Vroomble\.venv\Lib\site-packages\starlette\routing.py", line 715, in __call__
    await self.middleware_stack(scope, receive, send)
  File "C:\Users\Sobre\OneDrive\Desktop\Vroomble\.venv\Lib\site-packages\starlette\routing.py", line 735, in app
    await route.handle(scope, receive, send)
  File "C:\Users\Sobre\OneDrive\Desktop\Vroomble\.venv\Lib\site-packages\starlette\routing.py", line 288, in handle
    await self.app(scope, receive, send)
  File "C:\Users\Sobre\OneDrive\Desktop\Vroomble\.venv\Lib\site-packages\starlette\routing.py", line 76, in app
    await wrap_app_handling_exceptions(app, request)(scope, receive, send)
  File "C:\Users\Sobre\OneDrive\Desktop\Vroomble\.venv\Lib\site-packages\starlette\_exception_handler.py", line 59, in wrapped_app
    response = await handler(conn, exc)
               ^^^^^^^^^^^^^^^^^^^^^^^^
  File "C:\Users\Sobre\OneDrive\Desktop\Vroomble\src\APIs\vehicle_registration.py", line 170, in validation_exception_handler
    return JSONResponse(
           ^^^^^^^^^^^^^
  File "C:\Users\Sobre\OneDrive\Desktop\Vroomble\.venv\Lib\site-packages\starlette\responses.py", line 181, in __init__
    super().__init__(content, status_code, headers, media_type, background)
  File "C:\Users\Sobre\OneDrive\Desktop\Vroomble\.venv\Lib\site-packages\starlette\responses.py", line 44, in __init__
    self.body = self.render(content)
                ^^^^^^^^^^^^^^^^^^^^
  File "C:\Users\Sobre\OneDrive\Desktop\Vroomble\.venv\Lib\site-packages\starlette\responses.py", line 184, in render
    return json.dumps(
           ^^^^^^^^^^^
  File "C:\Program Files\WindowsApps\PythonSoftwareFoundation.Python.3.11_3.11.2544.0_x64__qbz5n2kfra8p0\Lib\json\__init__.py", line 238, in dumps
    **kw).encode(obj)
          ^^^^^^^^^^^
  File "C:\Program Files\WindowsApps\PythonSoftwareFoundation.Python.3.11_3.11.2544.0_x64__qbz5n2kfra8p0\Lib\json\encoder.py", line 200, in encode
    chunks = self.iterencode(o, _one_shot=True)
             ^^^^^^^^^^^^^^^^^^^^^^^^^^^^^^^^^^
  File "C:\Program Files\WindowsApps\PythonSoftwareFoundation.Python.3.11_3.11.2544.0_x64__qbz5n2kfra8p0\Lib\json\encoder.py", line 258, in iterencode
    return _iterencode(o, 0)
           ^^^^^^^^^^^^^^^^^
  File "C:\Program Files\WindowsApps\PythonSoftwareFoundation.Python.3.11_3.11.2544.0_x64__qbz5n2kfra8p0\Lib\json\encoder.py", line 180, in default
    raise TypeError(f'Object of type {o.__class__.__name__} '
TypeError: Object of type ValueError is not JSON serializable
2025-03-02 02:04:17,407 - INFO - Database table created or already exists.
2025-03-02 02:10:10,129 - ERROR - Validation error: [{'type': 'int_parsing', 'loc': ('body', 'year'), 'msg': 'Input should be a valid integer, unable to parse string as an integer', 'input': ''}, {'type': 'float_parsing', 'loc': ('body', 'retail_srp'), 'msg': 'Input should be a valid number, unable to parse string as a number', 'input': ''}]
2025-03-02 02:10:13,286 - ERROR - Validation error: [{'type': 'int_parsing', 'loc': ('body', 'year'), 'msg': 'Input should be a valid integer, unable to parse string as an integer', 'input': ''}, {'type': 'float_parsing', 'loc': ('body', 'retail_srp'), 'msg': 'Input should be a valid number, unable to parse string as a number', 'input': ''}]
2025-03-02 02:12:40,730 - ERROR - Validation error: [{'type': 'value_error', 'loc': ('body', 'year'), 'msg': 'Value error, Invalid year', 'input': 0, 'ctx': {'error': ValueError('Invalid year')}}, {'type': 'value_error', 'loc': ('body', 'retail_srp'), 'msg': 'Value error, Retail SRP must be positive', 'input': 0, 'ctx': {'error': ValueError('Retail SRP must be positive')}}]
2025-03-02 02:12:40,731 - ERROR - Unhandled exception: Object of type ValueError is not JSON serializable
Traceback (most recent call last):
  File "C:\Users\Sobre\OneDrive\Desktop\Vroomble\.venv\Lib\site-packages\starlette\_exception_handler.py", line 42, in wrapped_app
    await app(scope, receive, sender)
  File "C:\Users\Sobre\OneDrive\Desktop\Vroomble\.venv\Lib\site-packages\starlette\routing.py", line 73, in app
    response = await f(request)
               ^^^^^^^^^^^^^^^^
  File "C:\Users\Sobre\OneDrive\Desktop\Vroomble\.venv\Lib\site-packages\fastapi\routing.py", line 346, in app
    raise validation_error
fastapi.exceptions.RequestValidationError: [{'type': 'value_error', 'loc': ('body', 'year'), 'msg': 'Value error, Invalid year', 'input': 0, 'ctx': {'error': ValueError('Invalid year')}}, {'type': 'value_error', 'loc': ('body', 'retail_srp'), 'msg': 'Value error, Retail SRP must be positive', 'input': 0, 'ctx': {'error': ValueError('Retail SRP must be positive')}}]

During handling of the above exception, another exception occurred:

Traceback (most recent call last):
  File "C:\Users\Sobre\OneDrive\Desktop\Vroomble\.venv\Lib\site-packages\starlette\middleware\errors.py", line 165, in __call__
    await self.app(scope, receive, _send)
  File "C:\Users\Sobre\OneDrive\Desktop\Vroomble\.venv\Lib\site-packages\starlette\middleware\cors.py", line 93, in __call__
    await self.simple_response(scope, receive, send, request_headers=headers)
  File "C:\Users\Sobre\OneDrive\Desktop\Vroomble\.venv\Lib\site-packages\starlette\middleware\cors.py", line 144, in simple_response
    await self.app(scope, receive, send)
  File "C:\Users\Sobre\OneDrive\Desktop\Vroomble\.venv\Lib\site-packages\starlette\middleware\exceptions.py", line 62, in __call__
    await wrap_app_handling_exceptions(self.app, conn)(scope, receive, send)
  File "C:\Users\Sobre\OneDrive\Desktop\Vroomble\.venv\Lib\site-packages\starlette\_exception_handler.py", line 53, in wrapped_app
    raise exc
  File "C:\Users\Sobre\OneDrive\Desktop\Vroomble\.venv\Lib\site-packages\starlette\_exception_handler.py", line 42, in wrapped_app
    await app(scope, receive, sender)
  File "C:\Users\Sobre\OneDrive\Desktop\Vroomble\.venv\Lib\site-packages\starlette\routing.py", line 715, in __call__
    await self.middleware_stack(scope, receive, send)
  File "C:\Users\Sobre\OneDrive\Desktop\Vroomble\.venv\Lib\site-packages\starlette\routing.py", line 735, in app
    await route.handle(scope, receive, send)
  File "C:\Users\Sobre\OneDrive\Desktop\Vroomble\.venv\Lib\site-packages\starlette\routing.py", line 288, in handle
    await self.app(scope, receive, send)
  File "C:\Users\Sobre\OneDrive\Desktop\Vroomble\.venv\Lib\site-packages\starlette\routing.py", line 76, in app
    await wrap_app_handling_exceptions(app, request)(scope, receive, send)
  File "C:\Users\Sobre\OneDrive\Desktop\Vroomble\.venv\Lib\site-packages\starlette\_exception_handler.py", line 59, in wrapped_app
    response = await handler(conn, exc)
               ^^^^^^^^^^^^^^^^^^^^^^^^
  File "C:\Users\Sobre\OneDrive\Desktop\Vroomble\src\APIs\vehicle_registration.py", line 172, in validation_exception_handler
    return JSONResponse(
           ^^^^^^^^^^^^^
  File "C:\Users\Sobre\OneDrive\Desktop\Vroomble\.venv\Lib\site-packages\starlette\responses.py", line 181, in __init__
    super().__init__(content, status_code, headers, media_type, background)
  File "C:\Users\Sobre\OneDrive\Desktop\Vroomble\.venv\Lib\site-packages\starlette\responses.py", line 44, in __init__
    self.body = self.render(content)
                ^^^^^^^^^^^^^^^^^^^^
  File "C:\Users\Sobre\OneDrive\Desktop\Vroomble\.venv\Lib\site-packages\starlette\responses.py", line 184, in render
    return json.dumps(
           ^^^^^^^^^^^
  File "C:\Program Files\WindowsApps\PythonSoftwareFoundation.Python.3.11_3.11.2544.0_x64__qbz5n2kfra8p0\Lib\json\__init__.py", line 238, in dumps
    **kw).encode(obj)
          ^^^^^^^^^^^
  File "C:\Program Files\WindowsApps\PythonSoftwareFoundation.Python.3.11_3.11.2544.0_x64__qbz5n2kfra8p0\Lib\json\encoder.py", line 200, in encode
    chunks = self.iterencode(o, _one_shot=True)
             ^^^^^^^^^^^^^^^^^^^^^^^^^^^^^^^^^^
  File "C:\Program Files\WindowsApps\PythonSoftwareFoundation.Python.3.11_3.11.2544.0_x64__qbz5n2kfra8p0\Lib\json\encoder.py", line 258, in iterencode
    return _iterencode(o, 0)
           ^^^^^^^^^^^^^^^^^
  File "C:\Program Files\WindowsApps\PythonSoftwareFoundation.Python.3.11_3.11.2544.0_x64__qbz5n2kfra8p0\Lib\json\encoder.py", line 180, in default
    raise TypeError(f'Object of type {o.__class__.__name__} '
TypeError: Object of type ValueError is not JSON serializable
2025-03-02 02:12:50,339 - ERROR - Validation error: [{'type': 'value_error', 'loc': ('body', 'year'), 'msg': 'Value error, Invalid year', 'input': 0, 'ctx': {'error': ValueError('Invalid year')}}, {'type': 'value_error', 'loc': ('body', 'retail_srp'), 'msg': 'Value error, Retail SRP must be positive', 'input': 0, 'ctx': {'error': ValueError('Retail SRP must be positive')}}]
2025-03-02 02:12:50,339 - ERROR - Unhandled exception: Object of type ValueError is not JSON serializable
Traceback (most recent call last):
  File "C:\Users\Sobre\OneDrive\Desktop\Vroomble\.venv\Lib\site-packages\starlette\_exception_handler.py", line 42, in wrapped_app
    await app(scope, receive, sender)
  File "C:\Users\Sobre\OneDrive\Desktop\Vroomble\.venv\Lib\site-packages\starlette\routing.py", line 73, in app
    response = await f(request)
               ^^^^^^^^^^^^^^^^
  File "C:\Users\Sobre\OneDrive\Desktop\Vroomble\.venv\Lib\site-packages\fastapi\routing.py", line 346, in app
    raise validation_error
fastapi.exceptions.RequestValidationError: [{'type': 'value_error', 'loc': ('body', 'year'), 'msg': 'Value error, Invalid year', 'input': 0, 'ctx': {'error': ValueError('Invalid year')}}, {'type': 'value_error', 'loc': ('body', 'retail_srp'), 'msg': 'Value error, Retail SRP must be positive', 'input': 0, 'ctx': {'error': ValueError('Retail SRP must be positive')}}]

During handling of the above exception, another exception occurred:

Traceback (most recent call last):
  File "C:\Users\Sobre\OneDrive\Desktop\Vroomble\.venv\Lib\site-packages\starlette\middleware\errors.py", line 165, in __call__
    await self.app(scope, receive, _send)
  File "C:\Users\Sobre\OneDrive\Desktop\Vroomble\.venv\Lib\site-packages\starlette\middleware\cors.py", line 93, in __call__
    await self.simple_response(scope, receive, send, request_headers=headers)
  File "C:\Users\Sobre\OneDrive\Desktop\Vroomble\.venv\Lib\site-packages\starlette\middleware\cors.py", line 144, in simple_response
    await self.app(scope, receive, send)
  File "C:\Users\Sobre\OneDrive\Desktop\Vroomble\.venv\Lib\site-packages\starlette\middleware\exceptions.py", line 62, in __call__
    await wrap_app_handling_exceptions(self.app, conn)(scope, receive, send)
  File "C:\Users\Sobre\OneDrive\Desktop\Vroomble\.venv\Lib\site-packages\starlette\_exception_handler.py", line 53, in wrapped_app
    raise exc
  File "C:\Users\Sobre\OneDrive\Desktop\Vroomble\.venv\Lib\site-packages\starlette\_exception_handler.py", line 42, in wrapped_app
    await app(scope, receive, sender)
  File "C:\Users\Sobre\OneDrive\Desktop\Vroomble\.venv\Lib\site-packages\starlette\routing.py", line 715, in __call__
    await self.middleware_stack(scope, receive, send)
  File "C:\Users\Sobre\OneDrive\Desktop\Vroomble\.venv\Lib\site-packages\starlette\routing.py", line 735, in app
    await route.handle(scope, receive, send)
  File "C:\Users\Sobre\OneDrive\Desktop\Vroomble\.venv\Lib\site-packages\starlette\routing.py", line 288, in handle
    await self.app(scope, receive, send)
  File "C:\Users\Sobre\OneDrive\Desktop\Vroomble\.venv\Lib\site-packages\starlette\routing.py", line 76, in app
    await wrap_app_handling_exceptions(app, request)(scope, receive, send)
  File "C:\Users\Sobre\OneDrive\Desktop\Vroomble\.venv\Lib\site-packages\starlette\_exception_handler.py", line 59, in wrapped_app
    response = await handler(conn, exc)
               ^^^^^^^^^^^^^^^^^^^^^^^^
  File "C:\Users\Sobre\OneDrive\Desktop\Vroomble\src\APIs\vehicle_registration.py", line 172, in validation_exception_handler
    return JSONResponse(
           ^^^^^^^^^^^^^
  File "C:\Users\Sobre\OneDrive\Desktop\Vroomble\.venv\Lib\site-packages\starlette\responses.py", line 181, in __init__
    super().__init__(content, status_code, headers, media_type, background)
  File "C:\Users\Sobre\OneDrive\Desktop\Vroomble\.venv\Lib\site-packages\starlette\responses.py", line 44, in __init__
    self.body = self.render(content)
                ^^^^^^^^^^^^^^^^^^^^
  File "C:\Users\Sobre\OneDrive\Desktop\Vroomble\.venv\Lib\site-packages\starlette\responses.py", line 184, in render
    return json.dumps(
           ^^^^^^^^^^^
  File "C:\Program Files\WindowsApps\PythonSoftwareFoundation.Python.3.11_3.11.2544.0_x64__qbz5n2kfra8p0\Lib\json\__init__.py", line 238, in dumps
    **kw).encode(obj)
          ^^^^^^^^^^^
  File "C:\Program Files\WindowsApps\PythonSoftwareFoundation.Python.3.11_3.11.2544.0_x64__qbz5n2kfra8p0\Lib\json\encoder.py", line 200, in encode
    chunks = self.iterencode(o, _one_shot=True)
             ^^^^^^^^^^^^^^^^^^^^^^^^^^^^^^^^^^
  File "C:\Program Files\WindowsApps\PythonSoftwareFoundation.Python.3.11_3.11.2544.0_x64__qbz5n2kfra8p0\Lib\json\encoder.py", line 258, in iterencode
    return _iterencode(o, 0)
           ^^^^^^^^^^^^^^^^^
  File "C:\Program Files\WindowsApps\PythonSoftwareFoundation.Python.3.11_3.11.2544.0_x64__qbz5n2kfra8p0\Lib\json\encoder.py", line 180, in default
    raise TypeError(f'Object of type {o.__class__.__name__} '
TypeError: Object of type ValueError is not JSON serializable
2025-03-02 02:12:54,203 - ERROR - Validation error: [{'type': 'value_error', 'loc': ('body', 'year'), 'msg': 'Value error, Invalid year', 'input': 0, 'ctx': {'error': ValueError('Invalid year')}}, {'type': 'value_error', 'loc': ('body', 'retail_srp'), 'msg': 'Value error, Retail SRP must be positive', 'input': 0, 'ctx': {'error': ValueError('Retail SRP must be positive')}}]
2025-03-02 02:12:54,203 - ERROR - Unhandled exception: Object of type ValueError is not JSON serializable
Traceback (most recent call last):
  File "C:\Users\Sobre\OneDrive\Desktop\Vroomble\.venv\Lib\site-packages\starlette\_exception_handler.py", line 42, in wrapped_app
    await app(scope, receive, sender)
  File "C:\Users\Sobre\OneDrive\Desktop\Vroomble\.venv\Lib\site-packages\starlette\routing.py", line 73, in app
    response = await f(request)
               ^^^^^^^^^^^^^^^^
  File "C:\Users\Sobre\OneDrive\Desktop\Vroomble\.venv\Lib\site-packages\fastapi\routing.py", line 346, in app
    raise validation_error
fastapi.exceptions.RequestValidationError: [{'type': 'value_error', 'loc': ('body', 'year'), 'msg': 'Value error, Invalid year', 'input': 0, 'ctx': {'error': ValueError('Invalid year')}}, {'type': 'value_error', 'loc': ('body', 'retail_srp'), 'msg': 'Value error, Retail SRP must be positive', 'input': 0, 'ctx': {'error': ValueError('Retail SRP must be positive')}}]

During handling of the above exception, another exception occurred:

Traceback (most recent call last):
  File "C:\Users\Sobre\OneDrive\Desktop\Vroomble\.venv\Lib\site-packages\starlette\middleware\errors.py", line 165, in __call__
    await self.app(scope, receive, _send)
  File "C:\Users\Sobre\OneDrive\Desktop\Vroomble\.venv\Lib\site-packages\starlette\middleware\cors.py", line 93, in __call__
    await self.simple_response(scope, receive, send, request_headers=headers)
  File "C:\Users\Sobre\OneDrive\Desktop\Vroomble\.venv\Lib\site-packages\starlette\middleware\cors.py", line 144, in simple_response
    await self.app(scope, receive, send)
  File "C:\Users\Sobre\OneDrive\Desktop\Vroomble\.venv\Lib\site-packages\starlette\middleware\exceptions.py", line 62, in __call__
    await wrap_app_handling_exceptions(self.app, conn)(scope, receive, send)
  File "C:\Users\Sobre\OneDrive\Desktop\Vroomble\.venv\Lib\site-packages\starlette\_exception_handler.py", line 53, in wrapped_app
    raise exc
  File "C:\Users\Sobre\OneDrive\Desktop\Vroomble\.venv\Lib\site-packages\starlette\_exception_handler.py", line 42, in wrapped_app
    await app(scope, receive, sender)
  File "C:\Users\Sobre\OneDrive\Desktop\Vroomble\.venv\Lib\site-packages\starlette\routing.py", line 715, in __call__
    await self.middleware_stack(scope, receive, send)
  File "C:\Users\Sobre\OneDrive\Desktop\Vroomble\.venv\Lib\site-packages\starlette\routing.py", line 735, in app
    await route.handle(scope, receive, send)
  File "C:\Users\Sobre\OneDrive\Desktop\Vroomble\.venv\Lib\site-packages\starlette\routing.py", line 288, in handle
    await self.app(scope, receive, send)
  File "C:\Users\Sobre\OneDrive\Desktop\Vroomble\.venv\Lib\site-packages\starlette\routing.py", line 76, in app
    await wrap_app_handling_exceptions(app, request)(scope, receive, send)
  File "C:\Users\Sobre\OneDrive\Desktop\Vroomble\.venv\Lib\site-packages\starlette\_exception_handler.py", line 59, in wrapped_app
    response = await handler(conn, exc)
               ^^^^^^^^^^^^^^^^^^^^^^^^
  File "C:\Users\Sobre\OneDrive\Desktop\Vroomble\src\APIs\vehicle_registration.py", line 172, in validation_exception_handler
    return JSONResponse(
           ^^^^^^^^^^^^^
  File "C:\Users\Sobre\OneDrive\Desktop\Vroomble\.venv\Lib\site-packages\starlette\responses.py", line 181, in __init__
    super().__init__(content, status_code, headers, media_type, background)
  File "C:\Users\Sobre\OneDrive\Desktop\Vroomble\.venv\Lib\site-packages\starlette\responses.py", line 44, in __init__
    self.body = self.render(content)
                ^^^^^^^^^^^^^^^^^^^^
  File "C:\Users\Sobre\OneDrive\Desktop\Vroomble\.venv\Lib\site-packages\starlette\responses.py", line 184, in render
    return json.dumps(
           ^^^^^^^^^^^
  File "C:\Program Files\WindowsApps\PythonSoftwareFoundation.Python.3.11_3.11.2544.0_x64__qbz5n2kfra8p0\Lib\json\__init__.py", line 238, in dumps
    **kw).encode(obj)
          ^^^^^^^^^^^
  File "C:\Program Files\WindowsApps\PythonSoftwareFoundation.Python.3.11_3.11.2544.0_x64__qbz5n2kfra8p0\Lib\json\encoder.py", line 200, in encode
    chunks = self.iterencode(o, _one_shot=True)
             ^^^^^^^^^^^^^^^^^^^^^^^^^^^^^^^^^^
  File "C:\Program Files\WindowsApps\PythonSoftwareFoundation.Python.3.11_3.11.2544.0_x64__qbz5n2kfra8p0\Lib\json\encoder.py", line 258, in iterencode
    return _iterencode(o, 0)
           ^^^^^^^^^^^^^^^^^
  File "C:\Program Files\WindowsApps\PythonSoftwareFoundation.Python.3.11_3.11.2544.0_x64__qbz5n2kfra8p0\Lib\json\encoder.py", line 180, in default
    raise TypeError(f'Object of type {o.__class__.__name__} '
TypeError: Object of type ValueError is not JSON serializable
2025-03-02 02:12:56,907 - ERROR - Validation error: [{'type': 'value_error', 'loc': ('body', 'year'), 'msg': 'Value error, Invalid year', 'input': 0, 'ctx': {'error': ValueError('Invalid year')}}, {'type': 'value_error', 'loc': ('body', 'retail_srp'), 'msg': 'Value error, Retail SRP must be positive', 'input': 0, 'ctx': {'error': ValueError('Retail SRP must be positive')}}]
2025-03-02 02:12:56,907 - ERROR - Unhandled exception: Object of type ValueError is not JSON serializable
Traceback (most recent call last):
  File "C:\Users\Sobre\OneDrive\Desktop\Vroomble\.venv\Lib\site-packages\starlette\_exception_handler.py", line 42, in wrapped_app
    await app(scope, receive, sender)
  File "C:\Users\Sobre\OneDrive\Desktop\Vroomble\.venv\Lib\site-packages\starlette\routing.py", line 73, in app
    response = await f(request)
               ^^^^^^^^^^^^^^^^
  File "C:\Users\Sobre\OneDrive\Desktop\Vroomble\.venv\Lib\site-packages\fastapi\routing.py", line 346, in app
    raise validation_error
fastapi.exceptions.RequestValidationError: [{'type': 'value_error', 'loc': ('body', 'year'), 'msg': 'Value error, Invalid year', 'input': 0, 'ctx': {'error': ValueError('Invalid year')}}, {'type': 'value_error', 'loc': ('body', 'retail_srp'), 'msg': 'Value error, Retail SRP must be positive', 'input': 0, 'ctx': {'error': ValueError('Retail SRP must be positive')}}]

During handling of the above exception, another exception occurred:

Traceback (most recent call last):
  File "C:\Users\Sobre\OneDrive\Desktop\Vroomble\.venv\Lib\site-packages\starlette\middleware\errors.py", line 165, in __call__
    await self.app(scope, receive, _send)
  File "C:\Users\Sobre\OneDrive\Desktop\Vroomble\.venv\Lib\site-packages\starlette\middleware\cors.py", line 93, in __call__
    await self.simple_response(scope, receive, send, request_headers=headers)
  File "C:\Users\Sobre\OneDrive\Desktop\Vroomble\.venv\Lib\site-packages\starlette\middleware\cors.py", line 144, in simple_response
    await self.app(scope, receive, send)
  File "C:\Users\Sobre\OneDrive\Desktop\Vroomble\.venv\Lib\site-packages\starlette\middleware\exceptions.py", line 62, in __call__
    await wrap_app_handling_exceptions(self.app, conn)(scope, receive, send)
  File "C:\Users\Sobre\OneDrive\Desktop\Vroomble\.venv\Lib\site-packages\starlette\_exception_handler.py", line 53, in wrapped_app
    raise exc
  File "C:\Users\Sobre\OneDrive\Desktop\Vroomble\.venv\Lib\site-packages\starlette\_exception_handler.py", line 42, in wrapped_app
    await app(scope, receive, sender)
  File "C:\Users\Sobre\OneDrive\Desktop\Vroomble\.venv\Lib\site-packages\starlette\routing.py", line 715, in __call__
    await self.middleware_stack(scope, receive, send)
  File "C:\Users\Sobre\OneDrive\Desktop\Vroomble\.venv\Lib\site-packages\starlette\routing.py", line 735, in app
    await route.handle(scope, receive, send)
  File "C:\Users\Sobre\OneDrive\Desktop\Vroomble\.venv\Lib\site-packages\starlette\routing.py", line 288, in handle
    await self.app(scope, receive, send)
  File "C:\Users\Sobre\OneDrive\Desktop\Vroomble\.venv\Lib\site-packages\starlette\routing.py", line 76, in app
    await wrap_app_handling_exceptions(app, request)(scope, receive, send)
  File "C:\Users\Sobre\OneDrive\Desktop\Vroomble\.venv\Lib\site-packages\starlette\_exception_handler.py", line 59, in wrapped_app
    response = await handler(conn, exc)
               ^^^^^^^^^^^^^^^^^^^^^^^^
  File "C:\Users\Sobre\OneDrive\Desktop\Vroomble\src\APIs\vehicle_registration.py", line 172, in validation_exception_handler
    return JSONResponse(
           ^^^^^^^^^^^^^
  File "C:\Users\Sobre\OneDrive\Desktop\Vroomble\.venv\Lib\site-packages\starlette\responses.py", line 181, in __init__
    super().__init__(content, status_code, headers, media_type, background)
  File "C:\Users\Sobre\OneDrive\Desktop\Vroomble\.venv\Lib\site-packages\starlette\responses.py", line 44, in __init__
    self.body = self.render(content)
                ^^^^^^^^^^^^^^^^^^^^
  File "C:\Users\Sobre\OneDrive\Desktop\Vroomble\.venv\Lib\site-packages\starlette\responses.py", line 184, in render
    return json.dumps(
           ^^^^^^^^^^^
  File "C:\Program Files\WindowsApps\PythonSoftwareFoundation.Python.3.11_3.11.2544.0_x64__qbz5n2kfra8p0\Lib\json\__init__.py", line 238, in dumps
    **kw).encode(obj)
          ^^^^^^^^^^^
  File "C:\Program Files\WindowsApps\PythonSoftwareFoundation.Python.3.11_3.11.2544.0_x64__qbz5n2kfra8p0\Lib\json\encoder.py", line 200, in encode
    chunks = self.iterencode(o, _one_shot=True)
             ^^^^^^^^^^^^^^^^^^^^^^^^^^^^^^^^^^
  File "C:\Program Files\WindowsApps\PythonSoftwareFoundation.Python.3.11_3.11.2544.0_x64__qbz5n2kfra8p0\Lib\json\encoder.py", line 258, in iterencode
    return _iterencode(o, 0)
           ^^^^^^^^^^^^^^^^^
  File "C:\Program Files\WindowsApps\PythonSoftwareFoundation.Python.3.11_3.11.2544.0_x64__qbz5n2kfra8p0\Lib\json\encoder.py", line 180, in default
    raise TypeError(f'Object of type {o.__class__.__name__} '
TypeError: Object of type ValueError is not JSON serializable
2025-03-02 02:12:59,774 - ERROR - Validation error: [{'type': 'value_error', 'loc': ('body', 'year'), 'msg': 'Value error, Invalid year', 'input': 0, 'ctx': {'error': ValueError('Invalid year')}}, {'type': 'value_error', 'loc': ('body', 'retail_srp'), 'msg': 'Value error, Retail SRP must be positive', 'input': 0, 'ctx': {'error': ValueError('Retail SRP must be positive')}}]
2025-03-02 02:12:59,774 - ERROR - Unhandled exception: Object of type ValueError is not JSON serializable
Traceback (most recent call last):
  File "C:\Users\Sobre\OneDrive\Desktop\Vroomble\.venv\Lib\site-packages\starlette\_exception_handler.py", line 42, in wrapped_app
    await app(scope, receive, sender)
  File "C:\Users\Sobre\OneDrive\Desktop\Vroomble\.venv\Lib\site-packages\starlette\routing.py", line 73, in app
    response = await f(request)
               ^^^^^^^^^^^^^^^^
  File "C:\Users\Sobre\OneDrive\Desktop\Vroomble\.venv\Lib\site-packages\fastapi\routing.py", line 346, in app
    raise validation_error
fastapi.exceptions.RequestValidationError: [{'type': 'value_error', 'loc': ('body', 'year'), 'msg': 'Value error, Invalid year', 'input': 0, 'ctx': {'error': ValueError('Invalid year')}}, {'type': 'value_error', 'loc': ('body', 'retail_srp'), 'msg': 'Value error, Retail SRP must be positive', 'input': 0, 'ctx': {'error': ValueError('Retail SRP must be positive')}}]

During handling of the above exception, another exception occurred:

Traceback (most recent call last):
  File "C:\Users\Sobre\OneDrive\Desktop\Vroomble\.venv\Lib\site-packages\starlette\middleware\errors.py", line 165, in __call__
    await self.app(scope, receive, _send)
  File "C:\Users\Sobre\OneDrive\Desktop\Vroomble\.venv\Lib\site-packages\starlette\middleware\cors.py", line 93, in __call__
    await self.simple_response(scope, receive, send, request_headers=headers)
  File "C:\Users\Sobre\OneDrive\Desktop\Vroomble\.venv\Lib\site-packages\starlette\middleware\cors.py", line 144, in simple_response
    await self.app(scope, receive, send)
  File "C:\Users\Sobre\OneDrive\Desktop\Vroomble\.venv\Lib\site-packages\starlette\middleware\exceptions.py", line 62, in __call__
    await wrap_app_handling_exceptions(self.app, conn)(scope, receive, send)
  File "C:\Users\Sobre\OneDrive\Desktop\Vroomble\.venv\Lib\site-packages\starlette\_exception_handler.py", line 53, in wrapped_app
    raise exc
  File "C:\Users\Sobre\OneDrive\Desktop\Vroomble\.venv\Lib\site-packages\starlette\_exception_handler.py", line 42, in wrapped_app
    await app(scope, receive, sender)
  File "C:\Users\Sobre\OneDrive\Desktop\Vroomble\.venv\Lib\site-packages\starlette\routing.py", line 715, in __call__
    await self.middleware_stack(scope, receive, send)
  File "C:\Users\Sobre\OneDrive\Desktop\Vroomble\.venv\Lib\site-packages\starlette\routing.py", line 735, in app
    await route.handle(scope, receive, send)
  File "C:\Users\Sobre\OneDrive\Desktop\Vroomble\.venv\Lib\site-packages\starlette\routing.py", line 288, in handle
    await self.app(scope, receive, send)
  File "C:\Users\Sobre\OneDrive\Desktop\Vroomble\.venv\Lib\site-packages\starlette\routing.py", line 76, in app
    await wrap_app_handling_exceptions(app, request)(scope, receive, send)
  File "C:\Users\Sobre\OneDrive\Desktop\Vroomble\.venv\Lib\site-packages\starlette\_exception_handler.py", line 59, in wrapped_app
    response = await handler(conn, exc)
               ^^^^^^^^^^^^^^^^^^^^^^^^
  File "C:\Users\Sobre\OneDrive\Desktop\Vroomble\src\APIs\vehicle_registration.py", line 172, in validation_exception_handler
    return JSONResponse(
           ^^^^^^^^^^^^^
  File "C:\Users\Sobre\OneDrive\Desktop\Vroomble\.venv\Lib\site-packages\starlette\responses.py", line 181, in __init__
    super().__init__(content, status_code, headers, media_type, background)
  File "C:\Users\Sobre\OneDrive\Desktop\Vroomble\.venv\Lib\site-packages\starlette\responses.py", line 44, in __init__
    self.body = self.render(content)
                ^^^^^^^^^^^^^^^^^^^^
  File "C:\Users\Sobre\OneDrive\Desktop\Vroomble\.venv\Lib\site-packages\starlette\responses.py", line 184, in render
    return json.dumps(
           ^^^^^^^^^^^
  File "C:\Program Files\WindowsApps\PythonSoftwareFoundation.Python.3.11_3.11.2544.0_x64__qbz5n2kfra8p0\Lib\json\__init__.py", line 238, in dumps
    **kw).encode(obj)
          ^^^^^^^^^^^
  File "C:\Program Files\WindowsApps\PythonSoftwareFoundation.Python.3.11_3.11.2544.0_x64__qbz5n2kfra8p0\Lib\json\encoder.py", line 200, in encode
    chunks = self.iterencode(o, _one_shot=True)
             ^^^^^^^^^^^^^^^^^^^^^^^^^^^^^^^^^^
  File "C:\Program Files\WindowsApps\PythonSoftwareFoundation.Python.3.11_3.11.2544.0_x64__qbz5n2kfra8p0\Lib\json\encoder.py", line 258, in iterencode
    return _iterencode(o, 0)
           ^^^^^^^^^^^^^^^^^
  File "C:\Program Files\WindowsApps\PythonSoftwareFoundation.Python.3.11_3.11.2544.0_x64__qbz5n2kfra8p0\Lib\json\encoder.py", line 180, in default
    raise TypeError(f'Object of type {o.__class__.__name__} '
TypeError: Object of type ValueError is not JSON serializable
2025-03-02 02:13:02,454 - ERROR - Validation error: [{'type': 'value_error', 'loc': ('body', 'year'), 'msg': 'Value error, Invalid year', 'input': 0, 'ctx': {'error': ValueError('Invalid year')}}, {'type': 'value_error', 'loc': ('body', 'retail_srp'), 'msg': 'Value error, Retail SRP must be positive', 'input': 0, 'ctx': {'error': ValueError('Retail SRP must be positive')}}]
2025-03-02 02:13:02,454 - ERROR - Unhandled exception: Object of type ValueError is not JSON serializable
Traceback (most recent call last):
  File "C:\Users\Sobre\OneDrive\Desktop\Vroomble\.venv\Lib\site-packages\starlette\_exception_handler.py", line 42, in wrapped_app
    await app(scope, receive, sender)
  File "C:\Users\Sobre\OneDrive\Desktop\Vroomble\.venv\Lib\site-packages\starlette\routing.py", line 73, in app
    response = await f(request)
               ^^^^^^^^^^^^^^^^
  File "C:\Users\Sobre\OneDrive\Desktop\Vroomble\.venv\Lib\site-packages\fastapi\routing.py", line 346, in app
    raise validation_error
fastapi.exceptions.RequestValidationError: [{'type': 'value_error', 'loc': ('body', 'year'), 'msg': 'Value error, Invalid year', 'input': 0, 'ctx': {'error': ValueError('Invalid year')}}, {'type': 'value_error', 'loc': ('body', 'retail_srp'), 'msg': 'Value error, Retail SRP must be positive', 'input': 0, 'ctx': {'error': ValueError('Retail SRP must be positive')}}]

During handling of the above exception, another exception occurred:

Traceback (most recent call last):
  File "C:\Users\Sobre\OneDrive\Desktop\Vroomble\.venv\Lib\site-packages\starlette\middleware\errors.py", line 165, in __call__
    await self.app(scope, receive, _send)
  File "C:\Users\Sobre\OneDrive\Desktop\Vroomble\.venv\Lib\site-packages\starlette\middleware\cors.py", line 93, in __call__
    await self.simple_response(scope, receive, send, request_headers=headers)
  File "C:\Users\Sobre\OneDrive\Desktop\Vroomble\.venv\Lib\site-packages\starlette\middleware\cors.py", line 144, in simple_response
    await self.app(scope, receive, send)
  File "C:\Users\Sobre\OneDrive\Desktop\Vroomble\.venv\Lib\site-packages\starlette\middleware\exceptions.py", line 62, in __call__
    await wrap_app_handling_exceptions(self.app, conn)(scope, receive, send)
  File "C:\Users\Sobre\OneDrive\Desktop\Vroomble\.venv\Lib\site-packages\starlette\_exception_handler.py", line 53, in wrapped_app
    raise exc
  File "C:\Users\Sobre\OneDrive\Desktop\Vroomble\.venv\Lib\site-packages\starlette\_exception_handler.py", line 42, in wrapped_app
    await app(scope, receive, sender)
  File "C:\Users\Sobre\OneDrive\Desktop\Vroomble\.venv\Lib\site-packages\starlette\routing.py", line 715, in __call__
    await self.middleware_stack(scope, receive, send)
  File "C:\Users\Sobre\OneDrive\Desktop\Vroomble\.venv\Lib\site-packages\starlette\routing.py", line 735, in app
    await route.handle(scope, receive, send)
  File "C:\Users\Sobre\OneDrive\Desktop\Vroomble\.venv\Lib\site-packages\starlette\routing.py", line 288, in handle
    await self.app(scope, receive, send)
  File "C:\Users\Sobre\OneDrive\Desktop\Vroomble\.venv\Lib\site-packages\starlette\routing.py", line 76, in app
    await wrap_app_handling_exceptions(app, request)(scope, receive, send)
  File "C:\Users\Sobre\OneDrive\Desktop\Vroomble\.venv\Lib\site-packages\starlette\_exception_handler.py", line 59, in wrapped_app
    response = await handler(conn, exc)
               ^^^^^^^^^^^^^^^^^^^^^^^^
  File "C:\Users\Sobre\OneDrive\Desktop\Vroomble\src\APIs\vehicle_registration.py", line 172, in validation_exception_handler
    return JSONResponse(
           ^^^^^^^^^^^^^
  File "C:\Users\Sobre\OneDrive\Desktop\Vroomble\.venv\Lib\site-packages\starlette\responses.py", line 181, in __init__
    super().__init__(content, status_code, headers, media_type, background)
  File "C:\Users\Sobre\OneDrive\Desktop\Vroomble\.venv\Lib\site-packages\starlette\responses.py", line 44, in __init__
    self.body = self.render(content)
                ^^^^^^^^^^^^^^^^^^^^
  File "C:\Users\Sobre\OneDrive\Desktop\Vroomble\.venv\Lib\site-packages\starlette\responses.py", line 184, in render
    return json.dumps(
           ^^^^^^^^^^^
  File "C:\Program Files\WindowsApps\PythonSoftwareFoundation.Python.3.11_3.11.2544.0_x64__qbz5n2kfra8p0\Lib\json\__init__.py", line 238, in dumps
    **kw).encode(obj)
          ^^^^^^^^^^^
  File "C:\Program Files\WindowsApps\PythonSoftwareFoundation.Python.3.11_3.11.2544.0_x64__qbz5n2kfra8p0\Lib\json\encoder.py", line 200, in encode
    chunks = self.iterencode(o, _one_shot=True)
             ^^^^^^^^^^^^^^^^^^^^^^^^^^^^^^^^^^
  File "C:\Program Files\WindowsApps\PythonSoftwareFoundation.Python.3.11_3.11.2544.0_x64__qbz5n2kfra8p0\Lib\json\encoder.py", line 258, in iterencode
    return _iterencode(o, 0)
           ^^^^^^^^^^^^^^^^^
  File "C:\Program Files\WindowsApps\PythonSoftwareFoundation.Python.3.11_3.11.2544.0_x64__qbz5n2kfra8p0\Lib\json\encoder.py", line 180, in default
    raise TypeError(f'Object of type {o.__class__.__name__} '
TypeError: Object of type ValueError is not JSON serializable
2025-03-02 02:13:48,125 - ERROR - Validation error: [{'type': 'value_error', 'loc': ('body', 'year'), 'msg': 'Value error, Invalid year', 'input': 0, 'ctx': {'error': ValueError('Invalid year')}}, {'type': 'value_error', 'loc': ('body', 'retail_srp'), 'msg': 'Value error, Retail SRP must be positive', 'input': 0, 'ctx': {'error': ValueError('Retail SRP must be positive')}}]
2025-03-02 02:13:48,125 - ERROR - Unhandled exception: Object of type ValueError is not JSON serializable
Traceback (most recent call last):
  File "C:\Users\Sobre\OneDrive\Desktop\Vroomble\.venv\Lib\site-packages\starlette\_exception_handler.py", line 42, in wrapped_app
    await app(scope, receive, sender)
  File "C:\Users\Sobre\OneDrive\Desktop\Vroomble\.venv\Lib\site-packages\starlette\routing.py", line 73, in app
    response = await f(request)
               ^^^^^^^^^^^^^^^^
  File "C:\Users\Sobre\OneDrive\Desktop\Vroomble\.venv\Lib\site-packages\fastapi\routing.py", line 346, in app
    raise validation_error
fastapi.exceptions.RequestValidationError: [{'type': 'value_error', 'loc': ('body', 'year'), 'msg': 'Value error, Invalid year', 'input': 0, 'ctx': {'error': ValueError('Invalid year')}}, {'type': 'value_error', 'loc': ('body', 'retail_srp'), 'msg': 'Value error, Retail SRP must be positive', 'input': 0, 'ctx': {'error': ValueError('Retail SRP must be positive')}}]

During handling of the above exception, another exception occurred:

Traceback (most recent call last):
  File "C:\Users\Sobre\OneDrive\Desktop\Vroomble\.venv\Lib\site-packages\starlette\middleware\errors.py", line 165, in __call__
    await self.app(scope, receive, _send)
  File "C:\Users\Sobre\OneDrive\Desktop\Vroomble\.venv\Lib\site-packages\starlette\middleware\cors.py", line 93, in __call__
    await self.simple_response(scope, receive, send, request_headers=headers)
  File "C:\Users\Sobre\OneDrive\Desktop\Vroomble\.venv\Lib\site-packages\starlette\middleware\cors.py", line 144, in simple_response
    await self.app(scope, receive, send)
  File "C:\Users\Sobre\OneDrive\Desktop\Vroomble\.venv\Lib\site-packages\starlette\middleware\exceptions.py", line 62, in __call__
    await wrap_app_handling_exceptions(self.app, conn)(scope, receive, send)
  File "C:\Users\Sobre\OneDrive\Desktop\Vroomble\.venv\Lib\site-packages\starlette\_exception_handler.py", line 53, in wrapped_app
    raise exc
  File "C:\Users\Sobre\OneDrive\Desktop\Vroomble\.venv\Lib\site-packages\starlette\_exception_handler.py", line 42, in wrapped_app
    await app(scope, receive, sender)
  File "C:\Users\Sobre\OneDrive\Desktop\Vroomble\.venv\Lib\site-packages\starlette\routing.py", line 715, in __call__
    await self.middleware_stack(scope, receive, send)
  File "C:\Users\Sobre\OneDrive\Desktop\Vroomble\.venv\Lib\site-packages\starlette\routing.py", line 735, in app
    await route.handle(scope, receive, send)
  File "C:\Users\Sobre\OneDrive\Desktop\Vroomble\.venv\Lib\site-packages\starlette\routing.py", line 288, in handle
    await self.app(scope, receive, send)
  File "C:\Users\Sobre\OneDrive\Desktop\Vroomble\.venv\Lib\site-packages\starlette\routing.py", line 76, in app
    await wrap_app_handling_exceptions(app, request)(scope, receive, send)
  File "C:\Users\Sobre\OneDrive\Desktop\Vroomble\.venv\Lib\site-packages\starlette\_exception_handler.py", line 59, in wrapped_app
    response = await handler(conn, exc)
               ^^^^^^^^^^^^^^^^^^^^^^^^
  File "C:\Users\Sobre\OneDrive\Desktop\Vroomble\src\APIs\vehicle_registration.py", line 172, in validation_exception_handler
    return JSONResponse(
           ^^^^^^^^^^^^^
  File "C:\Users\Sobre\OneDrive\Desktop\Vroomble\.venv\Lib\site-packages\starlette\responses.py", line 181, in __init__
    super().__init__(content, status_code, headers, media_type, background)
  File "C:\Users\Sobre\OneDrive\Desktop\Vroomble\.venv\Lib\site-packages\starlette\responses.py", line 44, in __init__
    self.body = self.render(content)
                ^^^^^^^^^^^^^^^^^^^^
  File "C:\Users\Sobre\OneDrive\Desktop\Vroomble\.venv\Lib\site-packages\starlette\responses.py", line 184, in render
    return json.dumps(
           ^^^^^^^^^^^
  File "C:\Program Files\WindowsApps\PythonSoftwareFoundation.Python.3.11_3.11.2544.0_x64__qbz5n2kfra8p0\Lib\json\__init__.py", line 238, in dumps
    **kw).encode(obj)
          ^^^^^^^^^^^
  File "C:\Program Files\WindowsApps\PythonSoftwareFoundation.Python.3.11_3.11.2544.0_x64__qbz5n2kfra8p0\Lib\json\encoder.py", line 200, in encode
    chunks = self.iterencode(o, _one_shot=True)
             ^^^^^^^^^^^^^^^^^^^^^^^^^^^^^^^^^^
  File "C:\Program Files\WindowsApps\PythonSoftwareFoundation.Python.3.11_3.11.2544.0_x64__qbz5n2kfra8p0\Lib\json\encoder.py", line 258, in iterencode
    return _iterencode(o, 0)
           ^^^^^^^^^^^^^^^^^
  File "C:\Program Files\WindowsApps\PythonSoftwareFoundation.Python.3.11_3.11.2544.0_x64__qbz5n2kfra8p0\Lib\json\encoder.py", line 180, in default
    raise TypeError(f'Object of type {o.__class__.__name__} '
TypeError: Object of type ValueError is not JSON serializable
2025-03-02 02:17:22,284 - INFO - Database table created or already exists.
2025-03-02 02:17:35,022 - ERROR - Validation error: [{'type': 'value_error', 'loc': ('body', 'year'), 'msg': 'Value error, Invalid year', 'input': 0, 'ctx': {'error': ValueError('Invalid year')}}, {'type': 'value_error', 'loc': ('body', 'retail_srp'), 'msg': 'Value error, Retail SRP must be positive', 'input': 0, 'ctx': {'error': ValueError('Retail SRP must be positive')}}]
2025-03-02 02:17:35,022 - ERROR - Unhandled exception: Object of type ValueError is not JSON serializable
Traceback (most recent call last):
  File "C:\Users\Sobre\OneDrive\Desktop\Vroomble\.venv\Lib\site-packages\starlette\_exception_handler.py", line 42, in wrapped_app
    await app(scope, receive, sender)
  File "C:\Users\Sobre\OneDrive\Desktop\Vroomble\.venv\Lib\site-packages\starlette\routing.py", line 73, in app
    response = await f(request)
               ^^^^^^^^^^^^^^^^
  File "C:\Users\Sobre\OneDrive\Desktop\Vroomble\.venv\Lib\site-packages\fastapi\routing.py", line 346, in app
    raise validation_error
fastapi.exceptions.RequestValidationError: [{'type': 'value_error', 'loc': ('body', 'year'), 'msg': 'Value error, Invalid year', 'input': 0, 'ctx': {'error': ValueError('Invalid year')}}, {'type': 'value_error', 'loc': ('body', 'retail_srp'), 'msg': 'Value error, Retail SRP must be positive', 'input': 0, 'ctx': {'error': ValueError('Retail SRP must be positive')}}]

During handling of the above exception, another exception occurred:

Traceback (most recent call last):
  File "C:\Users\Sobre\OneDrive\Desktop\Vroomble\.venv\Lib\site-packages\starlette\middleware\errors.py", line 165, in __call__
    await self.app(scope, receive, _send)
  File "C:\Users\Sobre\OneDrive\Desktop\Vroomble\.venv\Lib\site-packages\starlette\middleware\cors.py", line 93, in __call__
    await self.simple_response(scope, receive, send, request_headers=headers)
  File "C:\Users\Sobre\OneDrive\Desktop\Vroomble\.venv\Lib\site-packages\starlette\middleware\cors.py", line 144, in simple_response
    await self.app(scope, receive, send)
  File "C:\Users\Sobre\OneDrive\Desktop\Vroomble\.venv\Lib\site-packages\starlette\middleware\exceptions.py", line 62, in __call__
    await wrap_app_handling_exceptions(self.app, conn)(scope, receive, send)
  File "C:\Users\Sobre\OneDrive\Desktop\Vroomble\.venv\Lib\site-packages\starlette\_exception_handler.py", line 53, in wrapped_app
    raise exc
  File "C:\Users\Sobre\OneDrive\Desktop\Vroomble\.venv\Lib\site-packages\starlette\_exception_handler.py", line 42, in wrapped_app
    await app(scope, receive, sender)
  File "C:\Users\Sobre\OneDrive\Desktop\Vroomble\.venv\Lib\site-packages\starlette\routing.py", line 715, in __call__
    await self.middleware_stack(scope, receive, send)
  File "C:\Users\Sobre\OneDrive\Desktop\Vroomble\.venv\Lib\site-packages\starlette\routing.py", line 735, in app
    await route.handle(scope, receive, send)
  File "C:\Users\Sobre\OneDrive\Desktop\Vroomble\.venv\Lib\site-packages\starlette\routing.py", line 288, in handle
    await self.app(scope, receive, send)
  File "C:\Users\Sobre\OneDrive\Desktop\Vroomble\.venv\Lib\site-packages\starlette\routing.py", line 76, in app
    await wrap_app_handling_exceptions(app, request)(scope, receive, send)
  File "C:\Users\Sobre\OneDrive\Desktop\Vroomble\.venv\Lib\site-packages\starlette\_exception_handler.py", line 59, in wrapped_app
    response = await handler(conn, exc)
               ^^^^^^^^^^^^^^^^^^^^^^^^
  File "C:\Users\Sobre\OneDrive\Desktop\Vroomble\src\APIs\vehicle_registration.py", line 172, in validation_exception_handler
    return JSONResponse(
           ^^^^^^^^^^^^^
  File "C:\Users\Sobre\OneDrive\Desktop\Vroomble\.venv\Lib\site-packages\starlette\responses.py", line 181, in __init__
    super().__init__(content, status_code, headers, media_type, background)
  File "C:\Users\Sobre\OneDrive\Desktop\Vroomble\.venv\Lib\site-packages\starlette\responses.py", line 44, in __init__
    self.body = self.render(content)
                ^^^^^^^^^^^^^^^^^^^^
  File "C:\Users\Sobre\OneDrive\Desktop\Vroomble\.venv\Lib\site-packages\starlette\responses.py", line 184, in render
    return json.dumps(
           ^^^^^^^^^^^
  File "C:\Program Files\WindowsApps\PythonSoftwareFoundation.Python.3.11_3.11.2544.0_x64__qbz5n2kfra8p0\Lib\json\__init__.py", line 238, in dumps
    **kw).encode(obj)
          ^^^^^^^^^^^
  File "C:\Program Files\WindowsApps\PythonSoftwareFoundation.Python.3.11_3.11.2544.0_x64__qbz5n2kfra8p0\Lib\json\encoder.py", line 200, in encode
    chunks = self.iterencode(o, _one_shot=True)
             ^^^^^^^^^^^^^^^^^^^^^^^^^^^^^^^^^^
  File "C:\Program Files\WindowsApps\PythonSoftwareFoundation.Python.3.11_3.11.2544.0_x64__qbz5n2kfra8p0\Lib\json\encoder.py", line 258, in iterencode
    return _iterencode(o, 0)
           ^^^^^^^^^^^^^^^^^
  File "C:\Program Files\WindowsApps\PythonSoftwareFoundation.Python.3.11_3.11.2544.0_x64__qbz5n2kfra8p0\Lib\json\encoder.py", line 180, in default
    raise TypeError(f'Object of type {o.__class__.__name__} '
TypeError: Object of type ValueError is not JSON serializable
2025-03-02 02:20:04,008 - INFO - Database table created or already exists.
